Workbook

Sheet 周期整合及其行业风格表现汇总
B2: 一、周期整合：根据股债相对表现重新划分经济周期。注，债券收益率可以类比中证债基指数，回报率上行指牛市。 ※衰退：对应周期2（景气值<0，方向下降）。经济衰退阶段往往通货膨胀周期下行、实际经济增长放缓。此时货币宽松利好股票估值，但经济放缓对股票盈利构成抑制，股票收益率由弱转为更弱；而货币政策宽松和资金需求转弱同时推动利率下行并形成债券牛市。综合来看，当前阶段股票收益率弱于债券，且趋势上股债收益差下降。 ※复苏：对应周期3（景气值<0，方向上升）。经济复苏阶段往往通货膨胀周期下行、实际经济增长周期上行。此时因为经济复苏和货币宽松，股票估值和盈利同时修复，股票收益率由弱转强；而央行维持偏宽松的货币政策利好债券利率下行，但经济增长预期升温会产生利率上行的预期，所以债市收益率由强转弱。综合来看，当前阶段股票收益率弱于债券，但趋势上股债收益差上升。 ※过热：对应周期4（景气值>0，方向上升）。经济过热阶段通货膨胀周期上行、实际经济增长周期上行。此时宏观环境有利于股票盈利，对股票估值构成抑制，综合来看股市呈震荡阶段；但央行一般收紧货币政策，资金需求也比较旺盛，易推动债券利率上行，利空债市。综合来看，当前阶段股票收益率强于债券，且趋势上股债收益差上升。 ※滞涨：对应周期1（景气值>0，方向下降）。经济滞胀阶段往往通货膨胀周期上行、实际经济增长放缓。此时宏观环境对股票估值和盈利均构成抑制，综合来看股票收益率由强转弱；而央行治理通胀推动债券短端利率上行，经济的悲观预期推动中长端利率下行，综合来看债市收益率呈震荡阶段。综合来看，当前阶段股票收益率强于债券，但趋势上股债收益差下行。 二、行业风格表现：对各周期内的行业风格绝对回报、超额回报进行统计（月度平均收益率）。 1. 从超额收益看行业/风格轮动更有效：相对收益率可以更好体现出风格板块/行业表现与基本面的偏离情况，我们在绝对收益基础上结合相对收益（即各个风格较全A的超额回报来测算）； 2. 从超额收益看，存在以下特征： （1）经济放缓配大盘，经济走强配小盘。从沪深300vs中证1000，巨潮大盘vs巨潮小盘看，小盘股在经济走强时（复苏、过热）表现较好，大盘股在经济放缓时（滞涨、衰退）表现更佳，体现出防御属性。 （2）风格板块看，消费与金融、稳定能形成有效对冲，可以用于考虑配对交易来平抑风险。 （3）红利思路和大盘具有共通之处，经济下行时（滞涨、衰退）表现更佳。 （4）相比低估值的逆周期对抗效果，高估值板块在盈利下行期更易迎来“戴维斯双杀”。
B8: 周期整合
B9: 阶段划分 | G9: 划分依据
B11: 所处阶段 | C11: 阶段起点 | D11: 阶段终点
B12: 衰退 | C12: 45078 | D12: 45443
C13: 44348 | D13: 44500
C14: 43191 | D14: 43373
C15: 41791 | D15: 42004
C16: 40848 | D16: 41060
B17: 复苏 | C17: 45444 | D17: 45688
C18: 44501 | D18: 45077
C19: 43374 | D19: 43890
C20: 42005 | D20: 42429
C21: 41061 | D21: 41182
B22: 过热 | C22: 43891 | D22: 44135
C23: 42430 | D23: 42613
C24: 41183 | D24: 41486
B25: 滞涨 | C25: 44136 | D25: 44347
C26: 42614 | D26: 43190
C27: 41487 | D27: 41790
C28: 40179 | D28: 40847
B31: 超额收益——分股票风格和行业
C33: 个数 | D33: 总月数 | E33: 平均月数 | F33: 时期占比 | G33: 万得全A | H33: 上证50指数 | I33: 沪深300指数 | J33: 中证500指数 | K33: 中证1000指数
B34: 衰退 | C34: 5 | D34: 37 | E34: 7.4 | F34: 0.21387283 | H34: {=INDEX(货币信用周期收益计算!$Q$26:$BT$30,MATCH($B34,货币信用周期收益计算!$Q$26:$Q$30,0),MATCH(H$33,货币信用周期收益计算!$Q$26:$BT$26,0))} -> 6.2711653 | I34: {=INDEX(货币信用周期收益计算!$Q$26:$BT$30,MATCH($B34,货币信用周期收益计算!$Q$26:$Q$30,0),MATCH(I$33,货币信用周期收益计算!$Q$26:$BT$26,0))} -> 1.6999442 | J34: {=INDEX(货币信用周期收益计算!$Q$26:$BT$30,MATCH($B34,货币信用周期收益计算!$Q$26:$Q$30,0),MATCH(J$33,货币信用周期收益计算!$Q$26:$BT$26,0))} -> -4.8075247 | K34: {=INDEX(货币信用周期收益计算!$Q$26:$BT$30,MATCH($B34,货币信用周期收益计算!$Q$26:$Q$30,0),MATCH(K$33,货币信用周期收益计算!$Q$26:$BT$26,0))} -> -8.9802067
B35: 复苏 | C35: 4 | D35: 54 | E35: 13.5 | F35: 0.31213873 | H35: {=INDEX(货币信用周期收益计算!$Q$26:$BT$30,MATCH($B35,货币信用周期收益计算!$Q$26:$Q$30,0),MATCH(H$33,货币信用周期收益计算!$Q$26:$BT$26,0))} -> -9.7688737 | I35: {=INDEX(货币信用周期收益计算!$Q$26:$BT$30,MATCH($B35,货币信用周期收益计算!$Q$26:$Q$30,0),MATCH(I$33,货币信用周期收益计算!$Q$26:$BT$26,0))} -> -7.0921684 | J35: {=INDEX(货币信用周期收益计算!$Q$26:$BT$30,MATCH($B35,货币信用周期收益计算!$Q$26:$Q$30,0),MATCH(J$33,货币信用周期收益计算!$Q$26:$BT$26,0))} -> -1.4082342 | K35: {=INDEX(货币信用周期收益计算!$Q$26:$BT$30,MATCH($B35,货币信用周期收益计算!$Q$26:$Q$30,0),MATCH(K$33,货币信用周期收益计算!$Q$26:$BT$26,0))} -> 4.9244886
B36: 过热 | C36: 4 | D36: 58 | E36: 14.5 | F36: 0.33526012 | H36: {=INDEX(货币信用周期收益计算!$Q$26:$BT$30,MATCH($B36,货币信用周期收益计算!$Q$26:$Q$30,0),MATCH(H$33,货币信用周期收益计算!$Q$26:$BT$26,0))} -> -6.4710778 | I36: {=INDEX(货币信用周期收益计算!$Q$26:$BT$30,MATCH($B36,货币信用周期收益计算!$Q$26:$Q$30,0),MATCH(I$33,货币信用周期收益计算!$Q$26:$BT$26,0))} -> -4.4345811 | J36: {=INDEX(货币信用周期收益计算!$Q$26:$BT$30,MATCH($B36,货币信用周期收益计算!$Q$26:$Q$30,0),MATCH(J$33,货币信用周期收益计算!$Q$26:$BT$26,0))} -> -1.3910279 | K36: {=INDEX(货币信用周期收益计算!$Q$26:$BT$30,MATCH($B36,货币信用周期收益计算!$Q$26:$Q$30,0),MATCH(K$33,货币信用周期收益计算!$Q$26:$BT$26,0))} -> 2.0976137
B37: 滞涨 | C37: 3 | D37: 24 | E37: 8 | F37: 0.13872832 | H37: {=INDEX(货币信用周期收益计算!$Q$26:$BT$30,MATCH($B37,货币信用周期收益计算!$Q$26:$Q$30,0),MATCH(H$33,货币信用周期收益计算!$Q$26:$BT$26,0))} -> -0.14662292 | I37: {=INDEX(货币信用周期收益计算!$Q$26:$BT$30,MATCH($B37,货币信用周期收益计算!$Q$26:$Q$30,0),MATCH(I$33,货币信用周期收益计算!$Q$26:$BT$26,0))} -> 0.48124983 | J37: {=INDEX(货币信用周期收益计算!$Q$26:$BT$30,MATCH($B37,货币信用周期收益计算!$Q$26:$Q$30,0),MATCH(J$33,货币信用周期收益计算!$Q$26:$BT$26,0))} -> 0.85859361 | K37: {=INDEX(货币信用周期收益计算!$Q$26:$BT$30,MATCH($B37,货币信用周期收益计算!$Q$26:$Q$30,0),MATCH(K$33,货币信用周期收益计算!$Q$26:$BT$26,0))} -> -0.66859444
C40: 巨潮大盘 | D40: 巨潮中盘 | E40: 巨潮小盘
B41: 衰退 | C41: {=INDEX(货币信用周期收益计算!$Q$26:$BT$30,MATCH($B41,货币信用周期收益计算!$Q$26:$Q$30,0),MATCH(C$40,货币信用周期收益计算!$Q$26:$BT$26,0))} -> 2.7109775 | D41: {=INDEX(货币信用周期收益计算!$Q$26:$BT$30,MATCH($B41,货币信用周期收益计算!$Q$26:$Q$30,0),MATCH(D$40,货币信用周期收益计算!$Q$26:$BT$26,0))} -> -4.3181068 | E41: {=INDEX(货币信用周期收益计算!$Q$26:$BT$30,MATCH($B41,货币信用周期收益计算!$Q$26:$Q$30,0),MATCH(E$40,货币信用周期收益计算!$Q$26:$BT$26,0))} -> -5.1590797
B42: 复苏 | C42: {=INDEX(货币信用周期收益计算!$Q$26:$BT$30,MATCH($B42,货币信用周期收益计算!$Q$26:$Q$30,0),MATCH(C$40,货币信用周期收益计算!$Q$26:$BT$26,0))} -> -6.7457552 | D42: {=INDEX(货币信用周期收益计算!$Q$26:$BT$30,MATCH($B42,货币信用周期收益计算!$Q$26:$Q$30,0),MATCH(D$40,货币信用周期收益计算!$Q$26:$BT$26,0))} -> -3.3032223 | E42: {=INDEX(货币信用周期收益计算!$Q$26:$BT$30,MATCH($B42,货币信用周期收益计算!$Q$26:$Q$30,0),MATCH(E$40,货币信用周期收益计算!$Q$26:$BT$26,0))} -> 0.89238212
B43: 过热 | C43: {=INDEX(货币信用周期收益计算!$Q$26:$BT$30,MATCH($B43,货币信用周期收益计算!$Q$26:$Q$30,0),MATCH(C$40,货币信用周期收益计算!$Q$26:$BT$26,0))} -> -3.5585631 | D43: {=INDEX(货币信用周期收益计算!$Q$26:$BT$30,MATCH($B43,货币信用周期收益计算!$Q$26:$Q$30,0),MATCH(D$40,货币信用周期收益计算!$Q$26:$BT$26,0))} -> -3.2906536 | E43: {=INDEX(货币信用周期收益计算!$Q$26:$BT$30,MATCH($B43,货币信用周期收益计算!$Q$26:$Q$30,0),MATCH(E$40,货币信用周期收益计算!$Q$26:$BT$26,0))} -> 0.42350762
B44: 滞涨 | C44: {=INDEX(货币信用周期收益计算!$Q$26:$BT$30,MATCH($B44,货币信用周期收益计算!$Q$26:$Q$30,0),MATCH(C$40,货币信用周期收益计算!$Q$26:$BT$26,0))} -> 1.804068 | D44: {=INDEX(货币信用周期收益计算!$Q$26:$BT$30,MATCH($B44,货币信用周期收益计算!$Q$26:$Q$30,0),MATCH(D$40,货币信用周期收益计算!$Q$26:$BT$26,0))} -> -0.90752372 | E44: {=INDEX(货币信用周期收益计算!$Q$26:$BT$30,MATCH($B44,货币信用周期收益计算!$Q$26:$Q$30,0),MATCH(E$40,货币信用周期收益计算!$Q$26:$BT$26,0))} -> -0.627679
C46: 周期 | D46: 消费 | E46: 金融 | F46: 稳定 | G46: 成长
B47: 衰退 | C47: {=INDEX(货币信用周期收益计算!$Q$26:$BT$30,MATCH($B47,货币信用周期收益计算!$Q$26:$Q$30,0),MATCH(C$46,货币信用周期收益计算!$Q$26:$BT$26,0))} -> 1.6325242 | D47: {=INDEX(货币信用周期收益计算!$Q$26:$BT$30,MATCH($B47,货币信用周期收益计算!$Q$26:$Q$30,0),MATCH(D$46,货币信用周期收益计算!$Q$26:$BT$26,0))} -> -8.1844213 | E47: {=INDEX(货币信用周期收益计算!$Q$26:$BT$30,MATCH($B47,货币信用周期收益计算!$Q$26:$Q$30,0),MATCH(E$46,货币信用周期收益计算!$Q$26:$BT$26,0))} -> 12.973694 | F47: {=INDEX(货币信用周期收益计算!$Q$26:$BT$30,MATCH($B47,货币信用周期收益计算!$Q$26:$Q$30,0),MATCH(F$46,货币信用周期收益计算!$Q$26:$BT$26,0))} -> 11.649308 | G47: {=INDEX(货币信用周期收益计算!$Q$26:$BT$30,MATCH($B47,货币信用周期收益计算!$Q$26:$Q$30,0),MATCH(G$46,货币信用周期收益计算!$Q$26:$BT$26,0))} -> -7.391588
B48: 复苏 | C48: {=INDEX(货币信用周期收益计算!$Q$26:$BT$30,MATCH($B48,货币信用周期收益计算!$Q$26:$Q$30,0),MATCH(C$46,货币信用周期收益计算!$Q$26:$BT$26,0))} -> -4.3443 | D48: {=INDEX(货币信用周期收益计算!$Q$26:$BT$30,MATCH($B48,货币信用周期收益计算!$Q$26:$Q$30,0),MATCH(D$46,货币信用周期收益计算!$Q$26:$BT$26,0))} -> 3.1181521 | E48: {=INDEX(货币信用周期收益计算!$Q$26:$BT$30,MATCH($B48,货币信用周期收益计算!$Q$26:$Q$30,0),MATCH(E$46,货币信用周期收益计算!$Q$26:$BT$26,0))} -> -2.8886725 | F48: {=INDEX(货币信用周期收益计算!$Q$26:$BT$30,MATCH($B48,货币信用周期收益计算!$Q$26:$Q$30,0),MATCH(F$46,货币信用周期收益计算!$Q$26:$BT$26,0))} -> -5.7442499 | G48: {=INDEX(货币信用周期收益计算!$Q$26:$BT$30,MATCH($B48,货币信用周期收益计算!$Q$26:$Q$30,0),MATCH(G$46,货币信用周期收益计算!$Q$26:$BT$26,0))} -> 6.4292889
B49: 过热 | C49: {=INDEX(货币信用周期收益计算!$Q$26:$BT$30,MATCH($B49,货币信用周期收益计算!$Q$26:$Q$30,0),MATCH(C$46,货币信用周期收益计算!$Q$26:$BT$26,0))} -> -3.6119672 | D49: {=INDEX(货币信用周期收益计算!$Q$26:$BT$30,MATCH($B49,货币信用周期收益计算!$Q$26:$Q$30,0),MATCH(D$46,货币信用周期收益计算!$Q$26:$BT$26,0))} -> 8.4513097 | E49: {=INDEX(货币信用周期收益计算!$Q$26:$BT$30,MATCH($B49,货币信用周期收益计算!$Q$26:$Q$30,0),MATCH(E$46,货币信用周期收益计算!$Q$26:$BT$26,0))} -> -3.8241406 | F49: {=INDEX(货币信用周期收益计算!$Q$26:$BT$30,MATCH($B49,货币信用周期收益计算!$Q$26:$Q$30,0),MATCH(F$46,货币信用周期收益计算!$Q$26:$BT$26,0))} -> -7.8242854 | G49: {=INDEX(货币信用周期收益计算!$Q$26:$BT$30,MATCH($B49,货币信用周期收益计算!$Q$26:$Q$30,0),MATCH(G$46,货币信用周期收益计算!$Q$26:$BT$26,0))} -> 8.9106603
B50: 滞涨 | C50: {=INDEX(货币信用周期收益计算!$Q$26:$BT$30,MATCH($B50,货币信用周期收益计算!$Q$26:$Q$30,0),MATCH(C$46,货币信用周期收益计算!$Q$26:$BT$26,0))} -> 0.5115954 | D50: {=INDEX(货币信用周期收益计算!$Q$26:$BT$30,MATCH($B50,货币信用周期收益计算!$Q$26:$Q$30,0),MATCH(D$46,货币信用周期收益计算!$Q$26:$BT$26,0))} -> 8.4511109 | E50: {=INDEX(货币信用周期收益计算!$Q$26:$BT$30,MATCH($B50,货币信用周期收益计算!$Q$26:$Q$30,0),MATCH(E$46,货币信用周期收益计算!$Q$26:$BT$26,0))} -> -5.0305913 | F50: {=INDEX(货币信用周期收益计算!$Q$26:$BT$30,MATCH($B50,货币信用周期收益计算!$Q$26:$Q$30,0),MATCH(F$46,货币信用周期收益计算!$Q$26:$BT$26,0))} -> -4.4765763 | G50: {=INDEX(货币信用周期收益计算!$Q$26:$BT$30,MATCH($B50,货币信用周期收益计算!$Q$26:$Q$30,0),MATCH(G$46,货币信用周期收益计算!$Q$26:$BT$26,0))} -> 1.8132762
C52: 红利指数 | D52: 国证红利 | E52: 深证红利 | F52: 万得红利 | G52: 中证红利
B53: 衰退 | C53: {=INDEX(货币信用周期收益计算!$Q$26:$BT$30,MATCH($B53,货币信用周期收益计算!$Q$26:$Q$30,0),MATCH(C$52,货币信用周期收益计算!$Q$26:$BT$26,0))} -> 5.0919474 | D53: {=INDEX(货币信用周期收益计算!$Q$26:$BT$30,MATCH($B53,货币信用周期收益计算!$Q$26:$Q$30,0),MATCH(D$52,货币信用周期收益计算!$Q$26:$BT$26,0))} -> 6.9185009 | E53: {=INDEX(货币信用周期收益计算!$Q$26:$BT$30,MATCH($B53,货币信用周期收益计算!$Q$26:$Q$30,0),MATCH(E$52,货币信用周期收益计算!$Q$26:$BT$26,0))} -> -0.54076634 | F53: {=INDEX(货币信用周期收益计算!$Q$26:$BT$30,MATCH($B53,货币信用周期收益计算!$Q$26:$Q$30,0),MATCH(F$52,货币信用周期收益计算!$Q$26:$BT$26,0))} -> -6.569286 | G53: {=INDEX(货币信用周期收益计算!$Q$26:$BT$30,MATCH($B53,货币信用周期收益计算!$Q$26:$Q$30,0),MATCH(G$52,货币信用周期收益计算!$Q$26:$BT$26,0))} -> 3.7629755
B54: 复苏 | C54: {=INDEX(货币信用周期收益计算!$Q$26:$BT$30,MATCH($B54,货币信用周期收益计算!$Q$26:$Q$30,0),MATCH(C$52,货币信用周期收益计算!$Q$26:$BT$26,0))} -> -5.1993841 | D54: {=INDEX(货币信用周期收益计算!$Q$26:$BT$30,MATCH($B54,货币信用周期收益计算!$Q$26:$Q$30,0),MATCH(D$52,货币信用周期收益计算!$Q$26:$BT$26,0))} -> -5.8254295 | E54: {=INDEX(货币信用周期收益计算!$Q$26:$BT$30,MATCH($B54,货币信用周期收益计算!$Q$26:$Q$30,0),MATCH(E$52,货币信用周期收益计算!$Q$26:$BT$26,0))} -> -2.8585997 | F54: {=INDEX(货币信用周期收益计算!$Q$26:$BT$30,MATCH($B54,货币信用周期收益计算!$Q$26:$Q$30,0),MATCH(F$52,货币信用周期收益计算!$Q$26:$BT$26,0))} -> 1.542416 | G54: {=INDEX(货币信用周期收益计算!$Q$26:$BT$30,MATCH($B54,货币信用周期收益计算!$Q$26:$Q$30,0),MATCH(G$52,货币信用周期收益计算!$Q$26:$BT$26,0))} -> -1.7998185
...

Sheet 流程图
B2: 本页内容： 一、研究流程图 二、股债表现与经济周期对应图 三、风格指数汇总
B8: 研究流程图 | J8: 股债表现与经济周期对应图
B54: 风格指数汇总
B56: 风格 | C56: 代码 | D56: 指数
B57: 大中小盘 | C57: 399314.SZ | D57: 巨潮大盘
C58: 399315.SZ | D58: 巨潮中盘
C59: 399316.SZ | D59: 巨潮小盘
C60: 000016.SH | D60: 上证50指数
C61: 000300.SH | D61: 沪深300指数
C62: 000905.SH | D62: 中证500指数
C63: 000852.SH | D63: 中证1000指数
B64: 中信风格 | C64: CI005918.WI | D64: 周期
C65: CI005919.WI | D65: 消费
C66: CI005917.WI | D66: 金融
C67: CI005921.WI | D67: 稳定
C68: CI005920.WI | D68: 成长
B69: 红利 | C69: 399321.SZ | D69: 国证红利
C70: 399324.SZ | D70: 深证红利
C71: 867001.WI | D71: 万得红利
C72: 000922.CSI | D72: 中证红利
B73: 估值 | C73: 861101.CJ | D73: 低估值指数(长江)
C74: 861102.CJ | D74: 高估值指数(长江)
B75: 行业 | C75: 31个申万一级行业

Sheet 框架指示的股债胜率（综合）
J3: 美林时钟 | K3: 美林时钟 | L3: 货币信用周期 | M3: 货币信用周期 | N3: 财政货币周期 | O3: 财政货币周期 | P3: 信贷库存周期 | Q3: 信贷库存周期 | R3: 产能库存周期嵌套 | S3: 产能库存周期嵌套 | T3: 综合打分 | V3: 打分指示的股债强弱 | W3: 实际股债强弱（十年国债口径） | X3: 实际股债强弱（中证债基口径） | Y3: 打分指示的股债强弱(向前滚动5年、右轴) | Z3: 实际股债强弱（十年国债口径） | AA3: 实际股债强弱（中证债基口径）
B4: 万得全A:月:最后一条:环比 | C4: 中国:中债国债到期收益率:10年:月:平均值:环比增加:*100 | D4: 中证基金指数:债券基金:月:最后一条:环比 | E4: 美林时钟 | F4: 货币信用周期 | G4: 财政货币周期 | H4: 信贷库存周期 | I4: 产能库存周期嵌套 | J4: 股票 | K4: 债券 | L4: 股票 | M4: 债券 | N4: 股票 | O4: 债券 | P4: 股票 | Q4: 债券 | R4: 股票 | S4: 债券 | T4: 股票 | U4: 债券
A5: 46387 | E5: =VLOOKUP(A5,美林时钟!#REF!,28,TRUE) -> #REF! | F5: 宽货币紧信用 | G5: 紧货币宽财政 | H5: 被动去库存 | I5: 产能周期下行,主动补库存 | J5: {=INDEX(股债表现与四个维度!$A:$T,MATCH($A5,股债表现与四个维度!$A:$A,0),MATCH(J$3&J$4,股债表现与四个维度!$2:$2&股债表现与四个维度!$3:$3,0))} -> -0.076923077 | K5: {=INDEX(股债表现与四个维度!$A:$T,MATCH($A5,股债表现与四个维度!$A:$A,0),MATCH(K$3&K$4,股债表现与四个维度!$2:$2&股债表现与四个维度!$3:$3,0))} -> 0.15384615 | L5: {=INDEX(股债表现与四个维度!$A:$T,MATCH($A5,股债表现与四个维度!$A:$A,0),MATCH(L$3&L$4,股债表现与四个维度!$2:$2&股债表现与四个维度!$3:$3,0))} -> -0.083333333 | M5: {=INDEX(股债表现与四个维度!$A:$T,MATCH($A5,股债表现与四个维度!$A:$A,0),MATCH(M$3&M$4,股债表现与四个维度!$2:$2&股债表现与四个维度!$3:$3,0))} -> 0.56666667 | N5: {=INDEX(股债表现与四个维度!$A:$T,MATCH($A5,股债表现与四个维度!$A:$A,0),MATCH(N$3&N$4,股债表现与四个维度!$2:$2&股债表现与四个维度!$3:$3,0))} -> -0.043478261 | O5: {=INDEX(股债表现与四个维度!$A:$T,MATCH($A5,股债表现与四个维度!$A:$A,0),MATCH(O$3&O$4,股债表现与四个维度!$2:$2&股债表现与四个维度!$3:$3,0))} -> 0.95652174 | P5: {=INDEX(股债表现与四个维度!$A:$T,MATCH($A5,股债表现与四个维度!$A:$A,0),MATCH(P$3&P$4,股债表现与四个维度!$2:$2&股债表现与四个维度!$3:$3,0))} -> -0.076923077 | Q5: {=INDEX(股债表现与四个维度!$A:$T,MATCH($A5,股债表现与四个维度!$A:$A,0),MATCH(Q$3&Q$4,股债表现与四个维度!$2:$2&股债表现与四个维度!$3:$3,0))} -> 0.57692308 | ... S5: {=INDEX(股债表现与四个维度!$A:$T,MATCH($A5,股债表现与四个维度!$A:$A,0),MATCH(S$3&S$4,股债表现与四个维度!$2:$2&股债表现与四个维度!$3:$3,0))} -> 0.77777778 | T5: =SUMIFS($J5:$S5,$J5:$S5,"<>"&"#N/A",$J$4:$S$4,T$4) -> -0.3362133 | U5: =SUMIFS($J5:$S5,$J5:$S5,"<>"&"#N/A",$J$4:$S$4,U$4) -> 3.0317354 | V5: =T5-U5 -> -3.3679487
A6: 46356 | E6: =VLOOKUP(A6,美林时钟!#REF!,28,TRUE) -> #REF! | F6: 宽货币紧信用 | G6: 紧货币宽财政 | H6: 被动去库存 | I6: 产能周期下行,主动补库存 | J6: {=INDEX(股债表现与四个维度!$A:$T,MATCH($A6,股债表现与四个维度!$A:$A,0),MATCH(J$3&J$4,股债表现与四个维度!$2:$2&股债表现与四个维度!$3:$3,0))} -> -0.083333333 | K6: {=INDEX(股债表现与四个维度!$A:$T,MATCH($A6,股债表现与四个维度!$A:$A,0),MATCH(K$3&K$4,股债表现与四个维度!$2:$2&股债表现与四个维度!$3:$3,0))} -> 0.083333333 | L6: {=INDEX(股债表现与四个维度!$A:$T,MATCH($A6,股债表现与四个维度!$A:$A,0),MATCH(L$3&L$4,股债表现与四个维度!$2:$2&股债表现与四个维度!$3:$3,0))} -> -0.083333333 | M6: {=INDEX(股债表现与四个维度!$A:$T,MATCH($A6,股债表现与四个维度!$A:$A,0),MATCH(M$3&M$4,股债表现与四个维度!$2:$2&股债表现与四个维度!$3:$3,0))} -> 0.53333333 | N6: {=INDEX(股债表现与四个维度!$A:$T,MATCH($A6,股债表现与四个维度!$A:$A,0),MATCH(N$3&N$4,股债表现与四个维度!$2:$2&股债表现与四个维度!$3:$3,0))} -> -0.045454545 | O6: {=INDEX(股债表现与四个维度!$A:$T,MATCH($A6,股债表现与四个维度!$A:$A,0),MATCH(O$3&O$4,股债表现与四个维度!$2:$2&股债表现与四个维度!$3:$3,0))} -> 0.95454545 | P6: {=INDEX(股债表现与四个维度!$A:$T,MATCH($A6,股债表现与四个维度!$A:$A,0),MATCH(P$3&P$4,股债表现与四个维度!$2:$2&股债表现与四个维度!$3:$3,0))} -> -0.08 | Q6: {=INDEX(股债表现与四个维度!$A:$T,MATCH($A6,股债表现与四个维度!$A:$A,0),MATCH(Q$3&Q$4,股债表现与四个维度!$2:$2&股债表现与四个维度!$3:$3,0))} -> 0.56 | ... S6: {=INDEX(股债表现与四个维度!$A:$T,MATCH($A6,股债表现与四个维度!$A:$A,0),MATCH(S$3&S$4,股债表现与四个维度!$2:$2&股债表现与四个维度!$3:$3,0))} -> 0.77142857 | T6: =SUMIFS($J6:$S6,$J6:$S6,"<>"&"#N/A",$J$4:$S$4,T$4) -> -0.34926407 | U6: =SUMIFS($J6:$S6,$J6:$S6,"<>"&"#N/A",$J$4:$S$4,U$4) -> 2.9026407 | V6: =T6-U6 -> -3.2519048
A7: 46326 | E7: =VLOOKUP(A7,美林时钟!#REF!,28,TRUE) -> #REF! | F7: 宽货币紧信用 | G7: 紧货币宽财政 | H7: 被动去库存 | I7: 产能周期下行,主动补库存 | J7: {=INDEX(股债表现与四个维度!$A:$T,MATCH($A7,股债表现与四个维度!$A:$A,0),MATCH(J$3&J$4,股债表现与四个维度!$2:$2&股债表现与四个维度!$3:$3,0))} -> -0.090909091 | K7: {=INDEX(股债表现与四个维度!$A:$T,MATCH($A7,股债表现与四个维度!$A:$A,0),MATCH(K$3&K$4,股债表现与四个维度!$2:$2&股债表现与四个维度!$3:$3,0))} -> 0 | L7: {=INDEX(股债表现与四个维度!$A:$T,MATCH($A7,股债表现与四个维度!$A:$A,0),MATCH(L$3&L$4,股债表现与四个维度!$2:$2&股债表现与四个维度!$3:$3,0))} -> -0.1 | M7: {=INDEX(股债表现与四个维度!$A:$T,MATCH($A7,股债表现与四个维度!$A:$A,0),MATCH(M$3&M$4,股债表现与四个维度!$2:$2&股债表现与四个维度!$3:$3,0))} -> 0.51666667 | N7: {=INDEX(股债表现与四个维度!$A:$T,MATCH($A7,股债表现与四个维度!$A:$A,0),MATCH(N$3&N$4,股债表现与四个维度!$2:$2&股债表现与四个维度!$3:$3,0))} -> -0.047619048 | O7: {=INDEX(股债表现与四个维度!$A:$T,MATCH($A7,股债表现与四个维度!$A:$A,0),MATCH(O$3&O$4,股债表现与四个维度!$2:$2&股债表现与四个维度!$3:$3,0))} -> 0.95238095 | P7: {=INDEX(股债表现与四个维度!$A:$T,MATCH($A7,股债表现与四个维度!$A:$A,0),MATCH(P$3&P$4,股债表现与四个维度!$2:$2&股债表现与四个维度!$3:$3,0))} -> -0.083333333 | Q7: {=INDEX(股债表现与四个维度!$A:$T,MATCH($A7,股债表现与四个维度!$A:$A,0),MATCH(Q$3&Q$4,股债表现与四个维度!$2:$2&股债表现与四个维度!$3:$3,0))} -> 0.54166667 | ... S7: {=INDEX(股债表现与四个维度!$A:$T,MATCH($A7,股债表现与四个维度!$A:$A,0),MATCH(S$3&S$4,股债表现与四个维度!$2:$2&股债表现与四个维度!$3:$3,0))} -> 0.76470588 | T7: =SUMIFS($J7:$S7,$J7:$S7,"<>"&"#N/A",$J$4:$S$4,T$4) -> -0.380685 | U7: =SUMIFS($J7:$S7,$J7:$S7,"<>"&"#N/A",$J$4:$S$4,U$4) -> 2.7754202 | V7: =T7-U7 -> -3.1561052
A8: 46295 | E8: =VLOOKUP(A8,美林时钟!#REF!,28,TRUE) -> #REF! | F8: 宽货币紧信用 | G8: 紧货币宽财政 | H8: 被动去库存 | I8: 产能周期下行,主动补库存 | J8: {=INDEX(股债表现与四个维度!$A:$T,MATCH($A8,股债表现与四个维度!$A:$A,0),MATCH(J$3&J$4,股债表现与四个维度!$2:$2&股债表现与四个维度!$3:$3,0))} -> -0.1 | K8: {=INDEX(股债表现与四个维度!$A:$T,MATCH($A8,股债表现与四个维度!$A:$A,0),MATCH(K$3&K$4,股债表现与四个维度!$2:$2&股债表现与四个维度!$3:$3,0))} -> -0.1 | L8: {=INDEX(股债表现与四个维度!$A:$T,MATCH($A8,股债表现与四个维度!$A:$A,0),MATCH(L$3&L$4,股债表现与四个维度!$2:$2&股债表现与四个维度!$3:$3,0))} -> -0.083333333 | M8: {=INDEX(股债表现与四个维度!$A:$T,MATCH($A8,股债表现与四个维度!$A:$A,0),MATCH(M$3&M$4,股债表现与四个维度!$2:$2&股债表现与四个维度!$3:$3,0))} -> 0.51666667 | N8: {=INDEX(股债表现与四个维度!$A:$T,MATCH($A8,股债表现与四个维度!$A:$A,0),MATCH(N$3&N$4,股债表现与四个维度!$2:$2&股债表现与四个维度!$3:$3,0))} -> -0.05 | O8: {=INDEX(股债表现与四个维度!$A:$T,MATCH($A8,股债表现与四个维度!$A:$A,0),MATCH(O$3&O$4,股债表现与四个维度!$2:$2&股债表现与四个维度!$3:$3,0))} -> 0.95 | P8: {=INDEX(股债表现与四个维度!$A:$T,MATCH($A8,股债表现与四个维度!$A:$A,0),MATCH(P$3&P$4,股债表现与四个维度!$2:$2&股债表现与四个维度!$3:$3,0))} -> -0.086956522 | Q8: {=INDEX(股债表现与四个维度!$A:$T,MATCH($A8,股债表现与四个维度!$A:$A,0),MATCH(Q$3&Q$4,股债表现与四个维度!$2:$2&股债表现与四个维度!$3:$3,0))} -> 0.52173913 | ... S8: {=INDEX(股债表现与四个维度!$A:$T,MATCH($A8,股债表现与四个维度!$A:$A,0),MATCH(S$3&S$4,股债表现与四个维度!$2:$2&股债表现与四个维度!$3:$3,0))} -> 0.75757576 | T8: =SUMIFS($J8:$S8,$J8:$S8,"<>"&"#N/A",$J$4:$S$4,T$4) -> -0.38089592 | U8: =SUMIFS($J8:$S8,$J8:$S8,"<>"&"#N/A",$J$4:$S$4,U$4) -> 2.6459816 | V8: =T8-U8 -> -3.0268775
A9: 46265 | E9: =VLOOKUP(A9,美林时钟!#REF!,28,TRUE) -> #REF! | F9: 宽货币紧信用 | G9: 紧货币宽财政 | H9: 被动去库存 | I9: 产能周期下行,主动补库存 | J9: {=INDEX(股债表现与四个维度!$A:$T,MATCH($A9,股债表现与四个维度!$A:$A,0),MATCH(J$3&J$4,股债表现与四个维度!$2:$2&股债表现与四个维度!$3:$3,0))} -> -0.11111111 | K9: {=INDEX(股债表现与四个维度!$A:$T,MATCH($A9,股债表现与四个维度!$A:$A,0),MATCH(K$3&K$4,股债表现与四个维度!$2:$2&股债表现与四个维度!$3:$3,0))} -> -0.22222222 | L9: {=INDEX(股债表现与四个维度!$A:$T,MATCH($A9,股债表现与四个维度!$A:$A,0),MATCH(L$3&L$4,股债表现与四个维度!$2:$2&股债表现与四个维度!$3:$3,0))} -> -0.1 | M9: {=INDEX(股债表现与四个维度!$A:$T,MATCH($A9,股债表现与四个维度!$A:$A,0),MATCH(M$3&M$4,股债表现与四个维度!$2:$2&股债表现与四个维度!$3:$3,0))} -> 0.51666667 | N9: {=INDEX(股债表现与四个维度!$A:$T,MATCH($A9,股债表现与四个维度!$A:$A,0),MATCH(N$3&N$4,股债表现与四个维度!$2:$2&股债表现与四个维度!$3:$3,0))} -> -0.052631579 | O9: {=INDEX(股债表现与四个维度!$A:$T,MATCH($A9,股债表现与四个维度!$A:$A,0),MATCH(O$3&O$4,股债表现与四个维度!$2:$2&股债表现与四个维度!$3:$3,0))} -> 0.94736842 | P9: {=INDEX(股债表现与四个维度!$A:$T,MATCH($A9,股债表现与四个维度!$A:$A,0),MATCH(P$3&P$4,股债表现与四个维度!$2:$2&股债表现与四个维度!$3:$3,0))} -> -0.090909091 | Q9: {=INDEX(股债表现与四个维度!$A:$T,MATCH($A9,股债表现与四个维度!$A:$A,0),MATCH(Q$3&Q$4,股债表现与四个维度!$2:$2&股债表现与四个维度!$3:$3,0))} -> 0.5 | ... S9: {=INDEX(股债表现与四个维度!$A:$T,MATCH($A9,股债表现与四个维度!$A:$A,0),MATCH(S$3&S$4,股债表现与四个维度!$2:$2&股债表现与四个维度!$3:$3,0))} -> 0.75 | T9: =SUMIFS($J9:$S9,$J9:$S9,"<>"&"#N/A",$J$4:$S$4,T$4) -> -0.41715178 | U9: =SUMIFS($J9:$S9,$J9:$S9,"<>"&"#N/A",$J$4:$S$4,U$4) -> 2.4918129 | V9: =T9-U9 -> -2.9089646
A10: 46234 | E10: =VLOOKUP(A10,美林时钟!#REF!,28,TRUE) -> #REF! | F10: 宽货币紧信用 | G10: 紧货币宽财政 | H10: 被动去库存 | I10: 产能周期下行,主动补库存 | J10: {=INDEX(股债表现与四个维度!$A:$T,MATCH($A10,股债表现与四个维度!$A:$A,0),MATCH(J$3&J$4,股债表现与四个维度!$2:$2&股债表现与四个维度!$3:$3,0))} -> -0.125 | K10: {=INDEX(股债表现与四个维度!$A:$T,MATCH($A10,股债表现与四个维度!$A:$A,0),MATCH(K$3&K$4,股债表现与四个维度!$2:$2&股债表现与四个维度!$3:$3,0))} -> -0.375 | L10: {=INDEX(股债表现与四个维度!$A:$T,MATCH($A10,股债表现与四个维度!$A:$A,0),MATCH(L$3&L$4,股债表现与四个维度!$2:$2&股债表现与四个维度!$3:$3,0))} -> -0.083333333 | M10: {=INDEX(股债表现与四个维度!$A:$T,MATCH($A10,股债表现与四个维度!$A:$A,0),MATCH(M$3&M$4,股债表现与四个维度!$2:$2&股债表现与四个维度!$3:$3,0))} -> 0.51666667 | N10: {=INDEX(股债表现与四个维度!$A:$T,MATCH($A10,股债表现与四个维度!$A:$A,0),MATCH(N$3&N$4,股债表现与四个维度!$2:$2&股债表现与四个维度!$3:$3,0))} -> -0.055555556 | O10: {=INDEX(股债表现与四个维度!$A:$T,MATCH($A10,股债表现与四个维度!$A:$A,0),MATCH(O$3&O$4,股债表现与四个维度!$2:$2&股债表现与四个维度!$3:$3,0))} -> 0.94444444 | P10: {=INDEX(股债表现与四个维度!$A:$T,MATCH($A10,股债表现与四个维度!$A:$A,0),MATCH(P$3&P$4,股债表现与四个维度!$2:$2&股债表现与四个维度!$3:$3,0))} -> -0.095238095 | Q10: {=INDEX(股债表现与四个维度!$A:$T,MATCH($A10,股债表现与四个维度!$A:$A,0),MATCH(Q$3&Q$4,股债表现与四个维度!$2:$2&股债表现与四个维度!$3:$3,0))} -> 0.47619048 | ... S10: {=INDEX(股债表现与四个维度!$A:$T,MATCH($A10,股债表现与四个维度!$A:$A,0),MATCH(S$3&S$4,股债表现与四个维度!$2:$2&股债表现与四个维度!$3:$3,0))} -> 0.74193548 | T10: =SUMIFS($J10:$S10,$J10:$S10,"<>"&"#N/A",$J$4:$S$4,T$4) -> -0.42364311 | U10: =SUMIFS($J10:$S10,$J10:$S10,"<>"&"#N/A",$J$4:$S$4,U$4) -> 2.3042371 | V10: =T10-U10 -> -2.7278802
A11: 46203 | E11: =VLOOKUP(A11,美林时钟!#REF!,28,TRUE) -> #REF! | F11: 宽货币紧信用 | G11: 紧货币宽财政 | H11: 被动去库存 | I11: 产能周期下行,主动补库存 | J11: {=INDEX(股债表现与四个维度!$A:$T,MATCH($A11,股债表现与四个维度!$A:$A,0),MATCH(J$3&J$4,股债表现与四个维度!$2:$2&股债表现与四个维度!$3:$3,0))} -> -0.14285714 | K11: {=INDEX(股债表现与四个维度!$A:$T,MATCH($A11,股债表现与四个维度!$A:$A,0),MATCH(K$3&K$4,股债表现与四个维度!$2:$2&股债表现与四个维度!$3:$3,0))} -> -0.57142857 | L11: {=INDEX(股债表现与四个维度!$A:$T,MATCH($A11,股债表现与四个维度!$A:$A,0),MATCH(L$3&L$4,股债表现与四个维度!$2:$2&股债表现与四个维度!$3:$3,0))} -> -0.066666667 | M11: {=INDEX(股债表现与四个维度!$A:$T,MATCH($A11,股债表现与四个维度!$A:$A,0),MATCH(M$3&M$4,股债表现与四个维度!$2:$2&股债表现与四个维度!$3:$3,0))} -> 0.51666667 | N11: {=INDEX(股债表现与四个维度!$A:$T,MATCH($A11,股债表现与四个维度!$A:$A,0),MATCH(N$3&N$4,股债表现与四个维度!$2:$2&股债表现与四个维度!$3:$3,0))} -> -0.058823529 | O11: {=INDEX(股债表现与四个维度!$A:$T,MATCH($A11,股债表现与四个维度!$A:$A,0),MATCH(O$3&O$4,股债表现与四个维度!$2:$2&股债表现与四个维度!$3:$3,0))} -> 0.94117647 | P11: {=INDEX(股债表现与四个维度!$A:$T,MATCH($A11,股债表现与四个维度!$A:$A,0),MATCH(P$3&P$4,股债表现与四个维度!$2:$2&股债表现与四个维度!$3:$3,0))} -> -0.1 | Q11: {=INDEX(股债表现与四个维度!$A:$T,MATCH($A11,股债表现与四个维度!$A:$A,0),MATCH(Q$3&Q$4,股债表现与四个维度!$2:$2&股债表现与四个维度!$3:$3,0))} -> 0.45 | ... S11: {=INDEX(股债表现与四个维度!$A:$T,MATCH($A11,股债表现与四个维度!$A:$A,0),MATCH(S$3&S$4,股债表现与四个维度!$2:$2&股债表现与四个维度!$3:$3,0))} -> 0.73333333 | T11: =SUMIFS($J11:$S11,$J11:$S11,"<>"&"#N/A",$J$4:$S$4,T$4) -> -0.43501401 | U11: =SUMIFS($J11:$S11,$J11:$S11,"<>"&"#N/A",$J$4:$S$4,U$4) -> 2.0697479 | V11: =T11-U11 -> -2.5047619
A12: 46173 | E12: =VLOOKUP(A12,美林时钟!#REF!,28,TRUE) -> #REF! | F12: 宽货币紧信用 | G12: 紧货币宽财政 | H12: 被动去库存 | I12: 产能周期下行,主动补库存 | J12: {=INDEX(股债表现与四个维度!$A:$T,MATCH($A12,股债表现与四个维度!$A:$A,0),MATCH(J$3&J$4,股债表现与四个维度!$2:$2&股债表现与四个维度!$3:$3,0))} -> -0.14285714 | K12: {=INDEX(股债表现与四个维度!$A:$T,MATCH($A12,股债表现与四个维度!$A:$A,0),MATCH(K$3&K$4,股债表现与四个维度!$2:$2&股债表现与四个维度!$3:$3,0))} -> -0.57142857 | L12: {=INDEX(股债表现与四个维度!$A:$T,MATCH($A12,股债表现与四个维度!$A:$A,0),MATCH(L$3&L$4,股债表现与四个维度!$2:$2&股债表现与四个维度!$3:$3,0))} -> -0.05 | M12: {=INDEX(股债表现与四个维度!$A:$T,MATCH($A12,股债表现与四个维度!$A:$A,0),MATCH(M$3&M$4,股债表现与四个维度!$2:$2&股债表现与四个维度!$3:$3,0))} -> 0.51666667 | N12: {=INDEX(股债表现与四个维度!$A:$T,MATCH($A12,股债表现与四个维度!$A:$A,0),MATCH(N$3&N$4,股债表现与四个维度!$2:$2&股债表现与四个维度!$3:$3,0))} -> -0.0625 | O12: {=INDEX(股债表现与四个维度!$A:$T,MATCH($A12,股债表现与四个维度!$A:$A,0),MATCH(O$3&O$4,股债表现与四个维度!$2:$2&股债表现与四个维度!$3:$3,0))} -> 0.9375 | P12: {=INDEX(股债表现与四个维度!$A:$T,MATCH($A12,股债表现与四个维度!$A:$A,0),MATCH(P$3&P$4,股债表现与四个维度!$2:$2&股债表现与四个维度!$3:$3,0))} -> -0.10526316 | Q12: {=INDEX(股债表现与四个维度!$A:$T,MATCH($A12,股债表现与四个维度!$A:$A,0),MATCH(Q$3&Q$4,股债表现与四个维度!$2:$2&股债表现与四个维度!$3:$3,0))} -> 0.42105263 | ... S12: {=INDEX(股债表现与四个维度!$A:$T,MATCH($A12,股债表现与四个维度!$A:$A,0),MATCH(S$3&S$4,股债表现与四个维度!$2:$2&股债表现与四个维度!$3:$3,0))} -> 0.72413793 | T12: =SUMIFS($J12:$S12,$J12:$S12,"<>"&"#N/A",$J$4:$S$4,T$4) -> -0.42958582 | U12: =SUMIFS($J12:$S12,$J12:$S12,"<>"&"#N/A",$J$4:$S$4,U$4) -> 2.0279287 | V12: =T12-U12 -> -2.4575145
A13: 46142 | E13: =VLOOKUP(A13,美林时钟!#REF!,28,TRUE) -> #REF! | F13: 宽货币紧信用 | G13: 紧货币宽财政 | H13: 被动去库存 | I13: 产能周期下行,主动补库存 | J13: {=INDEX(股债表现与四个维度!$A:$T,MATCH($A13,股债表现与四个维度!$A:$A,0),MATCH(J$3&J$4,股债表现与四个维度!$2:$2&股债表现与四个维度!$3:$3,0))} -> -0.13333333 | K13: {=INDEX(股债表现与四个维度!$A:$T,MATCH($A13,股债表现与四个维度!$A:$A,0),MATCH(K$3&K$4,股债表现与四个维度!$2:$2&股债表现与四个维度!$3:$3,0))} -> 0.46666667 | L13: {=INDEX(股债表现与四个维度!$A:$T,MATCH($A13,股债表现与四个维度!$A:$A,0),MATCH(L$3&L$4,股债表现与四个维度!$2:$2&股债表现与四个维度!$3:$3,0))} -> -0.066666667 | M13: {=INDEX(股债表现与四个维度!$A:$T,MATCH($A13,股债表现与四个维度!$A:$A,0),MATCH(M$3&M$4,股债表现与四个维度!$2:$2&股债表现与四个维度!$3:$3,0))} -> 0.5 | N13: {=INDEX(股债表现与四个维度!$A:$T,MATCH($A13,股债表现与四个维度!$A:$A,0),MATCH(N$3&N$4,股债表现与四个维度!$2:$2&股债表现与四个维度!$3:$3,0))} -> -0.066666667 | O13: {=INDEX(股债表现与四个维度!$A:$T,MATCH($A13,股债表现与四个维度!$A:$A,0),MATCH(O$3&O$4,股债表现与四个维度!$2:$2&股债表现与四个维度!$3:$3,0))} -> 0.93333333 | P13: {=INDEX(股债表现与四个维度!$A:$T,MATCH($A13,股债表现与四个维度!$A:$A,0),MATCH(P$3&P$4,股债表现与四个维度!$2:$2&股债表现与四个维度!$3:$3,0))} -> -0.11111111 | Q13: {=INDEX(股债表现与四个维度!$A:$T,MATCH($A13,股债表现与四个维度!$A:$A,0),MATCH(Q$3&Q$4,股债表现与四个维度!$2:$2&股债表现与四个维度!$3:$3,0))} -> 0.38888889 | ... S13: {=INDEX(股债表现与四个维度!$A:$T,MATCH($A13,股债表现与四个维度!$A:$A,0),MATCH(S$3&S$4,股债表现与四个维度!$2:$2&股债表现与四个维度!$3:$3,0))} -> 0.71428571 | T13: =SUMIFS($J13:$S13,$J13:$S13,"<>"&"#N/A",$J$4:$S$4,T$4) -> -0.44920635 | U13: =SUMIFS($J13:$S13,$J13:$S13,"<>"&"#N/A",$J$4:$S$4,U$4) -> 3.0031746 | V13: =T13-U13 -> -3.452381
A14: 46112 | E14: =VLOOKUP(A14,美林时钟!#REF!,28,TRUE) -> #REF! | F14: 宽货币紧信用 | G14: 紧货币宽财政 | H14: 被动去库存 | I14: 产能周期下行,主动补库存 | J14: {=INDEX(股债表现与四个维度!$A:$T,MATCH($A14,股债表现与四个维度!$A:$A,0),MATCH(J$3&J$4,股债表现与四个维度!$2:$2&股债表现与四个维度!$3:$3,0))} -> 0 | K14: {=INDEX(股债表现与四个维度!$A:$T,MATCH($A14,股债表现与四个维度!$A:$A,0),MATCH(K$3&K$4,股债表现与四个维度!$2:$2&股债表现与四个维度!$3:$3,0))} -> 0.79166667 | L14: {=INDEX(股债表现与四个维度!$A:$T,MATCH($A14,股债表现与四个维度!$A:$A,0),MATCH(L$3&L$4,股债表现与四个维度!$2:$2&股债表现与四个维度!$3:$3,0))} -> -0.066666667 | M14: {=INDEX(股债表现与四个维度!$A:$T,MATCH($A14,股债表现与四个维度!$A:$A,0),MATCH(M$3&M$4,股债表现与四个维度!$2:$2&股债表现与四个维度!$3:$3,0))} -> 0.46666667 | N14: {=INDEX(股债表现与四个维度!$A:$T,MATCH($A14,股债表现与四个维度!$A:$A,0),MATCH(N$3&N$4,股债表现与四个维度!$2:$2&股债表现与四个维度!$3:$3,0))} -> -0.071428571 | O14: {=INDEX(股债表现与四个维度!$A:$T,MATCH($A14,股债表现与四个维度!$A:$A,0),MATCH(O$3&O$4,股债表现与四个维度!$2:$2&股债表现与四个维度!$3:$3,0))} -> 0.92857143 | P14: {=INDEX(股债表现与四个维度!$A:$T,MATCH($A14,股债表现与四个维度!$A:$A,0),MATCH(P$3&P$4,股债表现与四个维度!$2:$2&股债表现与四个维度!$3:$3,0))} -> -0.11111111 | Q14: {=INDEX(股债表现与四个维度!$A:$T,MATCH($A14,股债表现与四个维度!$A:$A,0),MATCH(Q$3&Q$4,股债表现与四个维度!$2:$2&股债表现与四个维度!$3:$3,0))} -> 0.38888889 | ... S14: {=INDEX(股债表现与四个维度!$A:$T,MATCH($A14,股债表现与四个维度!$A:$A,0),MATCH(S$3&S$4,股债表现与四个维度!$2:$2&股债表现与四个维度!$3:$3,0))} -> 0.71428571 | T14: =SUMIFS($J14:$S14,$J14:$S14,"<>"&"#N/A",$J$4:$S$4,T$4) -> -0.32063492 | U14: =SUMIFS($J14:$S14,$J14:$S14,"<>"&"#N/A",$J$4:$S$4,U$4) -> 3.2900794 | V14: =T14-U14 -> -3.6107143
A15: 46081 | E15: =VLOOKUP(A15,美林时钟!#REF!,28,TRUE) -> #REF! | F15: 宽货币紧信用 | G15: 紧货币宽财政 | H15: 被动去库存 | I15: 产能周期下行,主动补库存 | J15: {=INDEX(股债表现与四个维度!$A:$T,MATCH($A15,股债表现与四个维度!$A:$A,0),MATCH(J$3&J$4,股债表现与四个维度!$2:$2&股债表现与四个维度!$3:$3,0))} -> 0 | K15: {=INDEX(股债表现与四个维度!$A:$T,MATCH($A15,股债表现与四个维度!$A:$A,0),MATCH(K$3&K$4,股债表现与四个维度!$2:$2&股债表现与四个维度!$3:$3,0))} -> 0.7826087 | L15: {=INDEX(股债表现与四个维度!$A:$T,MATCH($A15,股债表现与四个维度!$A:$A,0),MATCH(L$3&L$4,股债表现与四个维度!$2:$2&股债表现与四个维度!$3:$3,0))} -> -0.066666667 | M15: {=INDEX(股债表现与四个维度!$A:$T,MATCH($A15,股债表现与四个维度!$A:$A,0),MATCH(M$3&M$4,股债表现与四个维度!$2:$2&股债表现与四个维度!$3:$3,0))} -> 0.46666667 | N15: {=INDEX(股债表现与四个维度!$A:$T,MATCH($A15,股债表现与四个维度!$A:$A,0),MATCH(N$3&N$4,股债表现与四个维度!$2:$2&股债表现与四个维度!$3:$3,0))} -> -0.071428571 | O15: {=INDEX(股债表现与四个维度!$A:$T,MATCH($A15,股债表现与四个维度!$A:$A,0),MATCH(O$3&O$4,股债表现与四个维度!$2:$2&股债表现与四个维度!$3:$3,0))} -> 0.92857143 | P15: {=INDEX(股债表现与四个维度!$A:$T,MATCH($A15,股债表现与四个维度!$A:$A,0),MATCH(P$3&P$4,股债表现与四个维度!$2:$2&股债表现与四个维度!$3:$3,0))} -> -0.5 | Q15: {=INDEX(股债表现与四个维度!$A:$T,MATCH($A15,股债表现与四个维度!$A:$A,0),MATCH(Q$3&Q$4,股债表现与四个维度!$2:$2&股债表现与四个维度!$3:$3,0))} -> 1 | ... S15: {=INDEX(股债表现与四个维度!$A:$T,MATCH($A15,股债表现与四个维度!$A:$A,0),MATCH(S$3&S$4,股债表现与四个维度!$2:$2&股债表现与四个维度!$3:$3,0))} -> 0.44444444 | T15: =SUMIFS($J15:$S15,$J15:$S15,"<>"&"#N/A",$J$4:$S$4,T$4) -> -0.86031746 | U15: =SUMIFS($J15:$S15,$J15:$S15,"<>"&"#N/A",$J$4:$S$4,U$4) -> 3.6222912 | V15: =T15-U15 -> -4.4826087
A16: 46053 | E16: =VLOOKUP(A16,美林时钟!A1:AB260,28,TRUE) -> 过热 | F16: 宽货币紧信用 | G16: 紧货币宽财政 | H16: 被动去库存 | I16: 产能周期下行,主动补库存 | J16: {=INDEX(股债表现与四个维度!$A:$T,MATCH($A16,股债表现与四个维度!$A:$A,0),MATCH(J$3&J$4,股债表现与四个维度!$2:$2&股债表现与四个维度!$3:$3,0))} -> 0 | K16: {=INDEX(股债表现与四个维度!$A:$T,MATCH($A16,股债表现与四个维度!$A:$A,0),MATCH(K$3&K$4,股债表现与四个维度!$2:$2&股债表现与四个维度!$3:$3,0))} -> 0.77272727 | L16: {=INDEX(股债表现与四个维度!$A:$T,MATCH($A16,股债表现与四个维度!$A:$A,0),MATCH(L$3&L$4,股债表现与四个维度!$2:$2&股债表现与四个维度!$3:$3,0))} -> -0.05 | M16: {=INDEX(股债表现与四个维度!$A:$T,MATCH($A16,股债表现与四个维度!$A:$A,0),MATCH(M$3&M$4,股债表现与四个维度!$2:$2&股债表现与四个维度!$3:$3,0))} -> 0.45 | N16: {=INDEX(股债表现与四个维度!$A:$T,MATCH($A16,股债表现与四个维度!$A:$A,0),MATCH(N$3&N$4,股债表现与四个维度!$2:$2&股债表现与四个维度!$3:$3,0))} -> -0.25 | O16: {=INDEX(股债表现与四个维度!$A:$T,MATCH($A16,股债表现与四个维度!$A:$A,0),MATCH(O$3&O$4,股债表现与四个维度!$2:$2&股债表现与四个维度!$3:$3,0))} -> 0.083333333 | P16: {=INDEX(股债表现与四个维度!$A:$T,MATCH($A16,股债表现与四个维度!$A:$A,0),MATCH(P$3&P$4,股债表现与四个维度!$2:$2&股债表现与四个维度!$3:$3,0))} -> -0.5 | Q16: {=INDEX(股债表现与四个维度!$A:$T,MATCH($A16,股债表现与四个维度!$A:$A,0),MATCH(Q$3&Q$4,股债表现与四个维度!$2:$2&股债表现与四个维度!$3:$3,0))} -> 1 | ... S16: {=INDEX(股债表现与四个维度!$A:$T,MATCH($A16,股债表现与四个维度!$A:$A,0),MATCH(S$3&S$4,股债表现与四个维度!$2:$2&股债表现与四个维度!$3:$3,0))} -> 0.44444444 | T16: =SUMIFS($J16:$S16,$J16:$S16,"<>"&"#N/A",$J$4:$S$4,T$4) -> -1.0222222 | U16: =SUMIFS($J16:$S16,$J16:$S16,"<>"&"#N/A",$J$4:$S$4,U$4) -> 2.7505051 | V16: =T16-U16 -> -3.7727273 | W16: 6.49 | Y16: -3.3160785
A17: 46022 | E17: =VLOOKUP(A17,美林时钟!A2:AB261,28,TRUE) -> 过热 | F17: 宽货币紧信用 | G17: 紧货币宽财政 | H17: 被动去库存 | I17: 产能周期下行,主动补库存 | J17: {=INDEX(股债表现与四个维度!$A:$T,MATCH($A17,股债表现与四个维度!$A:$A,0),MATCH(J$3&J$4,股债表现与四个维度!$2:$2&股债表现与四个维度!$3:$3,0))} -> 0 | K17: {=INDEX(股债表现与四个维度!$A:$T,MATCH($A17,股债表现与四个维度!$A:$A,0),MATCH(K$3&K$4,股债表现与四个维度!$2:$2&股债表现与四个维度!$3:$3,0))} -> 0.76190476 | L17: {=INDEX(股债表现与四个维度!$A:$T,MATCH($A17,股债表现与四个维度!$A:$A,0),MATCH(L$3&L$4,股债表现与四个维度!$2:$2&股债表现与四个维度!$3:$3,0))} -> -0.050847458 | M17: {=INDEX(股债表现与四个维度!$A:$T,MATCH($A17,股债表现与四个维度!$A:$A,0),MATCH(M$3&M$4,股债表现与四个维度!$2:$2&股债表现与四个维度!$3:$3,0))} -> 0.44067797 | N17: {=INDEX(股债表现与四个维度!$A:$T,MATCH($A17,股债表现与四个维度!$A:$A,0),MATCH(N$3&N$4,股债表现与四个维度!$2:$2&股债表现与四个维度!$3:$3,0))} -> -0.083333333 | O17: {=INDEX(股债表现与四个维度!$A:$T,MATCH($A17,股债表现与四个维度!$A:$A,0),MATCH(O$3&O$4,股债表现与四个维度!$2:$2&股债表现与四个维度!$3:$3,0))} -> 0.91666667 | P17: {=INDEX(股债表现与四个维度!$A:$T,MATCH($A17,股债表现与四个维度!$A:$A,0),MATCH(P$3&P$4,股债表现与四个维度!$2:$2&股债表现与四个维度!$3:$3,0))} -> 0 | Q17: {=INDEX(股债表现与四个维度!$A:$T,MATCH($A17,股债表现与四个维度!$A:$A,0),MATCH(Q$3&Q$4,股债表现与四个维度!$2:$2&股债表现与四个维度!$3:$3,0))} -> 0.37931034 | ... S17: {=INDEX(股债表现与四个维度!$A:$T,MATCH($A17,股债表现与四个维度!$A:$A,0),MATCH(S$3&S$4,股债表现与四个维度!$2:$2&股债表现与四个维度!$3:$3,0))} -> 0.69230769 | T17: =SUMIFS($J17:$S17,$J17:$S17,"<>"&"#N/A",$J$4:$S$4,T$4) -> -0.21110387 | U17: =SUMIFS($J17:$S17,$J17:$S17,"<>"&"#N/A",$J$4:$S$4,U$4) -> 3.1908674 | V17: =T17-U17 -> -3.4019713 | W17: 6.4860486 | X17: =C17+D17 -> 0 | Y17: =AVERAGE(V17:V22) -> -3.3160785
A18: 45991 | E18: =VLOOKUP(A18,美林时钟!A3:AB262,28,TRUE) -> 过热 | F18: 宽货币紧信用 | G18: 紧货币宽财政 | H18: 被动去库存 | I18: 产能周期下行,主动补库存 | J18: {=INDEX(股债表现与四个维度!$A:$T,MATCH($A18,股债表现与四个维度!$A:$A,0),MATCH(J$3&J$4,股债表现与四个维度!$2:$2&股债表现与四个维度!$3:$3,0))} -> 0 | K18: {=INDEX(股债表现与四个维度!$A:$T,MATCH($A18,股债表现与四个维度!$A:$A,0),MATCH(K$3&K$4,股债表现与四个维度!$2:$2&股债表现与四个维度!$3:$3,0))} -> 0.75 | L18: {=INDEX(股债表现与四个维度!$A:$T,MATCH($A18,股债表现与四个维度!$A:$A,0),MATCH(L$3&L$4,股债表现与四个维度!$2:$2&股债表现与四个维度!$3:$3,0))} -> -0.051724138 | M18: {=INDEX(股债表现与四个维度!$A:$T,MATCH($A18,股债表现与四个维度!$A:$A,0),MATCH(M$3&M$4,股债表现与四个维度!$2:$2&股债表现与四个维度!$3:$3,0))} -> 0.43103448 | N18: {=INDEX(股债表现与四个维度!$A:$T,MATCH($A18,股债表现与四个维度!$A:$A,0),MATCH(N$3&N$4,股债表现与四个维度!$2:$2&股债表现与四个维度!$3:$3,0))} -> -0.090909091 | O18: {=INDEX(股债表现与四个维度!$A:$T,MATCH($A18,股债表现与四个维度!$A:$A,0),MATCH(O$3&O$4,股债表现与四个维度!$2:$2&股债表现与四个维度!$3:$3,0))} -> 0.90909091 | P18: {=INDEX(股债表现与四个维度!$A:$T,MATCH($A18,股债表现与四个维度!$A:$A,0),MATCH(P$3&P$4,股债表现与四个维度!$2:$2&股债表现与四个维度!$3:$3,0))} -> 0 | Q18: {=INDEX(股债表现与四个维度!$A:$T,MATCH($A18,股债表现与四个维度!$A:$A,0),MATCH(Q$3&Q$4,股债表现与四个维度!$2:$2&股债表现与四个维度!$3:$3,0))} -> 0.37931034 | ... S18: {=INDEX(股债表现与四个维度!$A:$T,MATCH($A18,股债表现与四个维度!$A:$A,0),MATCH(S$3&S$4,股债表现与四个维度!$2:$2&股债表现与四个维度!$3:$3,0))} -> 0.68 | T18: =SUMIFS($J18:$S18,$J18:$S18,"<>"&"#N/A",$J$4:$S$4,T$4) -> -0.22263323 | U18: =SUMIFS($J18:$S18,$J18:$S18,"<>"&"#N/A",$J$4:$S$4,U$4) -> 3.1494357 | V18: =T18-U18 -> -3.372069 | W18: 5.740969 | X18: =C18+D18 -> 0 | Y18: =AVERAGE(V18:V23) -> -3.2575214
A19: 45961 | E19: =VLOOKUP(A19,美林时钟!A4:AB263,28,TRUE) -> 过热 | F19: 宽货币紧信用 | G19: 紧货币宽财政 | H19: 被动去库存 | I19: 产能周期下行,主动补库存 | J19: {=INDEX(股债表现与四个维度!$A:$T,MATCH($A19,股债表现与四个维度!$A:$A,0),MATCH(J$3&J$4,股债表现与四个维度!$2:$2&股债表现与四个维度!$3:$3,0))} -> 0 | K19: {=INDEX(股债表现与四个维度!$A:$T,MATCH($A19,股债表现与四个维度!$A:$A,0),MATCH(K$3&K$4,股债表现与四个维度!$2:$2&股债表现与四个维度!$3:$3,0))} -> 0.73684211 | L19: {=INDEX(股债表现与四个维度!$A:$T,MATCH($A19,股债表现与四个维度!$A:$A,0),MATCH(L$3&L$4,股债表现与四个维度!$2:$2&股债表现与四个维度!$3:$3,0))} -> -0.052631579 | M19: {=INDEX(股债表现与四个维度!$A:$T,MATCH($A19,股债表现与四个维度!$A:$A,0),MATCH(M$3&M$4,股债表现与四个维度!$2:$2&股债表现与四个维度!$3:$3,0))} -> 0.42105263 | N19: {=INDEX(股债表现与四个维度!$A:$T,MATCH($A19,股债表现与四个维度!$A:$A,0),MATCH(N$3&N$4,股债表现与四个维度!$2:$2&股债表现与四个维度!$3:$3,0))} -> -0.1 | O19: {=INDEX(股债表现与四个维度!$A:$T,MATCH($A19,股债表现与四个维度!$A:$A,0),MATCH(O$3&O$4,股债表现与四个维度!$2:$2&股债表现与四个维度!$3:$3,0))} -> 0.9 | P19: {=INDEX(股债表现与四个维度!$A:$T,MATCH($A19,股债表现与四个维度!$A:$A,0),MATCH(P$3&P$4,股债表现与四个维度!$2:$2&股债表现与四个维度!$3:$3,0))} -> -0.125 | Q19: {=INDEX(股债表现与四个维度!$A:$T,MATCH($A19,股债表现与四个维度!$A:$A,0),MATCH(Q$3&Q$4,股债表现与四个维度!$2:$2&股债表现与四个维度!$3:$3,0))} -> 0.3125 | ... S19: {=INDEX(股债表现与四个维度!$A:$T,MATCH($A19,股债表现与四个维度!$A:$A,0),MATCH(S$3&S$4,股债表现与四个维度!$2:$2&股债表现与四个维度!$3:$3,0))} -> 0.66666667 | T19: =SUMIFS($J19:$S19,$J19:$S19,"<>"&"#N/A",$J$4:$S$4,T$4) -> -0.36096491 | U19: =SUMIFS($J19:$S19,$J19:$S19,"<>"&"#N/A",$J$4:$S$4,U$4) -> 3.0370614 | V19: =T19-U19 -> -3.3980263 | W19: 7.013594 | X19: =C19+D19 -> 0 | Y19: =AVERAGE(V19:V24) -> -3.1881386
A20: 45930 | E20: =VLOOKUP(A20,美林时钟!A5:AB264,28,TRUE) -> 滞涨 | F20: 宽货币紧信用 | G20: 紧货币宽财政 | H20: 被动去库存 | I20: 产能周期下行,主动补库存 | J20: {=INDEX(股债表现与四个维度!$A:$T,MATCH($A20,股债表现与四个维度!$A:$A,0),MATCH(J$3&J$4,股债表现与四个维度!$2:$2&股债表现与四个维度!$3:$3,0))} -> 0 | K20: {=INDEX(股债表现与四个维度!$A:$T,MATCH($A20,股债表现与四个维度!$A:$A,0),MATCH(K$3&K$4,股债表现与四个维度!$2:$2&股债表现与四个维度!$3:$3,0))} -> 0.72222222 | L20: {=INDEX(股债表现与四个维度!$A:$T,MATCH($A20,股债表现与四个维度!$A:$A,0),MATCH(L$3&L$4,股债表现与四个维度!$2:$2&股债表现与四个维度!$3:$3,0))} -> -0.053571429 | M20: {=INDEX(股债表现与四个维度!$A:$T,MATCH($A20,股债表现与四个维度!$A:$A,0),MATCH(M$3&M$4,股债表现与四个维度!$2:$2&股债表现与四个维度!$3:$3,0))} -> 0.41071429 | N20: {=INDEX(股债表现与四个维度!$A:$T,MATCH($A20,股债表现与四个维度!$A:$A,0),MATCH(N$3&N$4,股债表现与四个维度!$2:$2&股债表现与四个维度!$3:$3,0))} -> -0.11111111 | O20: {=INDEX(股债表现与四个维度!$A:$T,MATCH($A20,股债表现与四个维度!$A:$A,0),MATCH(O$3&O$4,股债表现与四个维度!$2:$2&股债表现与四个维度!$3:$3,0))} -> 0.88888889 | P20: {=INDEX(股债表现与四个维度!$A:$T,MATCH($A20,股债表现与四个维度!$A:$A,0),MATCH(P$3&P$4,股债表现与四个维度!$2:$2&股债表现与四个维度!$3:$3,0))} -> -0.13333333 | Q20: {=INDEX(股债表现与四个维度!$A:$T,MATCH($A20,股债表现与四个维度!$A:$A,0),MATCH(Q$3&Q$4,股债表现与四个维度!$2:$2&股债表现与四个维度!$3:$3,0))} -> 0.26666667 | ... S20: {=INDEX(股债表现与四个维度!$A:$T,MATCH($A20,股债表现与四个维度!$A:$A,0),MATCH(S$3&S$4,股债表现与四个维度!$2:$2&股债表现与四个维度!$3:$3,0))} -> 0.65217391 | T20: =SUMIFS($J20:$S20,$J20:$S20,"<>"&"#N/A",$J$4:$S$4,T$4) -> -0.38497239 | U20: =SUMIFS($J20:$S20,$J20:$S20,"<>"&"#N/A",$J$4:$S$4,U$4) -> 2.940666 | V20: =T20-U20 -> -3.3256384 | W20: 4.4896607 | X20: =C20+D20 -> 0 | Y20: =AVERAGE(V20:V25) -> -2.9631337
A21: 45900 | E21: =VLOOKUP(A21,美林时钟!A6:AB265,28,TRUE) -> 滞涨 | F21: 宽货币紧信用 | G21: 紧货币宽财政 | H21: 被动去库存 | I21: 产能周期下行,主动补库存 | J21: {=INDEX(股债表现与四个维度!$A:$T,MATCH($A21,股债表现与四个维度!$A:$A,0),MATCH(J$3&J$4,股债表现与四个维度!$2:$2&股债表现与四个维度!$3:$3,0))} -> 0 | K21: {=INDEX(股债表现与四个维度!$A:$T,MATCH($A21,股债表现与四个维度!$A:$A,0),MATCH(K$3&K$4,股债表现与四个维度!$2:$2&股债表现与四个维度!$3:$3,0))} -> 0.70588235 | L21: {=INDEX(股债表现与四个维度!$A:$T,MATCH($A21,股债表现与四个维度!$A:$A,0),MATCH(L$3&L$4,股债表现与四个维度!$2:$2&股债表现与四个维度!$3:$3,0))} -> -0.054545455 | M21: {=INDEX(股债表现与四个维度!$A:$T,MATCH($A21,股债表现与四个维度!$A:$A,0),MATCH(M$3&M$4,股债表现与四个维度!$2:$2&股债表现与四个维度!$3:$3,0))} -> 0.4 | N21: {=INDEX(股债表现与四个维度!$A:$T,MATCH($A21,股债表现与四个维度!$A:$A,0),MATCH(N$3&N$4,股债表现与四个维度!$2:$2&股债表现与四个维度!$3:$3,0))} -> -0.125 | O21: {=INDEX(股债表现与四个维度!$A:$T,MATCH($A21,股债表现与四个维度!$A:$A,0),MATCH(O$3&O$4,股债表现与四个维度!$2:$2&股债表现与四个维度!$3:$3,0))} -> 0.875 | P21: {=INDEX(股债表现与四个维度!$A:$T,MATCH($A21,股债表现与四个维度!$A:$A,0),MATCH(P$3&P$4,股债表现与四个维度!$2:$2&股债表现与四个维度!$3:$3,0))} -> -0.14285714 | Q21: {=INDEX(股债表现与四个维度!$A:$T,MATCH($A21,股债表现与四个维度!$A:$A,0),MATCH(Q$3&Q$4,股债表现与四个维度!$2:$2&股债表现与四个维度!$3:$3,0))} -> 0.21428571 | ... S21: {=INDEX(股债表现与四个维度!$A:$T,MATCH($A21,股债表现与四个维度!$A:$A,0),MATCH(S$3&S$4,股债表现与四个维度!$2:$2&股债表现与四个维度!$3:$3,0))} -> 0.63636364 | T21: =SUMIFS($J21:$S21,$J21:$S21,"<>"&"#N/A",$J$4:$S$4,T$4) -> -0.41331169 | U21: =SUMIFS($J21:$S21,$J21:$S21,"<>"&"#N/A",$J$4:$S$4,U$4) -> 2.8315317 | V21: =T21-U21 -> -3.2448434 | W21: 4.5176469 | X21: =C21+D21 -> 0 | Y21: =AVERAGE(V21:V26) -> -2.8692679
A22: 45869 | E22: =VLOOKUP(A22,美林时钟!A7:AB266,28,TRUE) -> 滞涨 | F22: 宽货币紧信用 | G22: 紧货币宽财政 | H22: 被动去库存 | I22: 产能周期下行,主动补库存 | J22: {=INDEX(股债表现与四个维度!$A:$T,MATCH($A22,股债表现与四个维度!$A:$A,0),MATCH(J$3&J$4,股债表现与四个维度!$2:$2&股债表现与四个维度!$3:$3,0))} -> 0 | K22: {=INDEX(股债表现与四个维度!$A:$T,MATCH($A22,股债表现与四个维度!$A:$A,0),MATCH(K$3&K$4,股债表现与四个维度!$2:$2&股债表现与四个维度!$3:$3,0))} -> 0.6875 | L22: {=INDEX(股债表现与四个维度!$A:$T,MATCH($A22,股债表现与四个维度!$A:$A,0),MATCH(L$3&L$4,股债表现与四个维度!$2:$2&股债表现与四个维度!$3:$3,0))} -> -0.055555556 | M22: {=INDEX(股债表现与四个维度!$A:$T,MATCH($A22,股债表现与四个维度!$A:$A,0),MATCH(M$3&M$4,股债表现与四个维度!$2:$2&股债表现与四个维度!$3:$3,0))} -> 0.38888889 | N22: {=INDEX(股债表现与四个维度!$A:$T,MATCH($A22,股债表现与四个维度!$A:$A,0),MATCH(N$3&N$4,股债表现与四个维度!$2:$2&股债表现与四个维度!$3:$3,0))} -> -0.14285714 | O22: {=INDEX(股债表现与四个维度!$A:$T,MATCH($A22,股债表现与四个维度!$A:$A,0),MATCH(O$3&O$4,股债表现与四个维度!$2:$2&股债表现与四个维度!$3:$3,0))} -> 0.85714286 | P22: {=INDEX(股债表现与四个维度!$A:$T,MATCH($A22,股债表现与四个维度!$A:$A,0),MATCH(P$3&P$4,股债表现与四个维度!$2:$2&股债表现与四个维度!$3:$3,0))} -> -0.15384615 | Q22: {=INDEX(股债表现与四个维度!$A:$T,MATCH($A22,股债表现与四个维度!$A:$A,0),MATCH(Q$3&Q$4,股债表现与四个维度!$2:$2&股债表现与四个维度!$3:$3,0))} -> 0.15384615 | ... S22: {=INDEX(股债表现与四个维度!$A:$T,MATCH($A22,股债表现与四个维度!$A:$A,0),MATCH(S$3&S$4,股债表现与四个维度!$2:$2&股债表现与四个维度!$3:$3,0))} -> 0.61904762 | T22: =SUMIFS($J22:$S22,$J22:$S22,"<>"&"#N/A",$J$4:$S$4,T$4) -> -0.44749695 | U22: =SUMIFS($J22:$S22,$J22:$S22,"<>"&"#N/A",$J$4:$S$4,U$4) -> 2.7064255 | V22: =T22-U22 -> -3.1539225 | W22: 2.8260007 | X22: =C22+D22 -> 0 | Y22: =AVERAGE(V22:V27) -> -2.5582214
A23: 45838 | E23: =VLOOKUP(A23,美林时钟!A8:AB267,28,TRUE) -> 滞涨 | F23: 宽货币紧信用 | G23: 紧货币宽财政 | H23: 被动去库存 | I23: 产能周期下行,主动补库存 | J23: {=INDEX(股债表现与四个维度!$A:$T,MATCH($A23,股债表现与四个维度!$A:$A,0),MATCH(J$3&J$4,股债表现与四个维度!$2:$2&股债表现与四个维度!$3:$3,0))} -> 0 | K23: {=INDEX(股债表现与四个维度!$A:$T,MATCH($A23,股债表现与四个维度!$A:$A,0),MATCH(K$3&K$4,股债表现与四个维度!$2:$2&股债表现与四个维度!$3:$3,0))} -> 0.66666667 | L23: {=INDEX(股债表现与四个维度!$A:$T,MATCH($A23,股债表现与四个维度!$A:$A,0),MATCH(L$3&L$4,股债表现与四个维度!$2:$2&股债表现与四个维度!$3:$3,0))} -> -0.056603774 | M23: {=INDEX(股债表现与四个维度!$A:$T,MATCH($A23,股债表现与四个维度!$A:$A,0),MATCH(M$3&M$4,股债表现与四个维度!$2:$2&股债表现与四个维度!$3:$3,0))} -> 0.37735849 | N23: {=INDEX(股债表现与四个维度!$A:$T,MATCH($A23,股债表现与四个维度!$A:$A,0),MATCH(N$3&N$4,股债表现与四个维度!$2:$2&股债表现与四个维度!$3:$3,0))} -> -0.16666667 | O23: {=INDEX(股债表现与四个维度!$A:$T,MATCH($A23,股债表现与四个维度!$A:$A,0),MATCH(O$3&O$4,股债表现与四个维度!$2:$2&股债表现与四个维度!$3:$3,0))} -> 0.83333333 | P23: {=INDEX(股债表现与四个维度!$A:$T,MATCH($A23,股债表现与四个维度!$A:$A,0),MATCH(P$3&P$4,股债表现与四个维度!$2:$2&股债表现与四个维度!$3:$3,0))} -> -0.16666667 | Q23: {=INDEX(股债表现与四个维度!$A:$T,MATCH($A23,股债表现与四个维度!$A:$A,0),MATCH(Q$3&Q$4,股债表现与四个维度!$2:$2&股债表现与四个维度!$3:$3,0))} -> 0.083333333 | ... S23: {=INDEX(股债表现与四个维度!$A:$T,MATCH($A23,股债表现与四个维度!$A:$A,0),MATCH(S$3&S$4,股债表现与四个维度!$2:$2&股债表现与四个维度!$3:$3,0))} -> 0.6 | T23: =SUMIFS($J23:$S23,$J23:$S23,"<>"&"#N/A",$J$4:$S$4,T$4) -> -0.48993711 | U23: =SUMIFS($J23:$S23,$J23:$S23,"<>"&"#N/A",$J$4:$S$4,U$4) -> 2.5606918 | V23: =T23-U23 -> -3.0506289 | W23: -1.4990226 | X23: =C23+D23 -> 0 | Y23: =AVERAGE(V23:V28) -> -2.0756232
A24: 45808 | E24: =VLOOKUP(A24,美林时钟!A9:AB268,28,TRUE) -> 滞涨 | F24: 宽货币紧信用 | G24: 紧货币宽财政 | H24: 被动去库存 | I24: 产能周期下行,主动补库存 | J24: {=INDEX(股债表现与四个维度!$A:$T,MATCH($A24,股债表现与四个维度!$A:$A,0),MATCH(J$3&J$4,股债表现与四个维度!$2:$2&股债表现与四个维度!$3:$3,0))} -> 0 | K24: {=INDEX(股债表现与四个维度!$A:$T,MATCH($A24,股债表现与四个维度!$A:$A,0),MATCH(K$3&K$4,股债表现与四个维度!$2:$2&股债表现与四个维度!$3:$3,0))} -> 0.66666667 | L24: {=INDEX(股债表现与四个维度!$A:$T,MATCH($A24,股债表现与四个维度!$A:$A,0),MATCH(L$3&L$4,股债表现与四个维度!$2:$2&股债表现与四个维度!$3:$3,0))} -> -0.057692308 | M24: {=INDEX(股债表现与四个维度!$A:$T,MATCH($A24,股债表现与四个维度!$A:$A,0),MATCH(M$3&M$4,股债表现与四个维度!$2:$2&股债表现与四个维度!$3:$3,0))} -> 0.36538462 | N24: {=INDEX(股债表现与四个维度!$A:$T,MATCH($A24,股债表现与四个维度!$A:$A,0),MATCH(N$3&N$4,股债表现与四个维度!$2:$2&股债表现与四个维度!$3:$3,0))} -> -0.2 | O24: {=INDEX(股债表现与四个维度!$A:$T,MATCH($A24,股债表现与四个维度!$A:$A,0),MATCH(O$3&O$4,股债表现与四个维度!$2:$2&股债表现与四个维度!$3:$3,0))} -> 0.8 | P24: {=INDEX(股债表现与四个维度!$A:$T,MATCH($A24,股债表现与四个维度!$A:$A,0),MATCH(P$3&P$4,股债表现与四个维度!$2:$2&股债表现与四个维度!$3:$3,0))} -> -0.18181818 | Q24: {=INDEX(股债表现与四个维度!$A:$T,MATCH($A24,股债表现与四个维度!$A:$A,0),MATCH(Q$3&Q$4,股债表现与四个维度!$2:$2&股债表现与四个维度!$3:$3,0))} -> 0 | ... S24: {=INDEX(股债表现与四个维度!$A:$T,MATCH($A24,股债表现与四个维度!$A:$A,0),MATCH(S$3&S$4,股债表现与四个维度!$2:$2&股债表现与四个维度!$3:$3,0))} -> 0.57894737 | T24: =SUMIFS($J24:$S24,$J24:$S24,"<>"&"#N/A",$J$4:$S$4,T$4) -> -0.54477365 | U24: =SUMIFS($J24:$S24,$J24:$S24,"<>"&"#N/A",$J$4:$S$4,U$4) -> 2.4109987 | V24: =T24-U24 -> -2.9557723 | W24: -6.8973344 | X24: =C24+D24 -> 0 | Y24: =AVERAGE(V24:V29) -> -1.6159862
A25: 45777 | E25: =VLOOKUP(A25,美林时钟!A10:AB269,28,TRUE) -> 衰退 | F25: 宽货币紧信用 | G25: 紧货币宽财政 | H25: 被动去库存 | I25: 产能周期下行,主动补库存 | J25: {=INDEX(股债表现与四个维度!$A:$T,MATCH($A25,股债表现与四个维度!$A:$A,0),MATCH(J$3&J$4,股债表现与四个维度!$2:$2&股债表现与四个维度!$3:$3,0))} -> 0.13043478 | K25: {=INDEX(股债表现与四个维度!$A:$T,MATCH($A25,股债表现与四个维度!$A:$A,0),MATCH(K$3&K$4,股债表现与四个维度!$2:$2&股债表现与四个维度!$3:$3,0))} -> 0 | L25: {=INDEX(股债表现与四个维度!$A:$T,MATCH($A25,股债表现与四个维度!$A:$A,0),MATCH(L$3&L$4,股债表现与四个维度!$2:$2&股债表现与四个维度!$3:$3,0))} -> -0.058823529 | M25: {=INDEX(股债表现与四个维度!$A:$T,MATCH($A25,股债表现与四个维度!$A:$A,0),MATCH(M$3&M$4,股债表现与四个维度!$2:$2&股债表现与四个维度!$3:$3,0))} -> 0.35294118 | N25: {=INDEX(股债表现与四个维度!$A:$T,MATCH($A25,股债表现与四个维度!$A:$A,0),MATCH(N$3&N$4,股债表现与四个维度!$2:$2&股债表现与四个维度!$3:$3,0))} -> -0.25 | O25: {=INDEX(股债表现与四个维度!$A:$T,MATCH($A25,股债表现与四个维度!$A:$A,0),MATCH(O$3&O$4,股债表现与四个维度!$2:$2&股债表现与四个维度!$3:$3,0))} -> 0.75 | P25: {=INDEX(股债表现与四个维度!$A:$T,MATCH($A25,股债表现与四个维度!$A:$A,0),MATCH(P$3&P$4,股债表现与四个维度!$2:$2&股债表现与四个维度!$3:$3,0))} -> -0.2 | Q25: {=INDEX(股债表现与四个维度!$A:$T,MATCH($A25,股债表现与四个维度!$A:$A,0),MATCH(Q$3&Q$4,股债表现与四个维度!$2:$2&股债表现与四个维度!$3:$3,0))} -> -0.1 | ... S25: {=INDEX(股债表现与四个维度!$A:$T,MATCH($A25,股债表现与四个维度!$A:$A,0),MATCH(S$3&S$4,股债表现与四个维度!$2:$2&股债表现与四个维度!$3:$3,0))} -> 0.55555556 | T25: =SUMIFS($J25:$S25,$J25:$S25,"<>"&"#N/A",$J$4:$S$4,T$4) -> -0.48949986 | U25: =SUMIFS($J25:$S25,$J25:$S25,"<>"&"#N/A",$J$4:$S$4,U$4) -> 1.5584967 | V25: =T25-U25 -> -2.0479966 | W25: -8.2816599 | X25: =C25+D25 -> 0 | Y25: =AVERAGE(V25:V30) -> -1.2574154
A26: 45747 | E26: =VLOOKUP(A26,美林时钟!A11:AB270,28,TRUE) -> 复苏 | F26: 宽货币紧信用 | G26: 紧货币宽财政 | H26: 被动去库存 | I26: 产能周期下行,主动补库存 | J26: {=INDEX(股债表现与四个维度!$A:$T,MATCH($A26,股债表现与四个维度!$A:$A,0),MATCH(J$3&J$4,股债表现与四个维度!$2:$2&股债表现与四个维度!$3:$3,0))} -> 0 | K26: {=INDEX(股债表现与四个维度!$A:$T,MATCH($A26,股债表现与四个维度!$A:$A,0),MATCH(K$3&K$4,股债表现与四个维度!$2:$2&股债表现与四个维度!$3:$3,0))} -> 0.61538462 | L26: {=INDEX(股债表现与四个维度!$A:$T,MATCH($A26,股债表现与四个维度!$A:$A,0),MATCH(L$3&L$4,股债表现与四个维度!$2:$2&股债表现与四个维度!$3:$3,0))} -> -0.06 | M26: {=INDEX(股债表现与四个维度!$A:$T,MATCH($A26,股债表现与四个维度!$A:$A,0),MATCH(M$3&M$4,股债表现与四个维度!$2:$2&股债表现与四个维度!$3:$3,0))} -> 0.34 | N26: {=INDEX(股债表现与四个维度!$A:$T,MATCH($A26,股债表现与四个维度!$A:$A,0),MATCH(N$3&N$4,股债表现与四个维度!$2:$2&股债表现与四个维度!$3:$3,0))} -> -0.25 | O26: {=INDEX(股债表现与四个维度!$A:$T,MATCH($A26,股债表现与四个维度!$A:$A,0),MATCH(O$3&O$4,股债表现与四个维度!$2:$2&股债表现与四个维度!$3:$3,0))} -> 0.75 | P26: {=INDEX(股债表现与四个维度!$A:$T,MATCH($A26,股债表现与四个维度!$A:$A,0),MATCH(P$3&P$4,股债表现与四个维度!$2:$2&股债表现与四个维度!$3:$3,0))} -> -0.2 | Q26: {=INDEX(股债表现与四个维度!$A:$T,MATCH($A26,股债表现与四个维度!$A:$A,0),MATCH(Q$3&Q$4,股债表现与四个维度!$2:$2&股债表现与四个维度!$3:$3,0))} -> -0.1 | ... S26: {=INDEX(股债表现与四个维度!$A:$T,MATCH($A26,股债表现与四个维度!$A:$A,0),MATCH(S$3&S$4,股债表现与四个维度!$2:$2&股债表现与四个维度!$3:$3,0))} -> 0.52941176 | T26: =SUMIFS($J26:$S26,$J26:$S26,"<>"&"#N/A",$J$4:$S$4,T$4) -> -0.62764706 | U26: =SUMIFS($J26:$S26,$J26:$S26,"<>"&"#N/A",$J$4:$S$4,U$4) -> 2.1347964 | V26: =T26-U26 -> -2.7624434 | W26: -4.2268817 | X26: =C26+D26 -> 0 | Y26: =AVERAGE(V26:V31) -> -1.063367
A27: 45716 | B27: 4.6416175 | C27: -1.8484211 | D27: 0.12994035 | E27: =VLOOKUP(A27,美林时钟!A12:AB271,28,TRUE) -> 复苏 | F27: 宽货币紧信用 | G27: 双紧 | H27: 主动补库存 | I27: 产能周期下行,主动补库存 | J27: {=INDEX(股债表现与四个维度!$A:$T,MATCH($A27,股债表现与四个维度!$A:$A,0),MATCH(J$3&J$4,股债表现与四个维度!$2:$2&股债表现与四个维度!$3:$3,0))} -> 0 | K27: {=INDEX(股债表现与四个维度!$A:$T,MATCH($A27,股债表现与四个维度!$A:$A,0),MATCH(K$3&K$4,股债表现与四个维度!$2:$2&股债表现与四个维度!$3:$3,0))} -> 0.61538462 | L27: {=INDEX(股债表现与四个维度!$A:$T,MATCH($A27,股债表现与四个维度!$A:$A,0),MATCH(L$3&L$4,股债表现与四个维度!$2:$2&股债表现与四个维度!$3:$3,0))} -> -0.040816327 | M27: {=INDEX(股债表现与四个维度!$A:$T,MATCH($A27,股债表现与四个维度!$A:$A,0),MATCH(M$3&M$4,股债表现与四个维度!$2:$2&股债表现与四个维度!$3:$3,0))} -> 0.32653061 | N27: {=INDEX(股债表现与四个维度!$A:$T,MATCH($A27,股债表现与四个维度!$A:$A,0),MATCH(N$3&N$4,股债表现与四个维度!$2:$2&股债表现与四个维度!$3:$3,0))} -> 0.0625 | O27: {=INDEX(股债表现与四个维度!$A:$T,MATCH($A27,股债表现与四个维度!$A:$A,0),MATCH(O$3&O$4,股债表现与四个维度!$2:$2&股债表现与四个维度!$3:$3,0))} -> -0.4375 | P27: {=INDEX(股债表现与四个维度!$A:$T,MATCH($A27,股债表现与四个维度!$A:$A,0),MATCH(P$3&P$4,股债表现与四个维度!$2:$2&股债表现与四个维度!$3:$3,0))} -> 0 | Q27: {=INDEX(股债表现与四个维度!$A:$T,MATCH($A27,股债表现与四个维度!$A:$A,0),MATCH(Q$3&Q$4,股债表现与四个维度!$2:$2&股债表现与四个维度!$3:$3,0))} -> 0.33333333 | ... S27: {=INDEX(股债表现与四个维度!$A:$T,MATCH($A27,股债表现与四个维度!$A:$A,0),MATCH(S$3&S$4,股债表现与四个维度!$2:$2&股债表现与四个维度!$3:$3,0))} -> 0.5 | T27: =SUMIFS($J27:$S27,$J27:$S27,"<>"&"#N/A",$J$4:$S$4,T$4) -> -0.040816327 | U27: =SUMIFS($J27:$S27,$J27:$S27,"<>"&"#N/A",$J$4:$S$4,U$4) -> 1.3377486 | V27: =T27-U27 -> -1.3785649 | W27: -3.9967064 | X27: =C27+D27 -> -1.7184807 | Y27: =AVERAGE(V27:V32) -> -1.002581
A28: 45688 | B28: -2.3186982 | C28: -16.228852 | D28: 0.089306256 | E28: =VLOOKUP(A28,美林时钟!A13:AB272,28,TRUE) -> 过热 | F28: 宽货币紧信用 | G28: 双紧 | H28: 主动补库存 | I28: 产能周期下行,主动补库存 | J28: {=INDEX(股债表现与四个维度!$A:$T,MATCH($A28,股债表现与四个维度!$A:$A,0),MATCH(J$3&J$4,股债表现与四个维度!$2:$2&股债表现与四个维度!$3:$3,0))} -> 0.25 | K28: {=INDEX(股债表现与四个维度!$A:$T,MATCH($A28,股债表现与四个维度!$A:$A,0),MATCH(K$3&K$4,股债表现与四个维度!$2:$2&股债表现与四个维度!$3:$3,0))} -> 0.041666667 | L28: {=INDEX(股债表现与四个维度!$A:$T,MATCH($A28,股债表现与四个维度!$A:$A,0),MATCH(L$3&L$4,股债表现与四个维度!$2:$2&股债表现与四个维度!$3:$3,0))} -> -0.020833333 | M28: {=INDEX(股债表现与四个维度!$A:$T,MATCH($A28,股债表现与四个维度!$A:$A,0),MATCH(M$3&M$4,股债表现与四个维度!$2:$2&股债表现与四个维度!$3:$3,0))} -> 0.3125 | N28: {=INDEX(股债表现与四个维度!$A:$T,MATCH($A28,股债表现与四个维度!$A:$A,0),MATCH(N$3&N$4,股债表现与四个维度!$2:$2&股债表现与四个维度!$3:$3,0))} -> 0.13333333 | O28: {=INDEX(股债表现与四个维度!$A:$T,MATCH($A28,股债表现与四个维度!$A:$A,0),MATCH(O$3&O$4,股债表现与四个维度!$2:$2&股债表现与四个维度!$3:$3,0))} -> -0.53333333 | P28: {=INDEX(股债表现与四个维度!$A:$T,MATCH($A28,股债表现与四个维度!$A:$A,0),MATCH(P$3&P$4,股债表现与四个维度!$2:$2&股债表现与四个维度!$3:$3,0))} -> 0 | Q28: {=INDEX(股债表现与四个维度!$A:$T,MATCH($A28,股债表现与四个维度!$A:$A,0),MATCH(Q$3&Q$4,股债表现与四个维度!$2:$2&股债表现与四个维度!$3:$3,0))} -> 0.33333333 | ... S28: {=INDEX(股债表现与四个维度!$A:$T,MATCH($A28,股债表现与四个维度!$A:$A,0),MATCH(S$3&S$4,股债表现与四个维度!$2:$2&股债表现与四个维度!$3:$3,0))} -> 0.46666667 | T28: =SUMIFS($J28:$S28,$J28:$S28,"<>"&"#N/A",$J$4:$S$4,T$4) -> 0.3625 | U28: =SUMIFS($J28:$S28,$J28:$S28,"<>"&"#N/A",$J$4:$S$4,U$4) -> 0.62083333 | V28: =T28-U28 -> -0.25833333 | W28: -7.0871388 | X28: =C28+D28 -> -16.139545 | Y28: =AVERAGE(V28:V33) -> -1.4195336
A29: 45657 | B29: -1.9590725 | C29: -28.86368 | D29: 0.92221589 | E29: =VLOOKUP(A29,美林时钟!A14:AB273,28,TRUE) -> 过热 | F29: 宽货币紧信用 | G29: 双紧 | H29: 被动补库存 | I29: 产能周期下行,主动补库存 | J29: {=INDEX(股债表现与四个维度!$A:$T,MATCH($A29,股债表现与四个维度!$A:$A,0),MATCH(J$3&J$4,股债表现与四个维度!$2:$2&股债表现与四个维度!$3:$3,0))} -> 0.16666667 | K29: {=INDEX(股债表现与四个维度!$A:$T,MATCH($A29,股债表现与四个维度!$A:$A,0),MATCH(K$3&K$4,股债表现与四个维度!$2:$2&股债表现与四个维度!$3:$3,0))} -> 0 | L29: {=INDEX(股债表现与四个维度!$A:$T,MATCH($A29,股债表现与四个维度!$A:$A,0),MATCH(L$3&L$4,股债表现与四个维度!$2:$2&股债表现与四个维度!$3:$3,0))} -> -0.042553191 | M29: {=INDEX(股债表现与四个维度!$A:$T,MATCH($A29,股债表现与四个维度!$A:$A,0),MATCH(M$3&M$4,股债表现与四个维度!$2:$2&股债表现与四个维度!$3:$3,0))} -> 0.29787234 | N29: {=INDEX(股债表现与四个维度!$A:$T,MATCH($A29,股债表现与四个维度!$A:$A,0),MATCH(N$3&N$4,股债表现与四个维度!$2:$2&股债表现与四个维度!$3:$3,0))} -> 0.071428571 | O29: {=INDEX(股债表现与四个维度!$A:$T,MATCH($A29,股债表现与四个维度!$A:$A,0),MATCH(O$3&O$4,股债表现与四个维度!$2:$2&股债表现与四个维度!$3:$3,0))} -> -0.64285714 | P29: {=INDEX(股债表现与四个维度!$A:$T,MATCH($A29,股债表现与四个维度!$A:$A,0),MATCH(P$3&P$4,股债表现与四个维度!$2:$2&股债表现与四个维度!$3:$3,0))} -> 0 | Q29: {=INDEX(股债表现与四个维度!$A:$T,MATCH($A29,股债表现与四个维度!$A:$A,0),MATCH(Q$3&Q$4,股债表现与四个维度!$2:$2&股债表现与四个维度!$3:$3,0))} -> 0.33333333 | ... S29: {=INDEX(股债表现与四个维度!$A:$T,MATCH($A29,股债表现与四个维度!$A:$A,0),MATCH(S$3&S$4,股债表现与四个维度!$2:$2&股债表现与四个维度!$3:$3,0))} -> 0.42857143 | T29: =SUMIFS($J29:$S29,$J29:$S29,"<>"&"#N/A",$J$4:$S$4,T$4) -> 0.12411348 | U29: =SUMIFS($J29:$S29,$J29:$S29,"<>"&"#N/A",$J$4:$S$4,U$4) -> 0.41691996 | V29: =T29-U29 -> -0.29280648 | W29: -4.241618 | X29: =C29+D29 -> -27.941464 | Y29: =AVERAGE(V29:V34) -> -1.7174815 | Z29: =AVERAGE(W29:W34) -> 0.80849249 | AA29: =AVERAGE(X29:X34) -> -7.248321
A30: 45626 | B30: 1.3430445 | C30: -5.8158897 | D30: 0.59258383 | E30: =VLOOKUP(A30,美林时钟!A15:AB274,28,TRUE) -> 过热 | F30: 宽货币紧信用 | G30: 双紧 | H30: 被动补库存 | I30: 产能周期下行,主动补库存 | J30: {=INDEX(股债表现与四个维度!$A:$T,MATCH($A30,股债表现与四个维度!$A:$A,0),MATCH(J$3&J$4,股债表现与四个维度!$2:$2&股债表现与四个维度!$3:$3,0))} -> 0.13043478 | K30: {=INDEX(股债表现与四个维度!$A:$T,MATCH($A30,股债表现与四个维度!$A:$A,0),MATCH(K$3&K$4,股债表现与四个维度!$2:$2&股债表现与四个维度!$3:$3,0))} -> 0.043478261 | L30: {=INDEX(股债表现与四个维度!$A:$T,MATCH($A30,股债表现与四个维度!$A:$A,0),MATCH(L$3&L$4,股债表现与四个维度!$2:$2&股债表现与四个维度!$3:$3,0))} -> -0.065217391 | M30: {=INDEX(股债表现与四个维度!$A:$T,MATCH($A30,股债表现与四个维度!$A:$A,0),MATCH(M$3&M$4,股债表现与四个维度!$2:$2&股债表现与四个维度!$3:$3,0))} -> 0.32608696 | N30: {=INDEX(股债表现与四个维度!$A:$T,MATCH($A30,股债表现与四个维度!$A:$A,0),MATCH(N$3&N$4,股债表现与四个维度!$2:$2&股债表现与四个维度!$3:$3,0))} -> 0 | O30: {=INDEX(股债表现与四个维度!$A:$T,MATCH($A30,股债表现与四个维度!$A:$A,0),MATCH(O$3&O$4,股债表现与四个维度!$2:$2&股债表现与四个维度!$3:$3,0))} -> -0.61538462 | P30: {=INDEX(股债表现与四个维度!$A:$T,MATCH($A30,股债表现与四个维度!$A:$A,0),MATCH(P$3&P$4,股债表现与四个维度!$2:$2&股债表现与四个维度!$3:$3,0))} -> -0.038461538 | Q30: {=INDEX(股债表现与四个维度!$A:$T,MATCH($A30,股债表现与四个维度!$A:$A,0),MATCH(Q$3&Q$4,股债表现与四个维度!$2:$2&股债表现与四个维度!$3:$3,0))} -> 0.38461538 | ... S30: {=INDEX(股债表现与四个维度!$A:$T,MATCH($A30,股债表现与四个维度!$A:$A,0),MATCH(S$3&S$4,股债表现与四个维度!$2:$2&股债表现与四个维度!$3:$3,0))} -> 0.53846154 | T30: =SUMIFS($J30:$S30,$J30:$S30,"<>"&"#N/A",$J$4:$S$4,T$4) -> -0.1270903 | U30: =SUMIFS($J30:$S30,$J30:$S30,"<>"&"#N/A",$J$4:$S$4,U$4) -> 0.67725753 | V30: =T30-U30 -> -0.80434783 | W30: -0.7533162 | X30: =C30+D30 -> -5.2233059 | Y30: =AVERAGE(V30:V35) -> -2.0424001 | Z30: =AVERAGE(W30:W35) -> -0.13339469 | AA30: =AVERAGE(X30:X35) -> -3.3452051
A31: 45596 | B31: 2.2784563 | C31: 4.251604 | D31: 0.14691428 | E31: =VLOOKUP(A31,美林时钟!A16:AB275,28,TRUE) -> 复苏 | F31: 宽货币紧信用 | G31: 双紧 | H31: 被动补库存 | I31: 产能周期下行,主动补库存 | J31: {=INDEX(股债表现与四个维度!$A:$T,MATCH($A31,股债表现与四个维度!$A:$A,0),MATCH(J$3&J$4,股债表现与四个维度!$2:$2&股债表现与四个维度!$3:$3,0))} -> 0.090909091 | K31: {=INDEX(股债表现与四个维度!$A:$T,MATCH($A31,股债表现与四个维度!$A:$A,0),MATCH(K$3&K$4,股债表现与四个维度!$2:$2&股债表现与四个维度!$3:$3,0))} -> 0 | L31: {=INDEX(股债表现与四个维度!$A:$T,MATCH($A31,股债表现与四个维度!$A:$A,0),MATCH(L$3&L$4,股债表现与四个维度!$2:$2&股债表现与四个维度!$3:$3,0))} -> -0.088888889 | M31: {=INDEX(股债表现与四个维度!$A:$T,MATCH($A31,股债表现与四个维度!$A:$A,0),MATCH(M$3&M$4,股债表现与四个维度!$2:$2&股债表现与四个维度!$3:$3,0))} -> 0.31111111 | N31: {=INDEX(股债表现与四个维度!$A:$T,MATCH($A31,股债表现与四个维度!$A:$A,0),MATCH(N$3&N$4,股债表现与四个维度!$2:$2&股债表现与四个维度!$3:$3,0))} -> 0 | O31: {=INDEX(股债表现与四个维度!$A:$T,MATCH($A31,股债表现与四个维度!$A:$A,0),MATCH(O$3&O$4,股债表现与四个维度!$2:$2&股债表现与四个维度!$3:$3,0))} -> -0.61538462 | P31: {=INDEX(股债表现与四个维度!$A:$T,MATCH($A31,股债表现与四个维度!$A:$A,0),MATCH(P$3&P$4,股债表现与四个维度!$2:$2&股债表现与四个维度!$3:$3,0))} -> -0.08 | Q31: {=INDEX(股债表现与四个维度!$A:$T,MATCH($A31,股债表现与四个维度!$A:$A,0),MATCH(Q$3&Q$4,股债表现与四个维度!$2:$2&股债表现与四个维度!$3:$3,0))} -> 0.36 | ... S31: {=INDEX(股债表现与四个维度!$A:$T,MATCH($A31,股债表现与四个维度!$A:$A,0),MATCH(S$3&S$4,股债表现与四个维度!$2:$2&股债表现与四个维度!$3:$3,0))} -> 0.5 | T31: =SUMIFS($J31:$S31,$J31:$S31,"<>"&"#N/A",$J$4:$S$4,T$4) -> -0.3279798 | U31: =SUMIFS($J31:$S31,$J31:$S31,"<>"&"#N/A",$J$4:$S$4,U$4) -> 0.5557265 | V31: =T31-U31 -> -0.88370629 | W31: =B31+C31 -> 6.5300603 | X31: =C31+D31 -> 4.3985183 | Y31: =AVERAGE(V31:V36) -> -2.3084846 | Z31: =AVERAGE(W31:W36) -> 0.14161396 | AA31: =AVERAGE(X31:X36) -> -2.7406311
A32: 45565 | B32: 22.210135 | C32: -6.9838528 | D32: 0.32825829 | E32: =VLOOKUP(A32,美林时钟!A17:AB276,28,TRUE) -> 复苏 | F32: 宽货币紧信用 | G32: 紧货币宽财政 | H32: 被动补库存 | I32: 产能周期下行,主动补库存 | J32: {=INDEX(股债表现与四个维度!$A:$T,MATCH($A32,股债表现与四个维度!$A:$A,0),MATCH(J$3&J$4,股债表现与四个维度!$2:$2&股债表现与四个维度!$3:$3,0))} -> 0.090909091 | K32: {=INDEX(股债表现与四个维度!$A:$T,MATCH($A32,股债表现与四个维度!$A:$A,0),MATCH(K$3&K$4,股债表现与四个维度!$2:$2&股债表现与四个维度!$3:$3,0))} -> 0 | L32: {=INDEX(股债表现与四个维度!$A:$T,MATCH($A32,股债表现与四个维度!$A:$A,0),MATCH(L$3&L$4,股债表现与四个维度!$2:$2&股债表现与四个维度!$3:$3,0))} -> -0.068181818 | M32: {=INDEX(股债表现与四个维度!$A:$T,MATCH($A32,股债表现与四个维度!$A:$A,0),MATCH(M$3&M$4,股债表现与四个维度!$2:$2&股债表现与四个维度!$3:$3,0))} -> 0.29545455 | N32: {=INDEX(股债表现与四个维度!$A:$T,MATCH($A32,股债表现与四个维度!$A:$A,0),MATCH(N$3&N$4,股债表现与四个维度!$2:$2&股债表现与四个维度!$3:$3,0))} -> -0.5 | O32: {=INDEX(股债表现与四个维度!$A:$T,MATCH($A32,股债表现与四个维度!$A:$A,0),MATCH(O$3&O$4,股债表现与四个维度!$2:$2&股债表现与四个维度!$3:$3,0))} -> 0.5 | P32: {=INDEX(股债表现与四个维度!$A:$T,MATCH($A32,股债表现与四个维度!$A:$A,0),MATCH(P$3&P$4,股债表现与四个维度!$2:$2&股债表现与四个维度!$3:$3,0))} -> -0.041666667 | Q32: {=INDEX(股债表现与四个维度!$A:$T,MATCH($A32,股债表现与四个维度!$A:$A,0),MATCH(Q$3&Q$4,股债表现与四个维度!$2:$2&股债表现与四个维度!$3:$3,0))} -> 0.33333333 | ... S32: {=INDEX(股债表现与四个维度!$A:$T,MATCH($A32,股债表现与四个维度!$A:$A,0),MATCH(S$3&S$4,股债表现与四个维度!$2:$2&股债表现与四个维度!$3:$3,0))} -> 0.5 | T32: =SUMIFS($J32:$S32,$J32:$S32,"<>"&"#N/A",$J$4:$S$4,T$4) -> -0.76893939 | U32: =SUMIFS($J32:$S32,$J32:$S32,"<>"&"#N/A",$J$4:$S$4,U$4) -> 1.6287879 | V32: =T32-U32 -> -2.3977273 | W32: =B32+C32 -> 15.226282 | X32: =C32+D32 -> -6.6555945 | Y32: =AVERAGE(V32:V37) -> -2.5968375 | Z32: =AVERAGE(W32:W37) -> -1.1986391 | AA32: =AVERAGE(X32:X37) -> -3.3786863
A33: 45535 | B33: -3.9690314 | C33: -6.466996 | D33: -0.15323648 | E33: =VLOOKUP(A33,美林时钟!A18:AB277,28,TRUE) -> 衰退 | F33: 宽货币紧信用 | G33: 紧货币宽财政 | H33: 被动补库存 | I33: 产能周期下行,被动去库存 | J33: {=INDEX(股债表现与四个维度!$A:$T,MATCH($A33,股债表现与四个维度!$A:$A,0),MATCH(J$3&J$4,股债表现与四个维度!$2:$2&股债表现与四个维度!$3:$3,0))} -> 0.090909091 | K33: {=INDEX(股债表现与四个维度!$A:$T,MATCH($A33,股债表现与四个维度!$A:$A,0),MATCH(K$3&K$4,股债表现与四个维度!$2:$2&股债表现与四个维度!$3:$3,0))} -> 0.63636364 | L33: {=INDEX(股债表现与四个维度!$A:$T,MATCH($A33,股债表现与四个维度!$A:$A,0),MATCH(L$3&L$4,股债表现与四个维度!$2:$2&股债表现与四个维度!$3:$3,0))} -> -0.069767442 | M33: {=INDEX(股债表现与四个维度!$A:$T,MATCH($A33,股债表现与四个维度!$A:$A,0),MATCH(M$3&M$4,股债表现与四个维度!$2:$2&股债表现与四个维度!$3:$3,0))} -> 0.30232558 | N33: {=INDEX(股债表现与四个维度!$A:$T,MATCH($A33,股债表现与四个维度!$A:$A,0),MATCH(N$3&N$4,股债表现与四个维度!$2:$2&股债表现与四个维度!$3:$3,0))} -> -1 | O33: {=INDEX(股债表现与四个维度!$A:$T,MATCH($A33,股债表现与四个维度!$A:$A,0),MATCH(O$3&O$4,股债表现与四个维度!$2:$2&股债表现与四个维度!$3:$3,0))} -> 1 | P33: {=INDEX(股债表现与四个维度!$A:$T,MATCH($A33,股债表现与四个维度!$A:$A,0),MATCH(P$3&P$4,股债表现与四个维度!$2:$2&股债表现与四个维度!$3:$3,0))} -> -0.043478261 | Q33: {=INDEX(股债表现与四个维度!$A:$T,MATCH($A33,股债表现与四个维度!$A:$A,0),MATCH(Q$3&Q$4,股债表现与四个维度!$2:$2&股债表现与四个维度!$3:$3,0))} -> 0.34782609 | ... S33: {=INDEX(股债表现与四个维度!$A:$T,MATCH($A33,股债表现与四个维度!$A:$A,0),MATCH(S$3&S$4,股债表现与四个维度!$2:$2&股债表现与四个维度!$3:$3,0))} -> 0.42857143 | T33: =SUMIFS($J33:$S33,$J33:$S33,"<>"&"#N/A",$J$4:$S$4,T$4) -> -1.1651938 | U33: =SUMIFS($J33:$S33,$J33:$S33,"<>"&"#N/A",$J$4:$S$4,U$4) -> 2.7150867 | V33: =T33-U33 -> -3.8802805 | W33: =B33+C33 -> -10.436027 | X33: =C33+D33 -> -6.6202325 | Y33: =AVERAGE(V33:V38) -> -2.6485948 | Z33: =AVERAGE(W33:W38) -> -5.9851539 | AA33: =AVERAGE(X33:X38) -> -2.0758991
A34: 45504 | B34: 0.27106655 | C34: -1.745492 | D34: 0.29764466 | E34: =VLOOKUP(A34,美林时钟!A19:AB278,28,TRUE) -> 滞涨 | F34: 宽货币紧信用 | G34: 紧货币宽财政 | H34: 主动补库存 | I34: 产能周期下行,被动去库存 | J34: {=INDEX(股债表现与四个维度!$A:$T,MATCH($A34,股债表现与四个维度!$A:$A,0),MATCH(J$3&J$4,股债表现与四个维度!$2:$2&股债表现与四个维度!$3:$3,0))} -> 0.2 | K34: {=INDEX(股债表现与四个维度!$A:$T,MATCH($A34,股债表现与四个维度!$A:$A,0),MATCH(K$3&K$4,股债表现与四个维度!$2:$2&股债表现与四个维度!$3:$3,0))} -> 0.6 | L34: {=INDEX(股债表现与四个维度!$A:$T,MATCH($A34,股债表现与四个维度!$A:$A,0),MATCH(L$3&L$4,股债表现与四个维度!$2:$2&股债表现与四个维度!$3:$3,0))} -> -0.047619048 | M34: {=INDEX(股债表现与四个维度!$A:$T,MATCH($A34,股债表现与四个维度!$A:$A,0),MATCH(M$3&M$4,股债表现与四个维度!$2:$2&股债表现与四个维度!$3:$3,0))} -> 0.28571429 | N34: {=INDEX(股债表现与四个维度!$A:$T,MATCH($A34,股债表现与四个维度!$A:$A,0),MATCH(N$3&N$4,股债表现与四个维度!$2:$2&股债表现与四个维度!$3:$3,0))} -> 0.038461538 | O34: {=INDEX(股债表现与四个维度!$A:$T,MATCH($A34,股债表现与四个维度!$A:$A,0),MATCH(O$3&O$4,股债表现与四个维度!$2:$2&股债表现与四个维度!$3:$3,0))} -> 0.46153846 | P34: {=INDEX(股债表现与四个维度!$A:$T,MATCH($A34,股债表现与四个维度!$A:$A,0),MATCH(P$3&P$4,股债表现与四个维度!$2:$2&股债表现与四个维度!$3:$3,0))} -> 0 | Q34: {=INDEX(股债表现与四个维度!$A:$T,MATCH($A34,股债表现与四个维度!$A:$A,0),MATCH(Q$3&Q$4,股债表现与四个维度!$2:$2&股债表现与四个维度!$3:$3,0))} -> 0.31818182 | ... S34: {=INDEX(股债表现与四个维度!$A:$T,MATCH($A34,股债表现与四个维度!$A:$A,0),MATCH(S$3&S$4,股债表现与四个维度!$2:$2&股债表现与四个维度!$3:$3,0))} -> 0.42857143 | T34: =SUMIFS($J34:$S34,$J34:$S34,"<>"&"#N/A",$J$4:$S$4,T$4) -> 0.047985348 | U34: =SUMIFS($J34:$S34,$J34:$S34,"<>"&"#N/A",$J$4:$S$4,U$4) -> 2.094006 | V34: =T34-U34 -> -2.0460206 | W34: =B34+C34 -> -1.4744254 | X34: =C34+D34 -> -1.4478473 | Y34: =AVERAGE(V34:V39) -> -2.2078799 | Z34: =AVERAGE(W34:W39) -> -5.9292295 | AA34: =AVERAGE(X34:X39) -> -1.4462161
A35: 45473 | B35: -5.1273772 | C35: -4.7655639 | D35: 0.24279531 | E35: =VLOOKUP(A35,美林时钟!A20:AB279,28,TRUE) -> 滞涨 | F35: 宽货币紧信用 | G35: 紧货币宽财政 | H35: 被动补库存 | I35: 产能周期下行,主动补库存 | J35: {=INDEX(股债表现与四个维度!$A:$T,MATCH($A35,股债表现与四个维度!$A:$A,0),MATCH(J$3&J$4,股债表现与四个维度!$2:$2&股债表现与四个维度!$3:$3,0))} -> 0.33333333 | K35: {=INDEX(股债表现与四个维度!$A:$T,MATCH($A35,股债表现与四个维度!$A:$A,0),MATCH(K$3&K$4,股债表现与四个维度!$2:$2&股债表现与四个维度!$3:$3,0))} -> 0.77777778 | L35: {=INDEX(股债表现与四个维度!$A:$T,MATCH($A35,股债表现与四个维度!$A:$A,0),MATCH(L$3&L$4,股债表现与四个维度!$2:$2&股债表现与四个维度!$3:$3,0))} -> -0.024390244 | M35: {=INDEX(股债表现与四个维度!$A:$T,MATCH($A35,股债表现与四个维度!$A:$A,0),MATCH(M$3&M$4,股债表现与四个维度!$2:$2&股债表现与四个维度!$3:$3,0))} -> 0.31707317 | N35: {=INDEX(股债表现与四个维度!$A:$T,MATCH($A35,股债表现与四个维度!$A:$A,0),MATCH(N$3&N$4,股债表现与四个维度!$2:$2&股债表现与四个维度!$3:$3,0))} -> 0.038461538 | O35: {=INDEX(股债表现与四个维度!$A:$T,MATCH($A35,股债表现与四个维度!$A:$A,0),MATCH(O$3&O$4,股债表现与四个维度!$2:$2&股债表现与四个维度!$3:$3,0))} -> 0.46153846 | P35: {=INDEX(股债表现与四个维度!$A:$T,MATCH($A35,股债表现与四个维度!$A:$A,0),MATCH(P$3&P$4,股债表现与四个维度!$2:$2&股债表现与四个维度!$3:$3,0))} -> 0.047619048 | Q35: {=INDEX(股债表现与四个维度!$A:$T,MATCH($A35,股债表现与四个维度!$A:$A,0),MATCH(Q$3&Q$4,股债表现与四个维度!$2:$2&股债表现与四个维度!$3:$3,0))} -> 0.38095238 | ... S35: {=INDEX(股债表现与四个维度!$A:$T,MATCH($A35,股债表现与四个维度!$A:$A,0),MATCH(S$3&S$4,股债表现与四个维度!$2:$2&股债表现与四个维度!$3:$3,0))} -> 0.6 | T35: =SUMIFS($J35:$S35,$J35:$S35,"<>"&"#N/A",$J$4:$S$4,T$4) -> 0.29502368 | U35: =SUMIFS($J35:$S35,$J35:$S35,"<>"&"#N/A",$J$4:$S$4,U$4) -> 2.5373418 | V35: =T35-U35 -> -2.2423181 | W35: =B35+C35 -> -9.8929411 | X35: =C35+D35 -> -4.5227686 | Y35: =AVERAGE(V35:V40) -> -2.0208268 | Z35: =AVERAGE(W35:W40) -> -6.87476 | AA35: =AVERAGE(X35:X40) -> -1.6221612
A36: 45443 | B36: -1.2058617 | C36: 2.1025974 | D36: 0.39 | E36: 滞涨 | F36: 宽货币紧信用 | G36: 双宽 | H36: 被动补库存 | I36: 产能周期下行,主动补库存 | J36: {=INDEX(股债表现与四个维度!$A:$T,MATCH($A36,股债表现与四个维度!$A:$A,0),MATCH(J$3&J$4,股债表现与四个维度!$2:$2&股债表现与四个维度!$3:$3,0))} -> 0.25 | K36: {=INDEX(股债表现与四个维度!$A:$T,MATCH($A36,股债表现与四个维度!$A:$A,0),MATCH(K$3&K$4,股债表现与四个维度!$2:$2&股债表现与四个维度!$3:$3,0))} -> 0.75 | L36: {=INDEX(股债表现与四个维度!$A:$T,MATCH($A36,股债表现与四个维度!$A:$A,0),MATCH(L$3&L$4,股债表现与四个维度!$2:$2&股债表现与四个维度!$3:$3,0))} -> -0.05 | M36: {=INDEX(股债表现与四个维度!$A:$T,MATCH($A36,股债表现与四个维度!$A:$A,0),MATCH(M$3&M$4,股债表现与四个维度!$2:$2&股债表现与四个维度!$3:$3,0))} -> 0.3 | N36: {=INDEX(股债表现与四个维度!$A:$T,MATCH($A36,股债表现与四个维度!$A:$A,0),MATCH(N$3&N$4,股债表现与四个维度!$2:$2&股债表现与四个维度!$3:$3,0))} -> 0.038461538 | O36: {=INDEX(股债表现与四个维度!$A:$T,MATCH($A36,股债表现与四个维度!$A:$A,0),MATCH(O$3&O$4,股债表现与四个维度!$2:$2&股债表现与四个维度!$3:$3,0))} -> 0.46153846 | P36: {=INDEX(股债表现与四个维度!$A:$T,MATCH($A36,股债表现与四个维度!$A:$A,0),MATCH(P$3&P$4,股债表现与四个维度!$2:$2&股债表现与四个维度!$3:$3,0))} -> 0 | Q36: {=INDEX(股债表现与四个维度!$A:$T,MATCH($A36,股债表现与四个维度!$A:$A,0),MATCH(Q$3&Q$4,股债表现与四个维度!$2:$2&股债表现与四个维度!$3:$3,0))} -> 0.35 | ... S36: {=INDEX(股债表现与四个维度!$A:$T,MATCH($A36,股债表现与四个维度!$A:$A,0),MATCH(S$3&S$4,股债表现与四个维度!$2:$2&股债表现与四个维度!$3:$3,0))} -> 0.55555556 | T36: =SUMIFS($J36:$S36,$J36:$S36,"<>"&"#N/A",$J$4:$S$4,T$4) -> 0.016239316 | U36: =SUMIFS($J36:$S36,$J36:$S36,"<>"&"#N/A",$J$4:$S$4,U$4) -> 2.417094 | V36: =T36-U36 -> -2.4008547 | W36: =B36+C36 -> 0.89673569 | X36: =B36-D36 -> -1.5958617 | Y36: =AVERAGE(V36:V41) -> -1.849816 | Z36: =AVERAGE(W36:W41) -> -5.6043879 | AA36: =AVERAGE(X36:X41) -> -0.83161845
