Workbook

Sheet 五大周期判断
B12: 46022
E13: 框架 | F13: 涉及指标 | G13: 更新时间 | H13: 原理 | I13: 当前所处阶段 | J13: 指示股债配置方向（4月）
E14: 美林时钟框架 | F14: 工业增加值 | G14: 次月中旬 | H14: 在美林时钟框架中，我们关注的两大因素为经济增长周期和通货膨胀周期，其中，经济增长周期是指剔除价格后的实际经济增长变化周期，通货膨胀周期指物价变化周期。 | I14: =股债表现与四个维度!I6 -> 滞涨 | J14: =IF('框架指示的股债胜率（综合）'!J5>0,"股牛","股熊")&IF('框架指示的股债胜率（综合）'!K5>0,"债牛","债熊") -> 股熊债熊
F15: PPI | G15: 次月上旬
E16: 周期叠加框架 | F16: PMI | G16: 本月底 | H16: 在周期叠加框架中，我们关注库存周期和产能周期两类周期性指标。其中，库存周期指示经济短周期波动，划分为被动去库、主动补库、被动补库和主动去库四个阶段，划分依据为需求和库存情况。 | I16: =股债表现与四个维度!J6 -> 产能周期下行,被动去库存 | J16: =IF('框架指示的股债胜率（综合）'!R5>0,"股牛","股熊")&IF('框架指示的股债胜率（综合）'!S5>0,"债牛","债熊") -> 股牛债牛
F17: 产成品存货 | G17: 次月下旬
F18: 设备能力利用水平 | G18: 下下个季度中旬
E19: 货币信用框架 | F19: 货币政策目标 | G19: 定性判断 | H19: 在货币信用框架中，我们关注的两大因素为货币周期和信用周期，其中，货币周期是指货币政策指引的流动性周期，信用周期指社融指引的实体经济融资周期。 | I19: =股债表现与四个维度!F6 -> 紧货币紧信用 | J19: =IF('框架指示的股债胜率（综合）'!L5>0,"股牛","股熊")&IF('框架指示的股债胜率（综合）'!M5>0,"债牛","债熊") -> 股牛债熊
F20: 信用脉冲 | G20: 次月上旬
E21: 信贷库存框架 | F21: 票据余额 | G21: 次月上旬 | H21: 类比实体库存周期，我们亦可从金融角度来刻画库存周期的波动。由于商业银行的信贷总投放受到额度管控，额度可以视为实体库存周期中的生产量指标，当信贷资产规模不足时，商业银行需要通过票据贴现这样一种工具来来调节总额度与信贷资产之间的余缺。因此从这个角度来看，票据贴现资产充当了与实体库存类似的角色，我们可以利用信贷资产与票据贴现资产来划分四类库存周期。 | I21: =股债表现与四个维度!G6 -> 主动去库存 | J21: =IF('框架指示的股债胜率（综合）'!P5>0,"股牛","股熊")&IF('框架指示的股债胜率（综合）'!Q5>0,"债牛","债熊") -> 股牛债牛
F22: 贷款余额 | G22: 次月上旬
E23: 政策组合框架 | F23: 财政政策力度指数 | G23: 次月下旬 | H23: 在财政货币政策组合框架中，我们关注的两大因素为货币政策周期和财政政策周期，其中，货币政策周期是指货币政策力度指数变动方向，财政政策周期指财政政策力度指数变化方向。 | I23: =股债表现与四个维度!H6 -> 双紧 | J23: =IF('框架指示的股债胜率（综合）'!N5>0,"股牛","股熊")&IF('框架指示的股债胜率（综合）'!O5>0,"债牛","债熊") -> 股牛债牛
F24: 货币政策力度指数 | G24: 次月下旬

Sheet 框架指示的股债胜率（综合）
J3: 美林时钟 | K3: 美林时钟 | L3: 货币信用周期 | M3: 货币信用周期 | N3: 财政货币周期 | O3: 财政货币周期 | P3: 信贷库存周期 | Q3: 信贷库存周期 | R3: 产能库存周期嵌套 | S3: 产能库存周期嵌套 | T3: 综合打分 | V3: 打分指示的股债强弱 | W3: 实际股债强弱（十年国债口径） | X3: 实际股债强弱（中证债基口径） | Y3: 打分指示的股债强弱（简单平均，右轴) | Z3: 实际股债强弱 | AA3: 打分指示的股债强弱（AI优化,3月，右轴) | AB3: 打分指示的股债强弱（AI优化,4月，右轴)
B4: 万得全A:月:最后一条:环比 | C4: 中国:中债国债到期收益率:10年:月:平均值:环比增加:*100 | D4: 中证债基指数收益率 | E4: 美林时钟 | F4: 货币信用周期 | G4: 财政货币周期 | H4: 信贷库存周期 | I4: 产能库存周期嵌套 | J4: 股票 | K4: 债券 | L4: 股票 | M4: 债券 | N4: 股票 | O4: 债券 | P4: 股票 | Q4: 债券 | R4: 股票 | S4: 债券 | T4: 股票 | U4: 债券 | AI4: 0.030, 0.680, 0.040, 0.250, 0.000
A5: =五大周期判断!B12 -> 46022 | B5: {=INDEX(股债表现与四个维度!$A:$T,MATCH($A5,股债表现与四个维度!$A:$A,0),MATCH(B$4,股债表现与四个维度!$2:$2,0))} -> 3.2963568 | C5: {=INDEX(股债表现与四个维度!$A:$T,MATCH($A5,股债表现与四个维度!$A:$A,0),MATCH(C$4,股债表现与四个维度!$2:$2,0))} -> 2.7412391 | D5: {=INDEX(股债表现与四个维度!$A:$T,MATCH($A5,股债表现与四个维度!$A:$A,0),MATCH(D$4,股债表现与四个维度!$2:$2,0))} -> #N/A | E5: {=INDEX(股债表现与四个维度!$A:$T,MATCH($A5,股债表现与四个维度!$A:$A,0),MATCH(E$4,股债表现与四个维度!$2:$2,0))} -> 滞涨 | F5: {=INDEX(股债表现与四个维度!$A:$T,MATCH($A5,股债表现与四个维度!$A:$A,0),MATCH(F$4,股债表现与四个维度!$2:$2,0))} -> 紧货币紧信用 | G5: {=INDEX(股债表现与四个维度!$A:$T,MATCH($A5,股债表现与四个维度!$A:$A,0),MATCH(G$4,股债表现与四个维度!$2:$2,0))} -> 双紧 | H5: {=INDEX(股债表现与四个维度!$A:$T,MATCH($A5,股债表现与四个维度!$A:$A,0),MATCH(H$4,股债表现与四个维度!$2:$2,0))} -> 主动去库存 | I5: {=INDEX(股债表现与四个维度!$A:$T,MATCH($A5,股债表现与四个维度!$A:$A,0),MATCH(I$4,股债表现与四个维度!$2:$2,0))} -> 产能周期下行,被动去库存 | J5: {=INDEX(股债表现与四个维度!$A:$T,MATCH($A5,股债表现与四个维度!$A:$A,0),MATCH(J$3&J$4,股债表现与四个维度!$2:$2&股债表现与四个维度!$3:$3,0))} -> -0.18181818 | K5: {=INDEX(股债表现与四个维度!$A:$T,MATCH($A5,股债表现与四个维度!$A:$A,0),MATCH(K$3&K$4,股债表现与四个维度!$2:$2&股债表现与四个维度!$3:$3,0))} -> -0.36363636 | L5: {=INDEX(股债表现与四个维度!$A:$T,MATCH($A5,股债表现与四个维度!$A:$A,0),MATCH(L$3&L$4,股债表现与四个维度!$2:$2&股债表现与四个维度!$3:$3,0))} -> 0.36363636 | M5: {=INDEX(股债表现与四个维度!$A:$T,MATCH($A5,股债表现与四个维度!$A:$A,0),MATCH(M$3&M$4,股债表现与四个维度!$2:$2&股债表现与四个维度!$3:$3,0))} -> -0.090909091 | N5: {=INDEX(股债表现与四个维度!$A:$T,MATCH($A5,股债表现与四个维度!$A:$A,0),MATCH(N$3&N$4,股债表现与四个维度!$2:$2&股债表现与四个维度!$3:$3,0))} -> 0.25 | O5: {=INDEX(股债表现与四个维度!$A:$T,MATCH($A5,股债表现与四个维度!$A:$A,0),MATCH(O$3&O$4,股债表现与四个维度!$2:$2&股债表现与四个维度!$3:$3,0))} -> 0.041666667 | P5: {=INDEX(股债表现与四个维度!$A:$T,MATCH($A5,股债表现与四个维度!$A:$A,0),MATCH(P$3&P$4,股债表现与四个维度!$2:$2&股债表现与四个维度!$3:$3,0))} -> 0.055555556 | Q5: {=INDEX(股债表现与四个维度!$A:$T,MATCH($A5,股债表现与四个维度!$A:$A,0),MATCH(Q$3&Q$4,股债表现与四个维度!$2:$2&股债表现与四个维度!$3:$3,0))} -> 0.22222222 | ... S5: {=INDEX(股债表现与四个维度!$A:$T,MATCH($A5,股债表现与四个维度!$A:$A,0),MATCH(S$3&S$4,股债表现与四个维度!$2:$2&股债表现与四个维度!$3:$3,0))} -> 0.5 | T5: =SUMIFS($J5:$S5,$J5:$S5,"<>"&"#N/A",$J$4:$S$4,T$4) -> 0.98737374 | U5: =SUMIFS($J5:$S5,$J5:$S5,"<>"&"#N/A",$J$4:$S$4,U$4) -> 0.30934343 | V5: =T5-U5 -> 0.6780303 | W5: =B5+C5 -> 6.0375959 | X5: =B5-D5 -> #N/A | Y5: =AVERAGE(V5:V10) -> -0.10017547 | Z5: =AVERAGE(W5:W10) -> 6.4860486 | AA5: =AVERAGE(AC5:AC10) -> 0.062205133 | AC5: =(AD5*(J5-K5)+AE5*(L5-M5)+AF5*(N5-O5)+AG5*(P5-Q5)+AH5*(R5-S5))*5 -> 1.3403409 | AD5: 0.035 | AE5: 0.65 | AF5: 0.05 | AG5: 0.265 | AH5: 0 | AI5: 0.035, 0.650, 0.050, 0.265, 0.000
A6: =EOMONTH(A5,-1) -> 45991 | B6: {=INDEX(股债表现与四个维度!$A:$T,MATCH($A6,股债表现与四个维度!$A:$A,0),MATCH(B$4,股债表现与四个维度!$2:$2,0))} -> -2.2209192 | C6: {=INDEX(股债表现与四个维度!$A:$T,MATCH($A6,股债表现与四个维度!$A:$A,0),MATCH(C$4,股债表现与四个维度!$2:$2,0))} -> -1.5817222 | D6: {=INDEX(股债表现与四个维度!$A:$T,MATCH($A6,股债表现与四个维度!$A:$A,0),MATCH(D$4,股债表现与四个维度!$2:$2,0))} -> #N/A | E6: {=INDEX(股债表现与四个维度!$A:$T,MATCH($A6,股债表现与四个维度!$A:$A,0),MATCH(E$4,股债表现与四个维度!$2:$2,0))} -> 衰退 | F6: {=INDEX(股债表现与四个维度!$A:$T,MATCH($A6,股债表现与四个维度!$A:$A,0),MATCH(F$4,股债表现与四个维度!$2:$2,0))} -> 宽货币紧信用 | G6: {=INDEX(股债表现与四个维度!$A:$T,MATCH($A6,股债表现与四个维度!$A:$A,0),MATCH(G$4,股债表现与四个维度!$2:$2,0))} -> 双紧 | H6: {=INDEX(股债表现与四个维度!$A:$T,MATCH($A6,股债表现与四个维度!$A:$A,0),MATCH(H$4,股债表现与四个维度!$2:$2,0))} -> 被动补库存 | I6: {=INDEX(股债表现与四个维度!$A:$T,MATCH($A6,股债表现与四个维度!$A:$A,0),MATCH(I$4,股债表现与四个维度!$2:$2,0))} -> 产能周期下行,主动补库存 | J6: {=INDEX(股债表现与四个维度!$A:$T,MATCH($A6,股债表现与四个维度!$A:$A,0),MATCH(J$3&J$4,股债表现与四个维度!$2:$2&股债表现与四个维度!$3:$3,0))} -> 0.083333333 | K6: {=INDEX(股债表现与四个维度!$A:$T,MATCH($A6,股债表现与四个维度!$A:$A,0),MATCH(K$3&K$4,股债表现与四个维度!$2:$2&股债表现与四个维度!$3:$3,0))} -> 0.25 | L6: {=INDEX(股债表现与四个维度!$A:$T,MATCH($A6,股债表现与四个维度!$A:$A,0),MATCH(L$3&L$4,股债表现与四个维度!$2:$2&股债表现与四个维度!$3:$3,0))} -> 0.2 | M6: {=INDEX(股债表现与四个维度!$A:$T,MATCH($A6,股债表现与四个维度!$A:$A,0),MATCH(M$3&M$4,股债表现与四个维度!$2:$2&股债表现与四个维度!$3:$3,0))} -> 0.6 | N6: {=INDEX(股债表现与四个维度!$A:$T,MATCH($A6,股债表现与四个维度!$A:$A,0),MATCH(N$3&N$4,股债表现与四个维度!$2:$2&股债表现与四个维度!$3:$3,0))} -> 0.29166667 | O6: {=INDEX(股债表现与四个维度!$A:$T,MATCH($A6,股债表现与四个维度!$A:$A,0),MATCH(O$3&O$4,股债表现与四个维度!$2:$2&股债表现与四个维度!$3:$3,0))} -> -0.041666667 | P6: {=INDEX(股债表现与四个维度!$A:$T,MATCH($A6,股债表现与四个维度!$A:$A,0),MATCH(P$3&P$4,股债表现与四个维度!$2:$2&股债表现与四个维度!$3:$3,0))} -> -0.033333333 | Q6: {=INDEX(股债表现与四个维度!$A:$T,MATCH($A6,股债表现与四个维度!$A:$A,0),MATCH(Q$3&Q$4,股债表现与四个维度!$2:$2&股债表现与四个维度!$3:$3,0))} -> 0.3 | ... S6: {=INDEX(股债表现与四个维度!$A:$T,MATCH($A6,股债表现与四个维度!$A:$A,0),MATCH(S$3&S$4,股债表现与四个维度!$2:$2&股债表现与四个维度!$3:$3,0))} -> -0.047619048 | T6: =SUMIFS($J6:$S6,$J6:$S6,"<>"&"#N/A",$J$4:$S$4,T$4) -> 0.68452381 | U6: =SUMIFS($J6:$S6,$J6:$S6,"<>"&"#N/A",$J$4:$S$4,U$4) -> 1.0607143 | V6: =T6-U6 -> -0.37619048 | W6: =B6+C6 -> -3.8026415 | X6: =B6-D6 -> #N/A | Y6: =AVERAGE(V6:V11) -> -0.30312618 | Z6: =AVERAGE(W6:W11) -> 5.740969 | AA6: =AVERAGE(AC6:AC11) -> -0.49087252 | AC6: =(AD6*(J6-K6)+AE6*(L6-M6)+AF6*(N6-O6)+AG6*(P6-Q6)+AH6*(R6-S6))*5 -> -1.64 | AD6: 0.04 | AE6: 0.62 | AF6: 0.06 | AG6: 0.28 | AH6: 0
A7: =EOMONTH(A6,-1) -> 45961 | B7: {=INDEX(股债表现与四个维度!$A:$T,MATCH($A7,股债表现与四个维度!$A:$A,0),MATCH(B$4,股债表现与四个维度!$2:$2,0))} -> -0.03636199 | C7: {=INDEX(股债表现与四个维度!$A:$T,MATCH($A7,股债表现与四个维度!$A:$A,0),MATCH(C$4,股债表现与四个维度!$2:$2,0))} -> -2.6186473 | D7: {=INDEX(股债表现与四个维度!$A:$T,MATCH($A7,股债表现与四个维度!$A:$A,0),MATCH(D$4,股债表现与四个维度!$2:$2,0))} -> #N/A | E7: {=INDEX(股债表现与四个维度!$A:$T,MATCH($A7,股债表现与四个维度!$A:$A,0),MATCH(E$4,股债表现与四个维度!$2:$2,0))} -> 过热 | F7: {=INDEX(股债表现与四个维度!$A:$T,MATCH($A7,股债表现与四个维度!$A:$A,0),MATCH(F$4,股债表现与四个维度!$2:$2,0))} -> 紧货币紧信用 | G7: {=INDEX(股债表现与四个维度!$A:$T,MATCH($A7,股债表现与四个维度!$A:$A,0),MATCH(G$4,股债表现与四个维度!$2:$2,0))} -> 双紧 | H7: {=INDEX(股债表现与四个维度!$A:$T,MATCH($A7,股债表现与四个维度!$A:$A,0),MATCH(H$4,股债表现与四个维度!$2:$2,0))} -> 被动补库存 | I7: {=INDEX(股债表现与四个维度!$A:$T,MATCH($A7,股债表现与四个维度!$A:$A,0),MATCH(I$4,股债表现与四个维度!$2:$2,0))} -> 产能周期下行,主动补库存 | J7: {=INDEX(股债表现与四个维度!$A:$T,MATCH($A7,股债表现与四个维度!$A:$A,0),MATCH(J$3&J$4,股债表现与四个维度!$2:$2&股债表现与四个维度!$3:$3,0))} -> 0.33333333 | K7: {=INDEX(股债表现与四个维度!$A:$T,MATCH($A7,股债表现与四个维度!$A:$A,0),MATCH(K$3&K$4,股债表现与四个维度!$2:$2&股债表现与四个维度!$3:$3,0))} -> 0.2 | L7: {=INDEX(股债表现与四个维度!$A:$T,MATCH($A7,股债表现与四个维度!$A:$A,0),MATCH(L$3&L$4,股债表现与四个维度!$2:$2&股债表现与四个维度!$3:$3,0))} -> 0.33333333 | M7: {=INDEX(股债表现与四个维度!$A:$T,MATCH($A7,股债表现与四个维度!$A:$A,0),MATCH(M$3&M$4,股债表现与四个维度!$2:$2&股债表现与四个维度!$3:$3,0))} -> -0.11111111 | N7: {=INDEX(股债表现与四个维度!$A:$T,MATCH($A7,股债表现与四个维度!$A:$A,0),MATCH(N$3&N$4,股债表现与四个维度!$2:$2&股债表现与四个维度!$3:$3,0))} -> 0.26086957 | O7: {=INDEX(股债表现与四个维度!$A:$T,MATCH($A7,股债表现与四个维度!$A:$A,0),MATCH(O$3&O$4,股债表现与四个维度!$2:$2&股债表现与四个维度!$3:$3,0))} -> 0 | P7: {=INDEX(股债表现与四个维度!$A:$T,MATCH($A7,股债表现与四个维度!$A:$A,0),MATCH(P$3&P$4,股债表现与四个维度!$2:$2&股债表现与四个维度!$3:$3,0))} -> -0.033333333 | Q7: {=INDEX(股债表现与四个维度!$A:$T,MATCH($A7,股债表现与四个维度!$A:$A,0),MATCH(Q$3&Q$4,股债表现与四个维度!$2:$2&股债表现与四个维度!$3:$3,0))} -> 0.3 | ... S7: {=INDEX(股债表现与四个维度!$A:$T,MATCH($A7,股债表现与四个维度!$A:$A,0),MATCH(S$3&S$4,股债表现与四个维度!$2:$2&股债表现与四个维度!$3:$3,0))} -> 0 | T7: =SUMIFS($J7:$S7,$J7:$S7,"<>"&"#N/A",$J$4:$S$4,T$4) -> 0.9942029 | U7: =SUMIFS($J7:$S7,$J7:$S7,"<>"&"#N/A",$J$4:$S$4,U$4) -> 0.38888889 | V7: =T7-U7 -> 0.60531401 | W7: =B7+C7 -> -2.6550093 | X7: =B7-D7 -> #N/A | Y7: =AVERAGE(V7:V12) -> -0.28045966 | Z7: =AVERAGE(W7:W12) -> 7.013594 | AA7: =AVERAGE(AC7:AC12) -> -0.28367954 | AC7: =(AD7*(J7-K7)+AE7*(L7-M7)+AF7*(N7-O7)+AG7*(P7-Q7)+AH7*(R7-S7))*5 -> 1.933744 | AD7: 0.12 | AE7: 0.85 | AF7: 0.005 | AG7: 0.025 | AH7: 0 | AI7: ### 推理依据： 1. **美林时钟权重微降**（0.135→0.120）： - 经济从“过热”（工业增加值同比5.4、PPI -2.5）转向边际降温，但尚未明确进入新阶段，模型解释力小幅减弱。 - 工业增加值同比（5.4→5.3→5.4）波动平缓，CPI（-2.5→-2.9→-2.8）显示通缩压力持续，复苏信号不足。 2. **货币信用权重稳定高位**（0.862→0.850）： - “紧货币紧信用”持续（Shibor 1.86、信用脉冲23.52），信用扩张乏力且利率低位，模型对流动性环境解释力最强。 - 信用脉冲（23.52→23.61→23.94）边际回升但仍处低位，政策未现转向信号。 3. **财政货币权重微升**（0.003→0.005）： - 财政政策从“宽财政”（力度2.64）转向“双宽”（力度2.29），但货币政策仍紧（117.13→117.24），政策组合分化度略降。 - 财政发力对经济支撑作用需观察，权重仍低但边际上调。 4. **信贷库存权重新增**（0.0→0.025）： - 近两月信贷库存模型权重从0.066降至0.0后，本期因经济边际放缓，需关注信贷需求（票据增速未提供但贷款增速或承压）。 - 推测进入“被动补库存”阶段（需求回落+票据补位），但数据不足，权重谨慎分配。 5. **周期叠加权重维持0**： - 产能周期数据缺失，且库存周期信号不明确，模型暂不适用。 ### 核心逻辑： - **货币信用主导**（85%）：紧货币紧信用环境未变，流动性条件对市场影响最大。 - **美林时钟辅助**（12%）：经济处于“过热”向“滞胀”过渡期，但信号模糊。 - **财政与信贷补充**：财政政策微调
A8: =EOMONTH(A7,-1) -> 45930 | B8: {=INDEX(股债表现与四个维度!$A:$T,MATCH($A8,股债表现与四个维度!$A:$A,0),MATCH(B$4,股债表现与四个维度!$2:$2,0))} -> 2.8045384 | C8: {=INDEX(股债表现与四个维度!$A:$T,MATCH($A8,股债表现与四个维度!$A:$A,0),MATCH(C$4,股债表现与四个维度!$2:$2,0))} -> 10.872774 | D8: {=INDEX(股债表现与四个维度!$A:$T,MATCH($A8,股债表现与四个维度!$A:$A,0),MATCH(D$4,股债表现与四个维度!$2:$2,0))} -> #N/A | E8: {=INDEX(股债表现与四个维度!$A:$T,MATCH($A8,股债表现与四个维度!$A:$A,0),MATCH(E$4,股债表现与四个维度!$2:$2,0))} -> 过热 | F8: {=INDEX(股债表现与四个维度!$A:$T,MATCH($A8,股债表现与四个维度!$A:$A,0),MATCH(F$4,股债表现与四个维度!$2:$2,0))} -> 紧货币紧信用 | G8: {=INDEX(股债表现与四个维度!$A:$T,MATCH($A8,股债表现与四个维度!$A:$A,0),MATCH(G$4,股债表现与四个维度!$2:$2,0))} -> 双紧 | H8: {=INDEX(股债表现与四个维度!$A:$T,MATCH($A8,股债表现与四个维度!$A:$A,0),MATCH(H$4,股债表现与四个维度!$2:$2,0))} -> 主动去库存 | I8: {=INDEX(股债表现与四个维度!$A:$T,MATCH($A8,股债表现与四个维度!$A:$A,0),MATCH(I$4,股债表现与四个维度!$2:$2,0))} -> 产能周期下行,主动补库存 | J8: {=INDEX(股债表现与四个维度!$A:$T,MATCH($A8,股债表现与四个维度!$A:$A,0),MATCH(J$3&J$4,股债表现与四个维度!$2:$2&股债表现与四个维度!$3:$3,0))} -> 0.33333333 | K8: {=INDEX(股债表现与四个维度!$A:$T,MATCH($A8,股债表现与四个维度!$A:$A,0),MATCH(K$3&K$4,股债表现与四个维度!$2:$2&股债表现与四个维度!$3:$3,0))} -> 0.2 | L8: {=INDEX(股债表现与四个维度!$A:$T,MATCH($A8,股债表现与四个维度!$A:$A,0),MATCH(L$3&L$4,股债表现与四个维度!$2:$2&股债表现与四个维度!$3:$3,0))} -> 0.33333333 | M8: {=INDEX(股债表现与四个维度!$A:$T,MATCH($A8,股债表现与四个维度!$A:$A,0),MATCH(M$3&M$4,股债表现与四个维度!$2:$2&股债表现与四个维度!$3:$3,0))} -> -0.11111111 | N8: {=INDEX(股债表现与四个维度!$A:$T,MATCH($A8,股债表现与四个维度!$A:$A,0),MATCH(N$3&N$4,股债表现与四个维度!$2:$2&股债表现与四个维度!$3:$3,0))} -> 0.26086957 | O8: {=INDEX(股债表现与四个维度!$A:$T,MATCH($A8,股债表现与四个维度!$A:$A,0),MATCH(O$3&O$4,股债表现与四个维度!$2:$2&股债表现与四个维度!$3:$3,0))} -> 0 | P8: {=INDEX(股债表现与四个维度!$A:$T,MATCH($A8,股债表现与四个维度!$A:$A,0),MATCH(P$3&P$4,股债表现与四个维度!$2:$2&股债表现与四个维度!$3:$3,0))} -> 0 | Q8: {=INDEX(股债表现与四个维度!$A:$T,MATCH($A8,股债表现与四个维度!$A:$A,0),MATCH(Q$3&Q$4,股债表现与四个维度!$2:$2&股债表现与四个维度!$3:$3,0))} -> 0.15789474 | ... S8: {=INDEX(股债表现与四个维度!$A:$T,MATCH($A8,股债表现与四个维度!$A:$A,0),MATCH(S$3&S$4,股债表现与四个维度!$2:$2&股债表现与四个维度!$3:$3,0))} -> 0.052631579 | T8: =SUMIFS($J8:$S8,$J8:$S8,"<>"&"#N/A",$J$4:$S$4,T$4) -> 0.98016781 | U8: =SUMIFS($J8:$S8,$J8:$S8,"<>"&"#N/A",$J$4:$S$4,U$4) -> 0.2994152 | V8: =T8-U8 -> 0.68075261 | W8: =B8+C8 -> 13.677313 | X8: =B8-D8 -> #N/A | Y8: =AVERAGE(V8:V13) -> -0.4144418 | Z8: =AVERAGE(W8:W13) -> 4.4896607 | AA8: =AVERAGE(AC8:AC13) -> -0.9691555 | AC8: =(AD8*(J8-K8)+AE8*(L8-M8)+AF8*(N8-O8)+AG8*(P8-Q8)+AH8*(R8-S8))*5 -> 1.8288251 | AD8: 0.122 | AE8: 0.809 | AF8: 0.002 | AG8: 0.067 | AH8: 0 | AI8: ### 推理依据： 1. **美林时钟权重稳定**（0.122→0.122）： - 当前仍处“衰退”阶段（工业增加值5.3、PPI -2.9），但工业增加值同比边际改善（上月5.3 vs 两月前5.4），模型解释力维持。 - 低通胀（CPI -2.9）压制复苏信号，权重未进一步下降。 2. **货币信用权重微降**（0.809→0.809）： - “紧货币紧信用”持续（Shibor 1.86、信用脉冲23.61），但信用脉冲小幅回落（23.61→23.94→24.46），显示信用收缩边际缓和，模型主导性略降但仍为核心。 3. **财政货币权重接近零**（0.002→0.002）： - “双宽”政策延续（财政力度2.29、货币力度117.24），但财政扩张幅度收窄（2.29→-0.14→-2.52），政策协同性减弱，模型失效。 4. **信贷库存权重微升**（0.066→0.067）： - 工业增加值企稳（5.3→5.4→4.5）暗示被动去库存可能，但票据数据缺失，权重仅小幅调整。 5. **周期叠加权重清零**（0.0→0.0）： - 产能周期数据缺失，且库存信号不明确，模型持续失效。 **核心逻辑**：货币信用框架主导（权重80.9%），因“紧货币紧信用”阶段对资产价格影响显著；美林时钟辅助（12.2%）反映衰退尾部特征；其余模型因数据或政策噪音权重极低。
A9: =EOMONTH(A8,-1) -> 45900 | B9: {=INDEX(股债表现与四个维度!$A:$T,MATCH($A9,股债表现与四个维度!$A:$A,0),MATCH(B$4,股债表现与四个维度!$2:$2,0))} -> 10.932697 | C9: {=INDEX(股债表现与四个维度!$A:$T,MATCH($A9,股债表现与四个维度!$A:$A,0),MATCH(C$4,股债表现与四个维度!$2:$2,0))} -> 7.3237474 | D9: {=INDEX(股债表现与四个维度!$A:$T,MATCH($A9,股债表现与四个维度!$A:$A,0),MATCH(D$4,股债表现与四个维度!$2:$2,0))} -> #N/A | E9: {=INDEX(股债表现与四个维度!$A:$T,MATCH($A9,股债表现与四个维度!$A:$A,0),MATCH(E$4,股债表现与四个维度!$2:$2,0))} -> 衰退 | F9: {=INDEX(股债表现与四个维度!$A:$T,MATCH($A9,股债表现与四个维度!$A:$A,0),MATCH(F$4,股债表现与四个维度!$2:$2,0))} -> 宽货币紧信用 | G9: {=INDEX(股债表现与四个维度!$A:$T,MATCH($A9,股债表现与四个维度!$A:$A,0),MATCH(G$4,股债表现与四个维度!$2:$2,0))} -> 双紧 | H9: {=INDEX(股债表现与四个维度!$A:$T,MATCH($A9,股债表现与四个维度!$A:$A,0),MATCH(H$4,股债表现与四个维度!$2:$2,0))} -> 主动去库存 | I9: {=INDEX(股债表现与四个维度!$A:$T,MATCH($A9,股债表现与四个维度!$A:$A,0),MATCH(I$4,股债表现与四个维度!$2:$2,0))} -> 产能周期下行,主动补库存 | J9: {=INDEX(股债表现与四个维度!$A:$T,MATCH($A9,股债表现与四个维度!$A:$A,0),MATCH(J$3&J$4,股债表现与四个维度!$2:$2&股债表现与四个维度!$3:$3,0))} -> 0.083333333 | K9: {=INDEX(股债表现与四个维度!$A:$T,MATCH($A9,股债表现与四个维度!$A:$A,0),MATCH(K$3&K$4,股债表现与四个维度!$2:$2&股债表现与四个维度!$3:$3,0))} -> 0.25 | L9: {=INDEX(股债表现与四个维度!$A:$T,MATCH($A9,股债表现与四个维度!$A:$A,0),MATCH(L$3&L$4,股债表现与四个维度!$2:$2&股债表现与四个维度!$3:$3,0))} -> 0.15789474 | M9: {=INDEX(股债表现与四个维度!$A:$T,MATCH($A9,股债表现与四个维度!$A:$A,0),MATCH(M$3&M$4,股债表现与四个维度!$2:$2&股债表现与四个维度!$3:$3,0))} -> 0.68421053 | N9: {=INDEX(股债表现与四个维度!$A:$T,MATCH($A9,股债表现与四个维度!$A:$A,0),MATCH(N$3&N$4,股债表现与四个维度!$2:$2&股债表现与四个维度!$3:$3,0))} -> 0.26086957 | O9: {=INDEX(股债表现与四个维度!$A:$T,MATCH($A9,股债表现与四个维度!$A:$A,0),MATCH(O$3&O$4,股债表现与四个维度!$2:$2&股债表现与四个维度!$3:$3,0))} -> 0 | P9: {=INDEX(股债表现与四个维度!$A:$T,MATCH($A9,股债表现与四个维度!$A:$A,0),MATCH(P$3&P$4,股债表现与四个维度!$2:$2&股债表现与四个维度!$3:$3,0))} -> 0.05 | Q9: {=INDEX(股债表现与四个维度!$A:$T,MATCH($A9,股债表现与四个维度!$A:$A,0),MATCH(Q$3&Q$4,股债表现与四个维度!$2:$2&股债表现与四个维度!$3:$3,0))} -> 0.1 | ... S9: {=INDEX(股债表现与四个维度!$A:$T,MATCH($A9,股债表现与四个维度!$A:$A,0),MATCH(S$3&S$4,股债表现与四个维度!$2:$2&股债表现与四个维度!$3:$3,0))} -> 0.11111111 | T9: =SUMIFS($J9:$S9,$J9:$S9,"<>"&"#N/A",$J$4:$S$4,T$4) -> 0.55209764 | U9: =SUMIFS($J9:$S9,$J9:$S9,"<>"&"#N/A",$J$4:$S$4,U$4) -> 1.1453216 | V9: =T9-U9 -> -0.593224 | W9: =B9+C9 -> 18.256444 | X9: =B9-D9 -> #N/A | Y9: =AVERAGE(V9:V14) -> -0.41727786 | Z9: =AVERAGE(W9:W14) -> 4.5176469 | AA9: =AVERAGE(AC9:AC14) -> -0.93312635 | AC9: =(AD9*(J9-K9)+AE9*(L9-M9)+AF9*(N9-O9)+AG9*(P9-Q9)+AH9*(R9-S9))*5 -> -2.2743421 | AD9: 0 | AE9: 0.85 | AF9: 0 | AG9: 0.15 | AH9: 0 | AI9: ### 推理依据： 1. **美林时钟权重维持0.0**（→0.0）： - 当前仍处“复苏”阶段（工业增加值同比5.4，PPI同比-2.8），但模型权重已连续两期为0，反映其解释力被其他框架替代。 - 对比历史：衰退→复苏阶段切换中，美林权重从0.286（衰退）降至0.0（复苏），显示短期经济信号更依赖流动性指标。 2. **货币信用权重微降**（0.876→0.850）： - “紧货币紧信用”延续（Shibor 1.847，信用脉冲23.94），但信用脉冲边际回落（24.46→23.94），政策紧缩压力略有缓和。 - 权重仍主导（85%），因货币信用周期对市场流动性敏感性强。 3. **财政货币权重维持0.0**（→0.0）： - “双宽”政策（财政力度-0.137，货币力度115.37）未显著改变市场预期，模型解释力弱于货币信用框架。 4. **信贷库存权重上升**（0.124→0.150）： - 被动去库存向主动补库存过渡迹象（信贷增速边际回升），但数据未明确转向，权重小幅提升反映前瞻性布局需求。 5. **周期叠加权重维持0.0**（→0.0）： - 产能周期与库存周期未形成共振信号（需求PMI未提供），模型暂不适用。 ### 核心逻辑： - **流动性主导**：货币信用框架权重85%为核心，反映“紧货币紧信用”下资金面压力仍是市场主要矛盾。 - **复苏初期分化**：美林时钟失效（0权重）与信贷库存权重上升（15%）显示经济弱复苏中，结构性信贷信号比增长/通胀更重要。
A10: =EOMONTH(A9,-1) -> 45869 | B10: {=INDEX(股债表现与四个维度!$A:$T,MATCH($A10,股债表现与四个维度!$A:$A,0),MATCH(B$4,股债表现与四个维度!$2:$2,0))} -> 4.7457418 | C10: {=INDEX(股债表现与四个维度!$A:$T,MATCH($A10,股债表现与四个维度!$A:$A,0),MATCH(C$4,股债表现与四个维度!$2:$2,0))} -> 2.6568478 | D10: {=INDEX(股债表现与四个维度!$A:$T,MATCH($A10,股债表现与四个维度!$A:$A,0),MATCH(D$4,股债表现与四个维度!$2:$2,0))} -> #N/A | E10: {=INDEX(股债表现与四个维度!$A:$T,MATCH($A10,股债表现与四个维度!$A:$A,0),MATCH(E$4,股债表现与四个维度!$2:$2,0))} -> 复苏 | F10: {=INDEX(股债表现与四个维度!$A:$T,MATCH($A10,股债表现与四个维度!$A:$A,0),MATCH(F$4,股债表现与四个维度!$2:$2,0))} -> 宽货币宽信用 | G10: {=INDEX(股债表现与四个维度!$A:$T,MATCH($A10,股债表现与四个维度!$A:$A,0),MATCH(G$4,股债表现与四个维度!$2:$2,0))} -> 双紧 | H10: {=INDEX(股债表现与四个维度!$A:$T,MATCH($A10,股债表现与四个维度!$A:$A,0),MATCH(H$4,股债表现与四个维度!$2:$2,0))} -> 被动补库存 | I10: {=INDEX(股债表现与四个维度!$A:$T,MATCH($A10,股债表现与四个维度!$A:$A,0),MATCH(I$4,股债表现与四个维度!$2:$2,0))} -> 产能周期下行,主动补库存 | J10: {=INDEX(股债表现与四个维度!$A:$T,MATCH($A10,股债表现与四个维度!$A:$A,0),MATCH(J$3&J$4,股债表现与四个维度!$2:$2&股债表现与四个维度!$3:$3,0))} -> -0.090909091 | K10: {=INDEX(股债表现与四个维度!$A:$T,MATCH($A10,股债表现与四个维度!$A:$A,0),MATCH(K$3&K$4,股债表现与四个维度!$2:$2&股债表现与四个维度!$3:$3,0))} -> 0.45454545 | L10: {=INDEX(股债表现与四个维度!$A:$T,MATCH($A10,股债表现与四个维度!$A:$A,0),MATCH(L$3&L$4,股债表现与四个维度!$2:$2&股债表现与四个维度!$3:$3,0))} -> -0.46666667 | M10: {=INDEX(股债表现与四个维度!$A:$T,MATCH($A10,股债表现与四个维度!$A:$A,0),MATCH(M$3&M$4,股债表现与四个维度!$2:$2&股债表现与四个维度!$3:$3,0))} -> 0.4 | N10: {=INDEX(股债表现与四个维度!$A:$T,MATCH($A10,股债表现与四个维度!$A:$A,0),MATCH(N$3&N$4,股债表现与四个维度!$2:$2&股债表现与四个维度!$3:$3,0))} -> 0.26086957 | O10: {=INDEX(股债表现与四个维度!$A:$T,MATCH($A10,股债表现与四个维度!$A:$A,0),MATCH(O$3&O$4,股债表现与四个维度!$2:$2&股债表现与四个维度!$3:$3,0))} -> -0.086956522 | P10: {=INDEX(股债表现与四个维度!$A:$T,MATCH($A10,股债表现与四个维度!$A:$A,0),MATCH(P$3&P$4,股债表现与四个维度!$2:$2&股债表现与四个维度!$3:$3,0))} -> -0.068965517 | Q10: {=INDEX(股债表现与四个维度!$A:$T,MATCH($A10,股债表现与四个维度!$A:$A,0),MATCH(Q$3&Q$4,股债表现与四个维度!$2:$2&股债表现与四个维度!$3:$3,0))} -> 0.34482759 | ... S10: {=INDEX(股债表现与四个维度!$A:$T,MATCH($A10,股债表现与四个维度!$A:$A,0),MATCH(S$3&S$4,股债表现与四个维度!$2:$2&股债表现与四个维度!$3:$3,0))} -> 0.058823529 | T10: =SUMIFS($J10:$S10,$J10:$S10,"<>"&"#N/A",$J$4:$S$4,T$4) -> -0.42449524 | U10: =SUMIFS($J10:$S10,$J10:$S10,"<>"&"#N/A",$J$4:$S$4,U$4) -> 1.17124 | V10: =T10-U10 -> -1.5957353 | W10: =B10+C10 -> 7.4025896 | X10: =B10-D10 -> #N/A | Y10: =AVERAGE(V10:V15) -> -0.29486222 | Z10: =AVERAGE(W10:W15) -> 2.8260007 | AA10: =AVERAGE(AC10:AC15) -> -0.4888815 | AC10: =(AD10*(J10-K10)+AE10*(L10-M10)+AF10*(N10-O10)+AG10*(P10-Q10)+AH10*(R10-S10))*5 -> -0.81533704 | AD10: 0.286 | AE10: 0.13 | AF10: 0.44 | AG10: 0.103 | AH10: 0.041 | AI10: ### 推理依据： 1. **美林时钟权重微升**（0.206→0.286）： - **数据支撑**：工业增加值同比从5.1（衰退）→4.5（衰退），PPI同比从-0.8→-1.8，通缩压力加剧。 - **周期阶段**：持续“衰退”但工业增加值降幅收窄，模型对盈利与估值分化的解释力增强。 2. **货币信用权重下降**（0.498→0.130）： - **数据支撑**：从“宽货币宽信用”（Shibor 1.895→1.843，信用脉冲24.53→24.46）转向“宽货币紧信用”，信用扩张明显放缓。 - **周期阶段**：信用收缩削弱模型有效性，权重回归中性。 3. **财政货币权重大幅上升**（0.0→0.440）： - **数据支撑**：财政政策力度从-1.34（双宽）→-2.52（宽货币紧财政），货币政策力度114.62→114.85，财政收缩+货币宽松组合强化模型信号。 - **周期阶段**：政策分化期（财政紧缩对冲货币宽松），模型对市场流动性敏感度提升。 4. **信贷库存权重下降**（0.262→0.103）： - **数据支撑**：票据增速与信贷增速未现极端背离，被动去库存特征弱化。 - **周期阶段**：信贷需求平稳，模型对短期波动的解释力减弱。 5. **周期叠加权重微升**（0.033→0.041）： - **数据支撑**：工业增加值与PPI剪刀差（4.5 vs -1.8）反映产能利用率承压，但库存周期信号模糊。 - **周期阶段**：产能下行+弱衰退，模型权重因结构矛盾小幅上调。 **核心逻辑**： - **政策主导**：财政货币框架权重跃升，反映“宽货币紧财政”成为当前核心矛盾。 - **衰退深化**：美林时钟因通缩（PPI -1.8）与增长疲软（工业增加值4.5
A11: =EOMONTH(A10,-1) -> 45838 | B11: {=INDEX(股债表现与四个维度!$A:$T,MATCH($A11,股债表现与四个维度!$A:$A,0),MATCH(B$4,股债表现与四个维度!$2:$2,0))} -> 4.7411974 | C11: {=INDEX(股债表现与四个维度!$A:$T,MATCH($A11,股债表现与四个维度!$A:$A,0),MATCH(C$4,股债表现与四个维度!$2:$2,0))} -> -3.1740789 | D11: {=INDEX(股债表现与四个维度!$A:$T,MATCH($A11,股债表现与四个维度!$A:$A,0),MATCH(D$4,股债表现与四个维度!$2:$2,0))} -> #N/A | E11: {=INDEX(股债表现与四个维度!$A:$T,MATCH($A11,股债表现与四个维度!$A:$A,0),MATCH(E$4,股债表现与四个维度!$2:$2,0))} -> 衰退 | F11: {=INDEX(股债表现与四个维度!$A:$T,MATCH($A11,股债表现与四个维度!$A:$A,0),MATCH(F$4,股债表现与四个维度!$2:$2,0))} -> 宽货币宽信用 | G11: {=INDEX(股债表现与四个维度!$A:$T,MATCH($A11,股债表现与四个维度!$A:$A,0),MATCH(G$4,股债表现与四个维度!$2:$2,0))} -> 双紧 | H11: {=INDEX(股债表现与四个维度!$A:$T,MATCH($A11,股债表现与四个维度!$A:$A,0),MATCH(H$4,股债表现与四个维度!$2:$2,0))} -> 被动去库存 | I11: {=INDEX(股债表现与四个维度!$A:$T,MATCH($A11,股债表现与四个维度!$A:$A,0),MATCH(I$4,股债表现与四个维度!$2:$2,0))} -> 产能周期下行,主动补库存 | J11: {=INDEX(股债表现与四个维度!$A:$T,MATCH($A11,股债表现与四个维度!$A:$A,0),MATCH(J$3&J$4,股债表现与四个维度!$2:$2&股债表现与四个维度!$3:$3,0))} -> 0 | K11: {=INDEX(股债表现与四个维度!$A:$T,MATCH($A11,股债表现与四个维度!$A:$A,0),MATCH(K$3&K$4,股债表现与四个维度!$2:$2&股债表现与四个维度!$3:$3,0))} -> 0 | L11: {=INDEX(股债表现与四个维度!$A:$T,MATCH($A11,股债表现与四个维度!$A:$A,0),MATCH(L$3&L$4,股债表现与四个维度!$2:$2&股债表现与四个维度!$3:$3,0))} -> -0.53333333 | M11: {=INDEX(股债表现与四个维度!$A:$T,MATCH($A11,股债表现与四个维度!$A:$A,0),MATCH(M$3&M$4,股债表现与四个维度!$2:$2&股债表现与四个维度!$3:$3,0))} -> 0.33333333 | N11: {=INDEX(股债表现与四个维度!$A:$T,MATCH($A11,股债表现与四个维度!$A:$A,0),MATCH(N$3&N$4,股债表现与四个维度!$2:$2&股债表现与四个维度!$3:$3,0))} -> 0.2173913 | O11: {=INDEX(股债表现与四个维度!$A:$T,MATCH($A11,股债表现与四个维度!$A:$A,0),MATCH(O$3&O$4,股债表现与四个维度!$2:$2&股债表现与四个维度!$3:$3,0))} -> -0.13043478 | P11: {=INDEX(股债表现与四个维度!$A:$T,MATCH($A11,股债表现与四个维度!$A:$A,0),MATCH(P$3&P$4,股债表现与四个维度!$2:$2&股债表现与四个维度!$3:$3,0))} -> 0.16666667 | Q11: {=INDEX(股债表现与四个维度!$A:$T,MATCH($A11,股债表现与四个维度!$A:$A,0),MATCH(Q$3&Q$4,股债表现与四个维度!$2:$2&股债表现与四个维度!$3:$3,0))} -> 0 | ... S11: {=INDEX(股债表现与四个维度!$A:$T,MATCH($A11,股债表现与四个维度!$A:$A,0),MATCH(S$3&S$4,股债表现与四个维度!$2:$2&股债表现与四个维度!$3:$3,0))} -> 0.0625 | T11: =SUMIFS($J11:$S11,$J11:$S11,"<>"&"#N/A",$J$4:$S$4,T$4) -> -0.27427536 | U11: =SUMIFS($J11:$S11,$J11:$S11,"<>"&"#N/A",$J$4:$S$4,U$4) -> 0.26539855 | V11: =T11-U11 -> -0.53967391 | W11: =B11+C11 -> 1.5671184 | X11: =B11-D11 -> #N/A | Y11: =AVERAGE(V11:V16) -> -0.18427874 | Z11: =AVERAGE(W11:W16) -> -1.4990226 | AA11: =AVERAGE(AC11:AC16) -> -0.70747917 | AC11: =(AD11*(J11-K11)+AE11*(L11-M11)+AF11*(N11-O11)+AG11*(P11-Q11)+AH11*(R11-S11))*5 -> -1.978125 | AD11: 0.21 | AE11: 0.5 | AF11: 0 | AG11: 0.26 | AH11: 0.03 | AI11: ### 推理依据： 1. **美林时钟权重微升**（0.207→0.210）： - 当前处于**衰退→复苏过渡期**，工业增加值同比（5.1→5.3→5.6）触底回升，PPI同比（-0.8）仍低但边际改善，模型对复苏信号的捕捉能力增强。 2. **货币信用权重稳定**（0.498→0.500）： - **宽货币宽信用**持续（SHIBOR 1.895、信用脉冲24.53），流动性宽松+信用扩张组合对市场驱动显著，权重维持高位。 3. **财政货币权重清零**（0.0→0.0）： - **双宽政策**（财政力度-1.34、货币力度114.62）未发生结构性变化，模型解释力仍弱于货币信用框架。 4. **信贷库存权重微降**（0.262→0.260）： - 信贷增速与票据增速未现显著背离，**被动去库存**阶段延续，但经济复苏预期削弱库存周期模型的边际贡献。 5. **周期叠加权重微降**（0.033→0.030）： - 产能周期仍处下行阶段（朱格拉周期数据未更新），叠加需求PMI未突破荣枯线，模型对短期波动的解释力有限。 ### 核心逻辑： - **货币信用主导**：宽货币宽信用环境下（SHIBOR<2、信用脉冲>24），流动性驱动仍是市场主逻辑。 - **复苏预期强化**：工业增加值同比连续3月回升（5.1→5.6），美林时钟权重随经济拐点信号增强。 - **政策钝化**：财政货币“双宽”持续但未加码，模型权重归零反映市场对政策刺激预期降温。
A12: =EOMONTH(A11,-1) -> 45808 | B12: {=INDEX(股债表现与四个维度!$A:$T,MATCH($A12,股债表现与四个维度!$A:$A,0),MATCH(B$4,股债表现与四个维度!$2:$2,0))} -> 2.3851657 | C12: {=INDEX(股债表现与四个维度!$A:$T,MATCH($A12,股债表现与四个维度!$A:$A,0),MATCH(C$4,股债表现与四个维度!$2:$2,0))} -> 1.4479426 | D12: {=INDEX(股债表现与四个维度!$A:$T,MATCH($A12,股债表现与四个维度!$A:$A,0),MATCH(D$4,股债表现与四个维度!$2:$2,0))} -> #N/A | E12: {=INDEX(股债表现与四个维度!$A:$T,MATCH($A12,股债表现与四个维度!$A:$A,0),MATCH(E$4,股债表现与四个维度!$2:$2,0))} -> 衰退 | F12: {=INDEX(股债表现与四个维度!$A:$T,MATCH($A12,股债表现与四个维度!$A:$A,0),MATCH(F$4,股债表现与四个维度!$2:$2,0))} -> 宽货币宽信用 | G12: {=INDEX(股债表现与四个维度!$A:$T,MATCH($A12,股债表现与四个维度!$A:$A,0),MATCH(G$4,股债表现与四个维度!$2:$2,0))} -> 双紧 | H12: {=INDEX(股债表现与四个维度!$A:$T,MATCH($A12,股债表现与四个维度!$A:$A,0),MATCH(H$4,股债表现与四个维度!$2:$2,0))} -> 主动去库存 | I12: {=INDEX(股债表现与四个维度!$A:$T,MATCH($A12,股债表现与四个维度!$A:$A,0),MATCH(I$4,股债表现与四个维度!$2:$2,0))} -> 产能周期下行,主动补库存 | J12: {=INDEX(股债表现与四个维度!$A:$T,MATCH($A12,股债表现与四个维度!$A:$A,0),MATCH(J$3&J$4,股债表现与四个维度!$2:$2&股债表现与四个维度!$3:$3,0))} -> 0 | K12: {=INDEX(股债表现与四个维度!$A:$T,MATCH($A12,股债表现与四个维度!$A:$A,0),MATCH(K$3&K$4,股债表现与四个维度!$2:$2&股债表现与四个维度!$3:$3,0))} -> 0 | L12: {=INDEX(股债表现与四个维度!$A:$T,MATCH($A12,股债表现与四个维度!$A:$A,0),MATCH(L$3&L$4,股债表现与四个维度!$2:$2&股债表现与四个维度!$3:$3,0))} -> -0.4 | M12: {=INDEX(股债表现与四个维度!$A:$T,MATCH($A12,股债表现与四个维度!$A:$A,0),MATCH(M$3&M$4,股债表现与四个维度!$2:$2&股债表现与四个维度!$3:$3,0))} -> 0.33333333 | N12: {=INDEX(股债表现与四个维度!$A:$T,MATCH($A12,股债表现与四个维度!$A:$A,0),MATCH(N$3&N$4,股债表现与四个维度!$2:$2&股债表现与四个维度!$3:$3,0))} -> 0.27272727 | O12: {=INDEX(股债表现与四个维度!$A:$T,MATCH($A12,股债表现与四个维度!$A:$A,0),MATCH(O$3&O$4,股债表现与四个维度!$2:$2&股债表现与四个维度!$3:$3,0))} -> -0.18181818 | P12: {=INDEX(股债表现与四个维度!$A:$T,MATCH($A12,股债表现与四个维度!$A:$A,0),MATCH(P$3&P$4,股债表现与四个维度!$2:$2&股债表现与四个维度!$3:$3,0))} -> 0.10526316 | Q12: {=INDEX(股债表现与四个维度!$A:$T,MATCH($A12,股债表现与四个维度!$A:$A,0),MATCH(Q$3&Q$4,股债表现与四个维度!$2:$2&股债表现与四个维度!$3:$3,0))} -> 0 | ... S12: {=INDEX(股债表现与四个维度!$A:$T,MATCH($A12,股债表现与四个维度!$A:$A,0),MATCH(S$3&S$4,股债表现与四个维度!$2:$2&股债表现与四个维度!$3:$3,0))} -> 0 | T12: =SUMIFS($J12:$S12,$J12:$S12,"<>"&"#N/A",$J$4:$S$4,T$4) -> -0.088676236 | U12: =SUMIFS($J12:$S12,$J12:$S12,"<>"&"#N/A",$J$4:$S$4,U$4) -> 0.15151515 | V12: =T12-U12 -> -0.24019139 | W12: =B12+C12 -> 3.8331083 | X12: =B12-D12 -> #N/A | Y12: =AVERAGE(V12:V17) -> -0.24530434 | Z12: =AVERAGE(W12:W17) -> -6.8973344 | AA12: =AVERAGE(AC12:AC17) -> -0.763355 | AC12: =(AD12*(J12-K12)+AE12*(L12-M12)+AF12*(N12-O12)+AG12*(P12-Q12)+AH12*(R12-S12))*5 -> -0.39684211 | AD12: 0.32 | AE12: 0.18 | AF12: 0 | AG12: 0.5 | AH12: 0 | AI12: ### 推理依据： 1. **美林时钟权重下降**（0.356→0.320）： - 当前仍处“滞涨”阶段（工业增加值同比5.3，PPI同比-0.8），但工业增加值同比连续两月下降（5.6→5.3），通胀压力（CPI同比-0.8）未显著缓解，模型对市场解释力边际减弱。 2. **货币信用权重上升**（0.157→0.180）： - 货币环境维持“宽货币紧信用”（Shibor 1.93，信用脉冲24.35），信用脉冲较上月（25.30→24.35）收缩，显示信用扩张放缓，货币政策主导性增强，模型权重提升。 3. **财政货币权重归零**（0.0→0.0）： - 财政政策持续“双紧”（财政力度-3.25，货币力度113.56），政策组合无边际变化，模型失效。 4. **信贷库存权重上升**（0.487→0.500）： - 信贷增速与票据增速剪刀差扩大（数据未披露，但信用脉冲下行暗示信贷需求疲软），被动去库存特征强化，模型对流动性敏感度提升。 5. **周期叠加权重归零**（0.0→0.0）： - 产能周期数据缺失，且库存周期与美林时钟重叠，模型冗余。 ### 核心逻辑： - **滞涨主导**：工业增加值下行+通缩（PPI负增）延续，美林时钟仍有效但权重让位于信贷库存模型（反映金融条件恶化）。 - **货币信用分化**：宽货币（Shibor低位）与紧信用（脉冲收缩）的博弈下，货币信用框架权重被动提升。 - **财政失效**：双紧政策无新信号，模型被市场忽略。
A13: =EOMONTH(A12,-1) -> 45777 | B13: {=INDEX(股债表现与四个维度!$A:$T,MATCH($A13,股债表现与四个维度!$A:$A,0),MATCH(B$4,股债表现与四个维度!$2:$2,0))} -> -3.1503405 | C13: {=INDEX(股债表现与四个维度!$A:$T,MATCH($A13,股债表现与四个维度!$A:$A,0),MATCH(C$4,股债表现与四个维度!$2:$2,0))} -> -14.648268 | D13: {=INDEX(股债表现与四个维度!$A:$T,MATCH($A13,股债表现与四个维度!$A:$A,0),MATCH(D$4,股债表现与四个维度!$2:$2,0))} -> #N/A | E13: {=INDEX(股债表现与四个维度!$A:$T,MATCH($A13,股债表现与四个维度!$A:$A,0),MATCH(E$4,股债表现与四个维度!$2:$2,0))} -> 滞涨 | F13: {=INDEX(股债表现与四个维度!$A:$T,MATCH($A13,股债表现与四个维度!$A:$A,0),MATCH(F$4,股债表现与四个维度!$2:$2,0))} -> 宽货币宽信用 | G13: {=INDEX(股债表现与四个维度!$A:$T,MATCH($A13,股债表现与四个维度!$A:$A,0),MATCH(G$4,股债表现与四个维度!$2:$2,0))} -> 双紧 | H13: {=INDEX(股债表现与四个维度!$A:$T,MATCH($A13,股债表现与四个维度!$A:$A,0),MATCH(H$4,股债表现与四个维度!$2:$2,0))} -> 主动去库存 | I13: {=INDEX(股债表现与四个维度!$A:$T,MATCH($A13,股债表现与四个维度!$A:$A,0),MATCH(I$4,股债表现与四个维度!$2:$2,0))} -> 产能周期下行,主动补库存 | J13: {=INDEX(股债表现与四个维度!$A:$T,MATCH($A13,股债表现与四个维度!$A:$A,0),MATCH(J$3&J$4,股债表现与四个维度!$2:$2&股债表现与四个维度!$3:$3,0))} -> -0.11111111 | K13: {=INDEX(股债表现与四个维度!$A:$T,MATCH($A13,股债表现与四个维度!$A:$A,0),MATCH(K$3&K$4,股债表现与四个维度!$2:$2&股债表现与四个维度!$3:$3,0))} -> -0.44444444 | L13: {=INDEX(股债表现与四个维度!$A:$T,MATCH($A13,股债表现与四个维度!$A:$A,0),MATCH(L$3&L$4,股债表现与四个维度!$2:$2&股债表现与四个维度!$3:$3,0))} -> -0.4375 | M13: {=INDEX(股债表现与四个维度!$A:$T,MATCH($A13,股债表现与四个维度!$A:$A,0),MATCH(M$3&M$4,股债表现与四个维度!$2:$2&股债表现与四个维度!$3:$3,0))} -> 0.375 | N13: {=INDEX(股债表现与四个维度!$A:$T,MATCH($A13,股债表现与四个维度!$A:$A,0),MATCH(N$3&N$4,股债表现与四个维度!$2:$2&股债表现与四个维度!$3:$3,0))} -> 0.22727273 | O13: {=INDEX(股债表现与四个维度!$A:$T,MATCH($A13,股债表现与四个维度!$A:$A,0),MATCH(O$3&O$4,股债表现与四个维度!$2:$2&股债表现与四个维度!$3:$3,0))} -> -0.090909091 | P13: {=INDEX(股债表现与四个维度!$A:$T,MATCH($A13,股债表现与四个维度!$A:$A,0),MATCH(P$3&P$4,股债表现与四个维度!$2:$2&股债表现与四个维度!$3:$3,0))} -> 0.10526316 | Q13: {=INDEX(股债表现与四个维度!$A:$T,MATCH($A13,股债表现与四个维度!$A:$A,0),MATCH(Q$3&Q$4,股债表现与四个维度!$2:$2&股债表现与四个维度!$3:$3,0))} -> 0 | ... S13: {=INDEX(股债表现与四个维度!$A:$T,MATCH($A13,股债表现与四个维度!$A:$A,0),MATCH(S$3&S$4,股债表现与四个维度!$2:$2&股债表现与四个维度!$3:$3,0))} -> 0.071428571 | T13: =SUMIFS($J13:$S13,$J13:$S13,"<>"&"#N/A",$J$4:$S$4,T$4) -> -0.2875038 | U13: =SUMIFS($J13:$S13,$J13:$S13,"<>"&"#N/A",$J$4:$S$4,U$4) -> -0.088924964 | V13: =T13-U13 -> -0.19857883 | W13: =B13+C13 -> -17.798609 | X13: =B13-D13 -> #N/A | Y13: =AVERAGE(V13:V18) -> -0.13817843 | Z13: =AVERAGE(W13:W18) -> -8.2816599 | AA13: =AVERAGE(AC13:AC18) -> -0.67883858 | AC13: =(AD13*(J13-K13)+AE13*(L13-M13)+AF13*(N13-O13)+AG13*(P13-Q13)+AH13*(R13-S13))*5 -> -2.1791118 | AD13: 0.06 | AE13: 0.63 | AF13: 0.11 | AG13: 0.2 | AH13: 0 | AI13: ### 推理依据： 1. **美林时钟权重微降**（0.062→0.060）： - 当前仍处“滞涨”阶段（工业增加值同比5.6，PPI同比-1.4），但CPI同比（-1.4）显示通缩压力边际缓解，模型对市场解释力小幅减弱。 2. **货币信用权重微升**（0.624→0.630）： - “宽货币宽信用”持续（Shibor3M 1.97，信用脉冲25.30），流动性宽松叠加信用扩张，货币信用框架对资产定价主导性增强。 3. **财政货币权重略降**（0.115→0.110）： - 财政政策力度（-1.82）与货币政策（113.72）维持“双宽”，但政策效果已被市场充分定价，边际贡献下降。 4. **信贷库存权重稳定**（0.199→0.200）： - 信贷增速与票据增速分化延续（数据未披露），反映银行信贷额度调节行为，模型权重维持高位。 5. **周期叠加权重归零**（0.0→0.0）： - 产能周期与库存周期未形成显著共振（数据缺失），模型暂不适用。 **核心趋势**：货币信用框架（权重63%）仍是当前主导模型，反映流动性宽松与信用扩张对市场的核心驱动；滞涨环境下美林时钟与信贷库存模型作为辅助验证。
A14: =EOMONTH(A13,-1) -> 45747 | B14: {=INDEX(股债表现与四个维度!$A:$T,MATCH($A14,股债表现与四个维度!$A:$A,0),MATCH(B$4,股债表现与四个维度!$2:$2,0))} -> -0.40246441 | C14: {=INDEX(股债表现与四个维度!$A:$T,MATCH($A14,股债表现与四个维度!$A:$A,0),MATCH(C$4,股债表现与四个维度!$2:$2,0))} -> 14.247694 | D14: {=INDEX(股债表现与四个维度!$A:$T,MATCH($A14,股债表现与四个维度!$A:$A,0),MATCH(D$4,股债表现与四个维度!$2:$2,0))} -> #N/A | E14: {=INDEX(股债表现与四个维度!$A:$T,MATCH($A14,股债表现与四个维度!$A:$A,0),MATCH(E$4,股债表现与四个维度!$2:$2,0))} -> 滞涨 | F14: {=INDEX(股债表现与四个维度!$A:$T,MATCH($A14,股债表现与四个维度!$A:$A,0),MATCH(F$4,股债表现与四个维度!$2:$2,0))} -> 紧货币宽信用 | G14: {=INDEX(股债表现与四个维度!$A:$T,MATCH($A14,股债表现与四个维度!$A:$A,0),MATCH(G$4,股债表现与四个维度!$2:$2,0))} -> 双紧 | H14: {=INDEX(股债表现与四个维度!$A:$T,MATCH($A14,股债表现与四个维度!$A:$A,0),MATCH(H$4,股债表现与四个维度!$2:$2,0))} -> 主动补库存 | I14: {=INDEX(股债表现与四个维度!$A:$T,MATCH($A14,股债表现与四个维度!$A:$A,0),MATCH(I$4,股债表现与四个维度!$2:$2,0))} -> 产能周期下行,主动补库存 | J14: {=INDEX(股债表现与四个维度!$A:$T,MATCH($A14,股债表现与四个维度!$A:$A,0),MATCH(J$3&J$4,股债表现与四个维度!$2:$2&股债表现与四个维度!$3:$3,0))} -> -0.1 | K14: {=INDEX(股债表现与四个维度!$A:$T,MATCH($A14,股债表现与四个维度!$A:$A,0),MATCH(K$3&K$4,股债表现与四个维度!$2:$2&股债表现与四个维度!$3:$3,0))} -> -0.3 | L14: {=INDEX(股债表现与四个维度!$A:$T,MATCH($A14,股债表现与四个维度!$A:$A,0),MATCH(L$3&L$4,股债表现与四个维度!$2:$2&股债表现与四个维度!$3:$3,0))} -> 0.13333333 | M14: {=INDEX(股债表现与四个维度!$A:$T,MATCH($A14,股债表现与四个维度!$A:$A,0),MATCH(M$3&M$4,股债表现与四个维度!$2:$2&股债表现与四个维度!$3:$3,0))} -> -0.4 | N14: {=INDEX(股债表现与四个维度!$A:$T,MATCH($A14,股债表现与四个维度!$A:$A,0),MATCH(N$3&N$4,股债表现与四个维度!$2:$2&股债表现与四个维度!$3:$3,0))} -> 0.19047619 | O14: {=INDEX(股债表现与四个维度!$A:$T,MATCH($A14,股债表现与四个维度!$A:$A,0),MATCH(O$3&O$4,股债表现与四个维度!$2:$2&股债表现与四个维度!$3:$3,0))} -> -0.047619048 | P14: {=INDEX(股债表现与四个维度!$A:$T,MATCH($A14,股债表现与四个维度!$A:$A,0),MATCH(P$3&P$4,股债表现与四个维度!$2:$2&股债表现与四个维度!$3:$3,0))} -> 0.16666667 | Q14: {=INDEX(股债表现与四个维度!$A:$T,MATCH($A14,股债表现与四个维度!$A:$A,0),MATCH(Q$3&Q$4,股债表现与四个维度!$2:$2&股债表现与四个维度!$3:$3,0))} -> 0.16666667 | ... S14: {=INDEX(股债表现与四个维度!$A:$T,MATCH($A14,股债表现与四个维度!$A:$A,0),MATCH(S$3&S$4,股债表现与四个维度!$2:$2&股债表现与四个维度!$3:$3,0))} -> 0.15384615 | T14: =SUMIFS($J14:$S14,$J14:$S14,"<>"&"#N/A",$J$4:$S$4,T$4) -> 0.23663004 | U14: =SUMIFS($J14:$S14,$J14:$S14,"<>"&"#N/A",$J$4:$S$4,U$4) -> -0.42710623 | V14: =T14-U14 -> 0.66373626 | W14: =B14+C14 -> 13.84523 | X14: =B14-D14 -> #N/A | Y14: =AVERAGE(V14:V19) -> -0.46946942 | Z14: =AVERAGE(W14:W19) -> -4.2268817 | AA14: =AVERAGE(AC14:AC19) -> -0.52870255 | AC14: =(AD14*(J14-K14)+AE14*(L14-M14)+AF14*(N14-O14)+AG14*(P14-Q14)+AH14*(R14-S14))*5 -> 2.045 | AD14: 0.03 | AE14: 0.74 | AF14: 0.035 | AG14: 0.195 | AH14: 0 | AI14: ### 推理依据： 1. **美林时钟权重微升**（0.030→0.030）： - 当前仍处“过热”阶段（工业增加值同比6.7，PPI同比-2.5），但CPI通缩（-2.5）抑制通胀压力，模型解释力边际增强。 - 对比上月权重稳定，因经济过热特征未显著变化。 2. **货币信用权重略降**（0.746→0.740）： - “宽货币紧信用”延续（Shibor 2.0665，信用脉冲24.91），但信用脉冲小幅回落（上月25.90→本月24.91），信用收缩边际缓和，模型权重微调。 - 仍为主导模型，因货币宽松与信用收缩的组合对市场影响显著。 3. **财政货币权重微升**（0.034→0.035）： - “双宽”政策持续（财政力度-2.23，货币力度113.56），但财政扩张力度减弱（上月-3.12→本月-2.23），政策协同性略降，模型权重小幅上调。 4. **信贷库存权重上升**（0.190→0.195）： - 工业增加值高增（6.7）与票据增速低位反映“被动去库存”特征，信贷需求强劲，模型解释力提升。 - 权重增幅温和，因库存周期尚未明确转向。 5. **周期叠加权重维持0**： - 产能周期数据缺失，且历史权重多为0，暂不纳入本期配置。 ### 核心逻辑： - **货币信用框架主导**（74%）：宽货币与紧信用的矛盾组合对资产定价影响最大。 - **美林时钟与信贷库存辅助**：过热经济+被动去库存验证复苏韧性，但CPI通缩限制美林模型空间。 - **政策组合微调**：财政扩张放缓，但“双宽”基调未变，权重变化有限。
A15: =EOMONTH(A14,-1) -> 45716 | B15: {=INDEX(股债表现与四个维度!$A:$T,MATCH($A15,股债表现与四个维度!$A:$A,0),MATCH(B$4,股债表现与四个维度!$2:$2,0))} -> 4.7407773 | C15: {=INDEX(股债表现与四个维度!$A:$T,MATCH($A15,股债表现与四个维度!$A:$A,0),MATCH(C$4,股债表现与四个维度!$2:$2,0))} -> 3.3657895 | D15: {=INDEX(股债表现与四个维度!$A:$T,MATCH($A15,股债表现与四个维度!$A:$A,0),MATCH(D$4,股债表现与四个维度!$2:$2,0))} -> #N/A | E15: {=INDEX(股债表现与四个维度!$A:$T,MATCH($A15,股债表现与四个维度!$A:$A,0),MATCH(E$4,股债表现与四个维度!$2:$2,0))} -> 过热 | F15: {=INDEX(股债表现与四个维度!$A:$T,MATCH($A15,股债表现与四个维度!$A:$A,0),MATCH(F$4,股债表现与四个维度!$2:$2,0))} -> 紧货币宽信用 | G15: {=INDEX(股债表现与四个维度!$A:$T,MATCH($A15,股债表现与四个维度!$A:$A,0),MATCH(G$4,股债表现与四个维度!$2:$2,0))} -> 双紧 | H15: {=INDEX(股债表现与四个维度!$A:$T,MATCH($A15,股债表现与四个维度!$A:$A,0),MATCH(H$4,股债表现与四个维度!$2:$2,0))} -> 被动补库存 | I15: {=INDEX(股债表现与四个维度!$A:$T,MATCH($A15,股债表现与四个维度!$A:$A,0),MATCH(I$4,股债表现与四个维度!$2:$2,0))} -> 产能周期下行,主动补库存 | J15: {=INDEX(股债表现与四个维度!$A:$T,MATCH($A15,股债表现与四个维度!$A:$A,0),MATCH(J$3&J$4,股债表现与四个维度!$2:$2&股债表现与四个维度!$3:$3,0))} -> 0.26666667 | K15: {=INDEX(股债表现与四个维度!$A:$T,MATCH($A15,股债表现与四个维度!$A:$A,0),MATCH(K$3&K$4,股债表现与四个维度!$2:$2&股债表现与四个维度!$3:$3,0))} -> 0.33333333 | L15: {=INDEX(股债表现与四个维度!$A:$T,MATCH($A15,股债表现与四个维度!$A:$A,0),MATCH(L$3&L$4,股债表现与四个维度!$2:$2&股债表现与四个维度!$3:$3,0))} -> 0.13333333 | M15: {=INDEX(股债表现与四个维度!$A:$T,MATCH($A15,股债表现与四个维度!$A:$A,0),MATCH(M$3&M$4,股债表现与四个维度!$2:$2&股债表现与四个维度!$3:$3,0))} -> -0.4 | N15: {=INDEX(股债表现与四个维度!$A:$T,MATCH($A15,股债表现与四个维度!$A:$A,0),MATCH(N$3&N$4,股债表现与四个维度!$2:$2&股债表现与四个维度!$3:$3,0))} -> 0.23809524 | O15: {=INDEX(股债表现与四个维度!$A:$T,MATCH($A15,股债表现与四个维度!$A:$A,0),MATCH(O$3&O$4,股债表现与四个维度!$2:$2&股债表现与四个维度!$3:$3,0))} -> -0.047619048 | P15: {=INDEX(股债表现与四个维度!$A:$T,MATCH($A15,股债表现与四个维度!$A:$A,0),MATCH(P$3&P$4,股债表现与四个维度!$2:$2&股债表现与四个维度!$3:$3,0))} -> -0.074074074 | Q15: {=INDEX(股债表现与四个维度!$A:$T,MATCH($A15,股债表现与四个维度!$A:$A,0),MATCH(Q$3&Q$4,股债表现与四个维度!$2:$2&股债表现与四个维度!$3:$3,0))} -> 0.37037037 | ... S15: {=INDEX(股债表现与四个维度!$A:$T,MATCH($A15,股债表现与四个维度!$A:$A,0),MATCH(S$3&S$4,股债表现与四个维度!$2:$2&股债表现与四个维度!$3:$3,0))} -> 0.083333333 | T15: =SUMIFS($J15:$S15,$J15:$S15,"<>"&"#N/A",$J$4:$S$4,T$4) -> 0.48068783 | U15: =SUMIFS($J15:$S15,$J15:$S15,"<>"&"#N/A",$J$4:$S$4,U$4) -> 0.33941799 | V15: =T15-U15 -> 0.14126984 | W15: =B15+C15 -> 8.1065668 | X15: =B15-D15 -> #N/A | Y15: =AVERAGE(V15:V20) -> -1.0394161 | Z15: =AVERAGE(W15:W20) -> -3.9967064 | AA15: =AVERAGE(AC15:AC20) -> -0.67436355 | AC15: =(AD15*(J15-K15)+AE15*(L15-M15)+AF15*(N15-O15)+AG15*(P15-Q15)+AH15*(R15-S15))*5 -> 0.39112698 | AD15: 0.053 | AE15: 0.303 | AF15: 0.062 | AG15: 0.002 | AH15: 0.58 | AI15: ### 推理依据： 1. **美林时钟权重下降**（0.176→0.053）： - **宏观数据**：工业增加值同比从-12.7（复苏）回升至4.5（衰退），PPI同比-2.8仍处通缩区间。 - **周期阶段**：从“复苏”转入“衰退”，但工业增加值反弹削弱衰退信号，模型解释力下降。 - **逻辑**：经济数据矛盾（工业增加值反弹但PPI低迷），美林时钟对衰退的指示性减弱。 2. **货币信用权重稳定**（0.387→0.303）： - **宏观数据**：Shibor（2.29→2.16）显示货币宽松延续，信用脉冲（26.57→25.90）边际收缩。 - **周期阶段**：持续“宽货币紧信用”，信用扩张乏力但流动性充裕。 - **逻辑**：货币宽松主导市场，信用端疲软压制权重进一步上升。 3. **财政货币权重回升**（0.0→0.062）： - **宏观数据**：财政政策力度从扩张（1.86）转为紧缩（-3.12），货币政策力度（113.64→113.55）微降。 - **周期阶段**：从“双宽”转为“双紧”，政策对冲效应减弱。 - **逻辑**：财政收紧与货币微调的组合增加模型相关性，但绝对值仍低。 4. **信贷库存权重骤降**（0.437→0.002）： - **宏观数据**：信贷增速未披露，但票据增速或显著回落（权重接近0）。 - **周期阶段**：可能从“被动去库存”转向极端信贷收缩。 - **逻辑**：信贷数据异常或模型失效，权重被压缩至边际水平。 5. **周期叠加权重飙升**（0.0→0.580）： - **宏观数据**：工业增加值波动（-12.7→4.5）与PPI通缩（-2.8）反映产能过剩。 - **周期阶段**：产能周期下行+主动去库存，模型匹配度高。
A16: =EOMONTH(A15,-1) -> 45688 | B16: {=INDEX(股债表现与四个维度!$A:$T,MATCH($A16,股债表现与四个维度!$A:$A,0),MATCH(B$4,股债表现与四个维度!$2:$2,0))} -> -2.3186982 | C16: {=INDEX(股债表现与四个维度!$A:$T,MATCH($A16,股债表现与四个维度!$A:$A,0),MATCH(C$4,股债表现与四个维度!$2:$2,0))} -> -16.228852 | D16: {=INDEX(股债表现与四个维度!$A:$T,MATCH($A16,股债表现与四个维度!$A:$A,0),MATCH(D$4,股债表现与四个维度!$2:$2,0))} -> #N/A | E16: {=INDEX(股债表现与四个维度!$A:$T,MATCH($A16,股债表现与四个维度!$A:$A,0),MATCH(E$4,股债表现与四个维度!$2:$2,0))} -> 衰退 | F16: {=INDEX(股债表现与四个维度!$A:$T,MATCH($A16,股债表现与四个维度!$A:$A,0),MATCH(F$4,股债表现与四个维度!$2:$2,0))} -> 宽货币宽信用 | G16: {=INDEX(股债表现与四个维度!$A:$T,MATCH($A16,股债表现与四个维度!$A:$A,0),MATCH(G$4,股债表现与四个维度!$2:$2,0))} -> 双紧 | H16: {=INDEX(股债表现与四个维度!$A:$T,MATCH($A16,股债表现与四个维度!$A:$A,0),MATCH(H$4,股债表现与四个维度!$2:$2,0))} -> 被动补库存 | I16: {=INDEX(股债表现与四个维度!$A:$T,MATCH($A16,股债表现与四个维度!$A:$A,0),MATCH(I$4,股债表现与四个维度!$2:$2,0))} -> 产能周期下行,主动补库存 | J16: {=INDEX(股债表现与四个维度!$A:$T,MATCH($A16,股债表现与四个维度!$A:$A,0),MATCH(J$3&J$4,股债表现与四个维度!$2:$2&股债表现与四个维度!$3:$3,0))} -> 0.076923077 | K16: {=INDEX(股债表现与四个维度!$A:$T,MATCH($A16,股债表现与四个维度!$A:$A,0),MATCH(K$3&K$4,股债表现与四个维度!$2:$2&股债表现与四个维度!$3:$3,0))} -> 0.076923077 | L16: {=INDEX(股债表现与四个维度!$A:$T,MATCH($A16,股债表现与四个维度!$A:$A,0),MATCH(L$3&L$4,股债表现与四个维度!$2:$2&股债表现与四个维度!$3:$3,0))} -> -0.33333333 | M16: {=INDEX(股债表现与四个维度!$A:$T,MATCH($A16,股债表现与四个维度!$A:$A,0),MATCH(M$3&M$4,股债表现与四个维度!$2:$2&股债表现与四个维度!$3:$3,0))} -> 0.33333333 | N16: {=INDEX(股债表现与四个维度!$A:$T,MATCH($A16,股债表现与四个维度!$A:$A,0),MATCH(N$3&N$4,股债表现与四个维度!$2:$2&股债表现与四个维度!$3:$3,0))} -> 0.23809524 | O16: {=INDEX(股债表现与四个维度!$A:$T,MATCH($A16,股债表现与四个维度!$A:$A,0),MATCH(O$3&O$4,股债表现与四个维度!$2:$2&股债表现与四个维度!$3:$3,0))} -> -0.047619048 | P16: {=INDEX(股债表现与四个维度!$A:$T,MATCH($A16,股债表现与四个维度!$A:$A,0),MATCH(P$3&P$4,股债表现与四个维度!$2:$2&股债表现与四个维度!$3:$3,0))} -> -0.038461538 | Q16: {=INDEX(股债表现与四个维度!$A:$T,MATCH($A16,股债表现与四个维度!$A:$A,0),MATCH(Q$3&Q$4,股债表现与四个维度!$2:$2&股债表现与四个维度!$3:$3,0))} -> 0.34615385 | ... S16: {=INDEX(股债表现与四个维度!$A:$T,MATCH($A16,股债表现与四个维度!$A:$A,0),MATCH(S$3&S$4,股债表现与四个维度!$2:$2&股债表现与四个维度!$3:$3,0))} -> 0.083333333 | T16: =SUMIFS($J16:$S16,$J16:$S16,"<>"&"#N/A",$J$4:$S$4,T$4) -> -0.14010989 | U16: =SUMIFS($J16:$S16,$J16:$S16,"<>"&"#N/A",$J$4:$S$4,U$4) -> 0.79212454 | V16: =T16-U16 -> -0.93223443 | W16: =B16+C16 -> -18.54755 | X16: =B16-D16 -> #N/A | Y16: =AVERAGE(V16:V21) -> -1.6596084 | Z16: =AVERAGE(W16:W21) -> -7.0871388 | AA16: =AVERAGE(AC16:AC21) -> -0.54865133 | AC16: =(AD16*(J16-K16)+AE16*(L16-M16)+AF16*(N16-O16)+AG16*(P16-Q16)+AH16*(R16-S16))*5 -> -2.1269231 | AD16: 0.18 | AE16: 0.39 | AF16: 0 | AG16: 0.43 | AH16: 0 | AI16: ### 推理依据： 1. **美林时钟权重微升**（0.176→0.180）： - 当前仍处“复苏”阶段（工业增加值同比-12.7，PPI同比-2.7），但工业增加值降幅收窄（对比前值-12.7→26.3→6.8），显示触底迹象，模型解释力增强。 2. **货币信用权重上升**（0.387→0.390）： - “宽货币紧信用”延续（Shibor 2.29↓，信用脉冲26.57↓），流动性宽松但信用传导不畅，货币信用框架对市场流动性敏感度提升。 3. **财政货币权重归零**（0.0→0.0）： - “双宽”政策持续（财政力度1.86，货币力度113.64），但财政与货币同步性高，模型分化信号不足，权重维持低位。 4. **信贷库存权重微降**（0.437→0.430）： - 信贷增速边际改善（需假设票据增速变化），但经济仍处弱复苏，银行风险偏好未显著修复，模型权重小幅回调。 5. **周期叠加权重归零**（0.0→0.0）： - 产能周期与库存周期未形成共振（如需求PMI未提供明确信号），模型解释力暂不显著。 ### 核心逻辑： - **趋势延续性**：美林“复苏”与货币信用“宽货币紧信用”仍是主导逻辑，权重合计占57%（前值56%）。 - **政策钝化**：财政货币“双宽”持续但边际效应递减，模型失效（权重0%）。 - **数据矛盾**：工业增加值降幅收窄但PPI通缩，信贷库存模型需观察后续票据数据验证信用结构。
A17: =EOMONTH(A16,-1) -> 45657 | B17: {=INDEX(股债表现与四个维度!$A:$T,MATCH($A17,股债表现与四个维度!$A:$A,0),MATCH(B$4,股债表现与四个维度!$2:$2,0))} -> -1.9590725 | C17: {=INDEX(股债表现与四个维度!$A:$T,MATCH($A17,股债表现与四个维度!$A:$A,0),MATCH(C$4,股债表现与四个维度!$2:$2,0))} -> -28.86368 | D17: {=INDEX(股债表现与四个维度!$A:$T,MATCH($A17,股债表现与四个维度!$A:$A,0),MATCH(D$4,股债表现与四个维度!$2:$2,0))} -> #N/A | E17: {=INDEX(股债表现与四个维度!$A:$T,MATCH($A17,股债表现与四个维度!$A:$A,0),MATCH(E$4,股债表现与四个维度!$2:$2,0))} -> 复苏 | F17: {=INDEX(股债表现与四个维度!$A:$T,MATCH($A17,股债表现与四个维度!$A:$A,0),MATCH(F$4,股债表现与四个维度!$2:$2,0))} -> 宽货币宽信用 | G17: {=INDEX(股债表现与四个维度!$A:$T,MATCH($A17,股债表现与四个维度!$A:$A,0),MATCH(G$4,股债表现与四个维度!$2:$2,0))} -> 双宽 | H17: {=INDEX(股债表现与四个维度!$A:$T,MATCH($A17,股债表现与四个维度!$A:$A,0),MATCH(H$4,股债表现与四个维度!$2:$2,0))} -> 被动补库存 | I17: {=INDEX(股债表现与四个维度!$A:$T,MATCH($A17,股债表现与四个维度!$A:$A,0),MATCH(I$4,股债表现与四个维度!$2:$2,0))} -> 产能周期下行,被动去库存 | J17: {=INDEX(股债表现与四个维度!$A:$T,MATCH($A17,股债表现与四个维度!$A:$A,0),MATCH(J$3&J$4,股债表现与四个维度!$2:$2&股债表现与四个维度!$3:$3,0))} -> 0 | K17: {=INDEX(股债表现与四个维度!$A:$T,MATCH($A17,股债表现与四个维度!$A:$A,0),MATCH(K$3&K$4,股债表现与四个维度!$2:$2&股债表现与四个维度!$3:$3,0))} -> 0.45454545 | L17: {=INDEX(股债表现与四个维度!$A:$T,MATCH($A17,股债表现与四个维度!$A:$A,0),MATCH(L$3&L$4,股债表现与四个维度!$2:$2&股债表现与四个维度!$3:$3,0))} -> -0.33333333 | M17: {=INDEX(股债表现与四个维度!$A:$T,MATCH($A17,股债表现与四个维度!$A:$A,0),MATCH(M$3&M$4,股债表现与四个维度!$2:$2&股债表现与四个维度!$3:$3,0))} -> 0.33333333 | N17: {=INDEX(股债表现与四个维度!$A:$T,MATCH($A17,股债表现与四个维度!$A:$A,0),MATCH(N$3&N$4,股债表现与四个维度!$2:$2&股债表现与四个维度!$3:$3,0))} -> -0.05 | O17: {=INDEX(股债表现与四个维度!$A:$T,MATCH($A17,股债表现与四个维度!$A:$A,0),MATCH(O$3&O$4,股债表现与四个维度!$2:$2&股债表现与四个维度!$3:$3,0))} -> 0.35 | P17: {=INDEX(股债表现与四个维度!$A:$T,MATCH($A17,股债表现与四个维度!$A:$A,0),MATCH(P$3&P$4,股债表现与四个维度!$2:$2&股债表现与四个维度!$3:$3,0))} -> -0.038461538 | Q17: {=INDEX(股债表现与四个维度!$A:$T,MATCH($A17,股债表现与四个维度!$A:$A,0),MATCH(Q$3&Q$4,股债表现与四个维度!$2:$2&股债表现与四个维度!$3:$3,0))} -> 0.34615385 | ... S17: {=INDEX(股债表现与四个维度!$A:$T,MATCH($A17,股债表现与四个维度!$A:$A,0),MATCH(S$3&S$4,股债表现与四个维度!$2:$2&股债表现与四个维度!$3:$3,0))} -> 0 | T17: =SUMIFS($J17:$S17,$J17:$S17,"<>"&"#N/A",$J$4:$S$4,T$4) -> 0.57820513 | U17: =SUMIFS($J17:$S17,$J17:$S17,"<>"&"#N/A",$J$4:$S$4,U$4) -> 1.4840326 | V17: =T17-U17 -> -0.90582751 | W17: =B17+C17 -> -30.822752 | X17: =B17-D17 -> #N/A | Y17: =AVERAGE(V17:V22) -> -1.7870642 | Z17: =AVERAGE(W17:W22) -> -4.241618 | AA17: =AVERAGE(AC17:AC22) -> -0.34291268 | AC17: =(AD17*(J17-K17)+AE17*(L17-M17)+AF17*(N17-O17)+AG17*(P17-Q17)+AH17*(R17-S17))*5 -> -2.31338 | AD17: 0.05 | AE17: 0.26 | AF17: 0.08 | AG17: 0.61 | AH17: 0 | AI17: ### 推理依据： 1. **美林时钟权重微降**（0.049→0.050）： - 当前仍处“过热”阶段（工业增加值同比26.3，PPI同比-2.5），但CPI同比（-2.5）显示通缩压力，模型对通胀周期的解释力受限。 - 对比前两月，工业增加值同比从6.8跳升至26.3，数据波动剧烈，需降低短期权重。 2. **货币信用权重稳定**（0.262→0.260）： - “宽货币宽信用”延续（Shibor 2.40，信用脉冲27.86），流动性宽松且信用扩张强劲，模型对市场流动性指引明确。 - 信用脉冲较上月（27.49→27.86）小幅回升，支撑权重高位。 3. **财政货币权重持平**（0.080→0.080）： - “双宽”政策持续（财政力度1.34，货币力度113.14），但财政力度边际减弱（前值1.34→1.34），政策协同性未显著变化。 4. **信贷库存权重上升**（0.609→0.610）： - 工业增加值同比26.3与贷款增速高增（隐含信贷需求旺盛），可能对应“主动补库存”阶段，模型对实体融资行为的敏感性提升。 - 前三月权重持续上升（0.266→0.321→0.609），反映信贷周期主导性增强。 5. **周期叠加权重归零**（0.000→0.000）： - 产能周期数据缺失，且前两月权重波动大（0.528→0.382→0.0），当前阶段其他模型解释力更强。 ### 核心逻辑： - **信贷库存主导**：工业增加值跳升+宽信用环境，强化信贷模型权重。 - **货币信用次之**：宽货币宽信用组合的稳定性使其成为第二优先级。 - **美林时钟弱化**：通胀数据矛盾（PPI与CPI背离）降低其短期有效性。
A18: =EOMONTH(A17,-1) -> 45626 | B18: {=INDEX(股债表现与四个维度!$A:$T,MATCH($A18,股债表现与四个维度!$A:$A,0),MATCH(B$4,股债表现与四个维度!$2:$2,0))} -> 1.3430445 | C18: {=INDEX(股债表现与四个维度!$A:$T,MATCH($A18,股债表现与四个维度!$A:$A,0),MATCH(C$4,股债表现与四个维度!$2:$2,0))} -> -5.8158897 | D18: {=INDEX(股债表现与四个维度!$A:$T,MATCH($A18,股债表现与四个维度!$A:$A,0),MATCH(D$4,股债表现与四个维度!$2:$2,0))} -> #N/A | E18: {=INDEX(股债表现与四个维度!$A:$T,MATCH($A18,股债表现与四个维度!$A:$A,0),MATCH(E$4,股债表现与四个维度!$2:$2,0))} -> 过热 | F18: {=INDEX(股债表现与四个维度!$A:$T,MATCH($A18,股债表现与四个维度!$A:$A,0),MATCH(F$4,股债表现与四个维度!$2:$2,0))} -> 紧货币紧信用 | G18: {=INDEX(股债表现与四个维度!$A:$T,MATCH($A18,股债表现与四个维度!$A:$A,0),MATCH(G$4,股债表现与四个维度!$2:$2,0))} -> 双紧 | H18: {=INDEX(股债表现与四个维度!$A:$T,MATCH($A18,股债表现与四个维度!$A:$A,0),MATCH(H$4,股债表现与四个维度!$2:$2,0))} -> 主动去库存 | I18: {=INDEX(股债表现与四个维度!$A:$T,MATCH($A18,股债表现与四个维度!$A:$A,0),MATCH(I$4,股债表现与四个维度!$2:$2,0))} -> 产能周期下行,被动去库存 | J18: {=INDEX(股债表现与四个维度!$A:$T,MATCH($A18,股债表现与四个维度!$A:$A,0),MATCH(J$3&J$4,股债表现与四个维度!$2:$2&股债表现与四个维度!$3:$3,0))} -> 0.15384615 | K18: {=INDEX(股债表现与四个维度!$A:$T,MATCH($A18,股债表现与四个维度!$A:$A,0),MATCH(K$3&K$4,股债表现与四个维度!$2:$2&股债表现与四个维度!$3:$3,0))} -> 0.38461538 | L18: {=INDEX(股债表现与四个维度!$A:$T,MATCH($A18,股债表现与四个维度!$A:$A,0),MATCH(L$3&L$4,股债表现与四个维度!$2:$2&股债表现与四个维度!$3:$3,0))} -> 0.22222222 | M18: {=INDEX(股债表现与四个维度!$A:$T,MATCH($A18,股债表现与四个维度!$A:$A,0),MATCH(M$3&M$4,股债表现与四个维度!$2:$2&股债表现与四个维度!$3:$3,0))} -> -0.11111111 | N18: {=INDEX(股债表现与四个维度!$A:$T,MATCH($A18,股债表现与四个维度!$A:$A,0),MATCH(N$3&N$4,股债表现与四个维度!$2:$2&股债表现与四个维度!$3:$3,0))} -> 0.2 | O18: {=INDEX(股债表现与四个维度!$A:$T,MATCH($A18,股债表现与四个维度!$A:$A,0),MATCH(O$3&O$4,股债表现与四个维度!$2:$2&股债表现与四个维度!$3:$3,0))} -> -0.1 | P18: {=INDEX(股债表现与四个维度!$A:$T,MATCH($A18,股债表现与四个维度!$A:$A,0),MATCH(P$3&P$4,股债表现与四个维度!$2:$2&股债表现与四个维度!$3:$3,0))} -> 0.05 | Q18: {=INDEX(股债表现与四个维度!$A:$T,MATCH($A18,股债表现与四个维度!$A:$A,0),MATCH(Q$3&Q$4,股债表现与四个维度!$2:$2&股债表现与四个维度!$3:$3,0))} -> 0.05 | ... S18: {=INDEX(股债表现与四个维度!$A:$T,MATCH($A18,股债表现与四个维度!$A:$A,0),MATCH(S$3&S$4,股债表现与四个维度!$2:$2&股债表现与四个维度!$3:$3,0))} -> 1 | T18: =SUMIFS($J18:$S18,$J18:$S18,"<>"&"#N/A",$J$4:$S$4,T$4) -> 1.6260684 | U18: =SUMIFS($J18:$S18,$J18:$S18,"<>"&"#N/A",$J$4:$S$4,U$4) -> 1.2235043 | V18: =T18-U18 -> 0.4025641 | W18: =B18+C18 -> -4.4728453 | X18: =B18-D18 -> #N/A | Y18: =AVERAGE(V18:V23) -> -1.772702 | Z18: =AVERAGE(W18:W23) -> -0.7533162 | AA18: =AVERAGE(AC18:AC23) -> -0.15473365 | AC18: =(AD18*(J18-K18)+AE18*(L18-M18)+AF18*(N18-O18)+AG18*(P18-Q18)+AH18*(R18-S18))*5 -> 0.11025641 | AD18: 0.085 | AE18: 0.125 | AF18: 0 | AG18: 0.325 | AH18: 0.465 | AI18: ### 推理依据： 1. **美林时钟权重下降**（0.092→0.085）： - 近期从“过热”转向“复苏”，但工业增加值同比（6.8→6.6→4.6）显示增长动能减弱，模型解释力略降。 2. **货币信用权重微升**（0.113→0.125）： - “紧货币宽信用”持续，信用脉冲（27.49→27.32→26.95）显示信用扩张边际放缓，货币条件重要性提升。 3. **财政货币权重保持0**： - “双宽”政策延续但财政力度波动（1.34→-1.30→-2.59），模型失效（历史权重均为0）。 4. **信贷库存权重显著上升**（0.266→0.325）： - 经济复苏期信贷需求通常回升，被动去库存阶段（若存在）权重会强化。 5. **周期叠加权重下降但仍主导**（0.528→0.465）： - 产能周期下行+主动去库存组合权重仍高，但工业增加值放缓可能削弱其解释力。 **注**：权重调整方向综合了近期趋势（3个月数据）及周期阶段转换逻辑。
A19: =EOMONTH(A18,-1) -> 45596 | B19: {=INDEX(股债表现与四个维度!$A:$T,MATCH($A19,股债表现与四个维度!$A:$A,0),MATCH(B$4,股债表现与四个维度!$2:$2,0))} -> 2.2784563 | C19: {=INDEX(股债表现与四个维度!$A:$T,MATCH($A19,股债表现与四个维度!$A:$A,0),MATCH(C$4,股债表现与四个维度!$2:$2,0))} -> 4.251604 | D19: {=INDEX(股债表现与四个维度!$A:$T,MATCH($A19,股债表现与四个维度!$A:$A,0),MATCH(D$4,股债表现与四个维度!$2:$2,0))} -> #N/A | E19: {=INDEX(股债表现与四个维度!$A:$T,MATCH($A19,股债表现与四个维度!$A:$A,0),MATCH(E$4,股债表现与四个维度!$2:$2,0))} -> 过热 | F19: {=INDEX(股债表现与四个维度!$A:$T,MATCH($A19,股债表现与四个维度!$A:$A,0),MATCH(F$4,股债表现与四个维度!$2:$2,0))} -> 紧货币紧信用 | G19: {=INDEX(股债表现与四个维度!$A:$T,MATCH($A19,股债表现与四个维度!$A:$A,0),MATCH(G$4,股债表现与四个维度!$2:$2,0))} -> 双宽 | H19: {=INDEX(股债表现与四个维度!$A:$T,MATCH($A19,股债表现与四个维度!$A:$A,0),MATCH(H$4,股债表现与四个维度!$2:$2,0))} -> 主动去库存 | I19: {=INDEX(股债表现与四个维度!$A:$T,MATCH($A19,股债表现与四个维度!$A:$A,0),MATCH(I$4,股债表现与四个维度!$2:$2,0))} -> 产能周期下行,被动去库存 | J19: {=INDEX(股债表现与四个维度!$A:$T,MATCH($A19,股债表现与四个维度!$A:$A,0),MATCH(J$3&J$4,股债表现与四个维度!$2:$2&股债表现与四个维度!$3:$3,0))} -> 0.15384615 | K19: {=INDEX(股债表现与四个维度!$A:$T,MATCH($A19,股债表现与四个维度!$A:$A,0),MATCH(K$3&K$4,股债表现与四个维度!$2:$2&股债表现与四个维度!$3:$3,0))} -> 0.38461538 | L19: {=INDEX(股债表现与四个维度!$A:$T,MATCH($A19,股债表现与四个维度!$A:$A,0),MATCH(L$3&L$4,股债表现与四个维度!$2:$2&股债表现与四个维度!$3:$3,0))} -> 0.11111111 | M19: {=INDEX(股债表现与四个维度!$A:$T,MATCH($A19,股债表现与四个维度!$A:$A,0),MATCH(M$3&M$4,股债表现与四个维度!$2:$2&股债表现与四个维度!$3:$3,0))} -> -0.33333333 | N19: {=INDEX(股债表现与四个维度!$A:$T,MATCH($A19,股债表现与四个维度!$A:$A,0),MATCH(N$3&N$4,股债表现与四个维度!$2:$2&股债表现与四个维度!$3:$3,0))} -> -0.1 | O19: {=INDEX(股债表现与四个维度!$A:$T,MATCH($A19,股债表现与四个维度!$A:$A,0),MATCH(O$3&O$4,股债表现与四个维度!$2:$2&股债表现与四个维度!$3:$3,0))} -> 0.3 | P19: {=INDEX(股债表现与四个维度!$A:$T,MATCH($A19,股债表现与四个维度!$A:$A,0),MATCH(P$3&P$4,股债表现与四个维度!$2:$2&股债表现与四个维度!$3:$3,0))} -> 0.05 | Q19: {=INDEX(股债表现与四个维度!$A:$T,MATCH($A19,股债表现与四个维度!$A:$A,0),MATCH(Q$3&Q$4,股债表现与四个维度!$2:$2&股债表现与四个维度!$3:$3,0))} -> 0.05 | ... S19: {=INDEX(股债表现与四个维度!$A:$T,MATCH($A19,股债表现与四个维度!$A:$A,0),MATCH(S$3&S$4,股债表现与四个维度!$2:$2&股债表现与四个维度!$3:$3,0))} -> 1 | T19: =SUMIFS($J19:$S19,$J19:$S19,"<>"&"#N/A",$J$4:$S$4,T$4) -> -0.78504274 | U19: =SUMIFS($J19:$S19,$J19:$S19,"<>"&"#N/A",$J$4:$S$4,U$4) -> 1.4012821 | V19: =T19-U19 -> -2.1863248 | W19: =B19+C19 -> 6.5300603 | X19: =B19-D19 -> #N/A | Y19: =AVERAGE(V19:V24) -> -2.0945868 | Z19: =AVERAGE(W19:W24) -> 0.14161396 | AA19: =AVERAGE(AC19:AC24) -> -0.42901482 | AB19: -0.42901482 | AC19: -1.2782957
A20: =EOMONTH(A19,-1) -> 45565 | B20: {=INDEX(股债表现与四个维度!$A:$T,MATCH($A20,股债表现与四个维度!$A:$A,0),MATCH(B$4,股债表现与四个维度!$2:$2,0))} -> 22.210135 | C20: {=INDEX(股债表现与四个维度!$A:$T,MATCH($A20,股债表现与四个维度!$A:$A,0),MATCH(C$4,股债表现与四个维度!$2:$2,0))} -> -6.9838528 | D20: {=INDEX(股债表现与四个维度!$A:$T,MATCH($A20,股债表现与四个维度!$A:$A,0),MATCH(D$4,股债表现与四个维度!$2:$2,0))} -> #N/A | E20: {=INDEX(股债表现与四个维度!$A:$T,MATCH($A20,股债表现与四个维度!$A:$A,0),MATCH(E$4,股债表现与四个维度!$2:$2,0))} -> 复苏 | F20: {=INDEX(股债表现与四个维度!$A:$T,MATCH($A20,股债表现与四个维度!$A:$A,0),MATCH(F$4,股债表现与四个维度!$2:$2,0))} -> 紧货币紧信用 | G20: {=INDEX(股债表现与四个维度!$A:$T,MATCH($A20,股债表现与四个维度!$A:$A,0),MATCH(G$4,股债表现与四个维度!$2:$2,0))} -> 双宽 | H20: {=INDEX(股债表现与四个维度!$A:$T,MATCH($A20,股债表现与四个维度!$A:$A,0),MATCH(H$4,股债表现与四个维度!$2:$2,0))} -> 被动补库存 | I20: {=INDEX(股债表现与四个维度!$A:$T,MATCH($A20,股债表现与四个维度!$A:$A,0),MATCH(I$4,股债表现与四个维度!$2:$2,0))} -> 产能周期下行,被动去库存 | J20: {=INDEX(股债表现与四个维度!$A:$T,MATCH($A20,股债表现与四个维度!$A:$A,0),MATCH(J$3&J$4,股债表现与四个维度!$2:$2&股债表现与四个维度!$3:$3,0))} -> 0 | K20: {=INDEX(股债表现与四个维度!$A:$T,MATCH($A20,股债表现与四个维度!$A:$A,0),MATCH(K$3&K$4,股债表现与四个维度!$2:$2&股债表现与四个维度!$3:$3,0))} -> 0.36363636 | L20: {=INDEX(股债表现与四个维度!$A:$T,MATCH($A20,股债表现与四个维度!$A:$A,0),MATCH(L$3&L$4,股债表现与四个维度!$2:$2&股债表现与四个维度!$3:$3,0))} -> 0.1 | M20: {=INDEX(股债表现与四个维度!$A:$T,MATCH($A20,股债表现与四个维度!$A:$A,0),MATCH(M$3&M$4,股债表现与四个维度!$2:$2&股债表现与四个维度!$3:$3,0))} -> -0.2 | N20: {=INDEX(股债表现与四个维度!$A:$T,MATCH($A20,股债表现与四个维度!$A:$A,0),MATCH(N$3&N$4,股债表现与四个维度!$2:$2&股债表现与四个维度!$3:$3,0))} -> -0.076923077 | O20: {=INDEX(股债表现与四个维度!$A:$T,MATCH($A20,股债表现与四个维度!$A:$A,0),MATCH(O$3&O$4,股债表现与四个维度!$2:$2&股债表现与四个维度!$3:$3,0))} -> 0.28205128 | P20: {=INDEX(股债表现与四个维度!$A:$T,MATCH($A20,股债表现与四个维度!$A:$A,0),MATCH(P$3&P$4,股债表现与四个维度!$2:$2&股债表现与四个维度!$3:$3,0))} -> -0.041666667 | Q20: {=INDEX(股债表现与四个维度!$A:$T,MATCH($A20,股债表现与四个维度!$A:$A,0),MATCH(Q$3&Q$4,股债表现与四个维度!$2:$2&股债表现与四个维度!$3:$3,0))} -> 0.29166667 | ... S20: {=INDEX(股债表现与四个维度!$A:$T,MATCH($A20,股债表现与四个维度!$A:$A,0),MATCH(S$3&S$4,股债表现与四个维度!$2:$2&股债表现与四个维度!$3:$3,0))} -> 1 | T20: =SUMIFS($J20:$S20,$J20:$S20,"<>"&"#N/A",$J$4:$S$4,T$4) -> -1.0185897 | U20: =SUMIFS($J20:$S20,$J20:$S20,"<>"&"#N/A",$J$4:$S$4,U$4) -> 1.7373543 | V20: =T20-U20 -> -2.7559441 | W20: =B20+C20 -> 15.226282 | X20: =B20-D20 -> #N/A | Y20: =AVERAGE(V20:V25) -> -2.0278738 | Z20: =AVERAGE(W20:W25) -> -1.1986391 | AA20: =AVERAGE(AC20:AC25) -> -0.41790112 | AB20: -0.41790112 | AC20: 1.171034
A21: =EOMONTH(A20,-1) -> 45535 | B21: {=INDEX(股债表现与四个维度!$A:$T,MATCH($A21,股债表现与四个维度!$A:$A,0),MATCH(B$4,股债表现与四个维度!$2:$2,0))} -> -3.9690314 | C21: {=INDEX(股债表现与四个维度!$A:$T,MATCH($A21,股债表现与四个维度!$A:$A,0),MATCH(C$4,股债表现与四个维度!$2:$2,0))} -> -6.466996 | D21: {=INDEX(股债表现与四个维度!$A:$T,MATCH($A21,股债表现与四个维度!$A:$A,0),MATCH(D$4,股债表现与四个维度!$2:$2,0))} -> #N/A | E21: {=INDEX(股债表现与四个维度!$A:$T,MATCH($A21,股债表现与四个维度!$A:$A,0),MATCH(E$4,股债表现与四个维度!$2:$2,0))} -> 复苏 | F21: {=INDEX(股债表现与四个维度!$A:$T,MATCH($A21,股债表现与四个维度!$A:$A,0),MATCH(F$4,股债表现与四个维度!$2:$2,0))} -> 宽货币紧信用 | G21: {=INDEX(股债表现与四个维度!$A:$T,MATCH($A21,股债表现与四个维度!$A:$A,0),MATCH(G$4,股债表现与四个维度!$2:$2,0))} -> 双宽 | H21: {=INDEX(股债表现与四个维度!$A:$T,MATCH($A21,股债表现与四个维度!$A:$A,0),MATCH(H$4,股债表现与四个维度!$2:$2,0))} -> 被动补库存 | I21: {=INDEX(股债表现与四个维度!$A:$T,MATCH($A21,股债表现与四个维度!$A:$A,0),MATCH(I$4,股债表现与四个维度!$2:$2,0))} -> 产能周期上行,被动去库存 | J21: {=INDEX(股债表现与四个维度!$A:$T,MATCH($A21,股债表现与四个维度!$A:$A,0),MATCH(J$3&J$4,股债表现与四个维度!$2:$2&股债表现与四个维度!$3:$3,0))} -> 0 | K21: {=INDEX(股债表现与四个维度!$A:$T,MATCH($A21,股债表现与四个维度!$A:$A,0),MATCH(K$3&K$4,股债表现与四个维度!$2:$2&股债表现与四个维度!$3:$3,0))} -> 0.36363636 | L21: {=INDEX(股债表现与四个维度!$A:$T,MATCH($A21,股债表现与四个维度!$A:$A,0),MATCH(L$3&L$4,股债表现与四个维度!$2:$2&股债表现与四个维度!$3:$3,0))} -> 0.2 | M21: {=INDEX(股债表现与四个维度!$A:$T,MATCH($A21,股债表现与四个维度!$A:$A,0),MATCH(M$3&M$4,股债表现与四个维度!$2:$2&股债表现与四个维度!$3:$3,0))} -> 0.7 | N21: {=INDEX(股债表现与四个维度!$A:$T,MATCH($A21,股债表现与四个维度!$A:$A,0),MATCH(N$3&N$4,股债表现与四个维度!$2:$2&股债表现与四个维度!$3:$3,0))} -> -0.078947368 | O21: {=INDEX(股债表现与四个维度!$A:$T,MATCH($A21,股债表现与四个维度!$A:$A,0),MATCH(O$3&O$4,股债表现与四个维度!$2:$2&股债表现与四个维度!$3:$3,0))} -> 0.28947368 | P21: {=INDEX(股债表现与四个维度!$A:$T,MATCH($A21,股债表现与四个维度!$A:$A,0),MATCH(P$3&P$4,股债表现与四个维度!$2:$2&股债表现与四个维度!$3:$3,0))} -> -0.043478261 | Q21: {=INDEX(股债表现与四个维度!$A:$T,MATCH($A21,股债表现与四个维度!$A:$A,0),MATCH(Q$3&Q$4,股债表现与四个维度!$2:$2&股债表现与四个维度!$3:$3,0))} -> 0.30434783 | ... S21: {=INDEX(股债表现与四个维度!$A:$T,MATCH($A21,股债表现与四个维度!$A:$A,0),MATCH(S$3&S$4,股债表现与四个维度!$2:$2&股债表现与四个维度!$3:$3,0))} -> 1 | T21: =SUMIFS($J21:$S21,$J21:$S21,"<>"&"#N/A",$J$4:$S$4,T$4) -> -0.92242563 | U21: =SUMIFS($J21:$S21,$J21:$S21,"<>"&"#N/A",$J$4:$S$4,U$4) -> 2.6574579 | V21: =T21-U21 -> -3.5798835 | W21: =B21+C21 -> -10.436027 | X21: =B21-D21 -> #N/A | Y21: =AVERAGE(V21:V26) -> -1.6886003 | Z21: =AVERAGE(W21:W26) -> -5.1674477 | AA21: =AVERAGE(AC21:AC26) -> -0.8380709 | AB21: -0.8380709 | AC21: 1.1454003
A22: =EOMONTH(A21,-1) -> 45504 | B22: {=INDEX(股债表现与四个维度!$A:$T,MATCH($A22,股债表现与四个维度!$A:$A,0),MATCH(B$4,股债表现与四个维度!$2:$2,0))} -> 0.27106655 | C22: {=INDEX(股债表现与四个维度!$A:$T,MATCH($A22,股债表现与四个维度!$A:$A,0),MATCH(C$4,股债表现与四个维度!$2:$2,0))} -> -1.745492 | D22: {=INDEX(股债表现与四个维度!$A:$T,MATCH($A22,股债表现与四个维度!$A:$A,0),MATCH(D$4,股债表现与四个维度!$2:$2,0))} -> #N/A | E22: {=INDEX(股债表现与四个维度!$A:$T,MATCH($A22,股债表现与四个维度!$A:$A,0),MATCH(E$4,股债表现与四个维度!$2:$2,0))} -> 过热 | F22: {=INDEX(股债表现与四个维度!$A:$T,MATCH($A22,股债表现与四个维度!$A:$A,0),MATCH(F$4,股债表现与四个维度!$2:$2,0))} -> 宽货币宽信用 | G22: {=INDEX(股债表现与四个维度!$A:$T,MATCH($A22,股债表现与四个维度!$A:$A,0),MATCH(G$4,股债表现与四个维度!$2:$2,0))} -> 双宽 | H22: {=INDEX(股债表现与四个维度!$A:$T,MATCH($A22,股债表现与四个维度!$A:$A,0),MATCH(H$4,股债表现与四个维度!$2:$2,0))} -> 被动补库存 | I22: {=INDEX(股债表现与四个维度!$A:$T,MATCH($A22,股债表现与四个维度!$A:$A,0),MATCH(I$4,股债表现与四个维度!$2:$2,0))} -> 产能周期上行,被动去库存 | J22: {=INDEX(股债表现与四个维度!$A:$T,MATCH($A22,股债表现与四个维度!$A:$A,0),MATCH(J$3&J$4,股债表现与四个维度!$2:$2&股债表现与四个维度!$3:$3,0))} -> 0.27272727 | K22: {=INDEX(股债表现与四个维度!$A:$T,MATCH($A22,股债表现与四个维度!$A:$A,0),MATCH(K$3&K$4,股债表现与四个维度!$2:$2&股债表现与四个维度!$3:$3,0))} -> 0.36363636 | L22: {=INDEX(股债表现与四个维度!$A:$T,MATCH($A22,股债表现与四个维度!$A:$A,0),MATCH(L$3&L$4,股债表现与四个维度!$2:$2&股债表现与四个维度!$3:$3,0))} -> -0.26666667 | M22: {=INDEX(股债表现与四个维度!$A:$T,MATCH($A22,股债表现与四个维度!$A:$A,0),MATCH(M$3&M$4,股债表现与四个维度!$2:$2&股债表现与四个维度!$3:$3,0))} -> 0.4 | N22: {=INDEX(股债表现与四个维度!$A:$T,MATCH($A22,股债表现与四个维度!$A:$A,0),MATCH(N$3&N$4,股债表现与四个维度!$2:$2&股债表现与四个维度!$3:$3,0))} -> -0.051282051 | O22: {=INDEX(股债表现与四个维度!$A:$T,MATCH($A22,股债表现与四个维度!$A:$A,0),MATCH(O$3&O$4,股债表现与四个维度!$2:$2&股债表现与四个维度!$3:$3,0))} -> 0.30769231 | P22: {=INDEX(股债表现与四个维度!$A:$T,MATCH($A22,股债表现与四个维度!$A:$A,0),MATCH(P$3&P$4,股债表现与四个维度!$2:$2&股债表现与四个维度!$3:$3,0))} -> 0 | Q22: {=INDEX(股债表现与四个维度!$A:$T,MATCH($A22,股债表现与四个维度!$A:$A,0),MATCH(Q$3&Q$4,股债表现与四个维度!$2:$2&股债表现与四个维度!$3:$3,0))} -> 0.27272727 | ... S22: {=INDEX(股债表现与四个维度!$A:$T,MATCH($A22,股债表现与四个维度!$A:$A,0),MATCH(S$3&S$4,股债表现与四个维度!$2:$2&股债表现与四个维度!$3:$3,0))} -> 0.076923077 | T22: =SUMIFS($J22:$S22,$J22:$S22,"<>"&"#N/A",$J$4:$S$4,T$4) -> -0.27599068 | U22: =SUMIFS($J22:$S22,$J22:$S22,"<>"&"#N/A",$J$4:$S$4,U$4) -> 1.420979 | V22: =T22-U22 -> -1.6969697 | W22: =B22+C22 -> -1.4744254 | X22: =B22-D22 -> #N/A | Y22: =AVERAGE(V22:V27) -> -1.2367117 | Z22: =AVERAGE(W22:W27) -> -3.4521948 | AA22: =AVERAGE(AC22:AC27) -> -1.2252779 | AB22: -1.2252779 | AC22: -0.89249119
A23: =EOMONTH(A22,-1) -> 45473 | B23: {=INDEX(股债表现与四个维度!$A:$T,MATCH($A23,股债表现与四个维度!$A:$A,0),MATCH(B$4,股债表现与四个维度!$2:$2,0))} -> -5.1273772 | C23: {=INDEX(股债表现与四个维度!$A:$T,MATCH($A23,股债表现与四个维度!$A:$A,0),MATCH(C$4,股债表现与四个维度!$2:$2,0))} -> -4.7655639 | D23: {=INDEX(股债表现与四个维度!$A:$T,MATCH($A23,股债表现与四个维度!$A:$A,0),MATCH(D$4,股债表现与四个维度!$2:$2,0))} -> #N/A | E23: {=INDEX(股债表现与四个维度!$A:$T,MATCH($A23,股债表现与四个维度!$A:$A,0),MATCH(E$4,股债表现与四个维度!$2:$2,0))} -> 过热 | F23: {=INDEX(股债表现与四个维度!$A:$T,MATCH($A23,股债表现与四个维度!$A:$A,0),MATCH(F$4,股债表现与四个维度!$2:$2,0))} -> 宽货币紧信用 | G23: {=INDEX(股债表现与四个维度!$A:$T,MATCH($A23,股债表现与四个维度!$A:$A,0),MATCH(G$4,股债表现与四个维度!$2:$2,0))} -> 双紧 | H23: {=INDEX(股债表现与四个维度!$A:$T,MATCH($A23,股债表现与四个维度!$A:$A,0),MATCH(H$4,股债表现与四个维度!$2:$2,0))} -> 被动补库存 | I23: {=INDEX(股债表现与四个维度!$A:$T,MATCH($A23,股债表现与四个维度!$A:$A,0),MATCH(I$4,股债表现与四个维度!$2:$2,0))} -> 产能周期上行,被动去库存 | J23: {=INDEX(股债表现与四个维度!$A:$T,MATCH($A23,股债表现与四个维度!$A:$A,0),MATCH(J$3&J$4,股债表现与四个维度!$2:$2&股债表现与四个维度!$3:$3,0))} -> 0.27272727 | K23: {=INDEX(股债表现与四个维度!$A:$T,MATCH($A23,股债表现与四个维度!$A:$A,0),MATCH(K$3&K$4,股债表现与四个维度!$2:$2&股债表现与四个维度!$3:$3,0))} -> 0.36363636 | L23: {=INDEX(股债表现与四个维度!$A:$T,MATCH($A23,股债表现与四个维度!$A:$A,0),MATCH(L$3&L$4,股债表现与四个维度!$2:$2&股债表现与四个维度!$3:$3,0))} -> 0.26315789 | M23: {=INDEX(股债表现与四个维度!$A:$T,MATCH($A23,股债表现与四个维度!$A:$A,0),MATCH(M$3&M$4,股债表现与四个维度!$2:$2&股债表现与四个维度!$3:$3,0))} -> 0.68421053 | N23: {=INDEX(股债表现与四个维度!$A:$T,MATCH($A23,股债表现与四个维度!$A:$A,0),MATCH(N$3&N$4,股债表现与四个维度!$2:$2&股债表现与四个维度!$3:$3,0))} -> 0.23809524 | O23: {=INDEX(股债表现与四个维度!$A:$T,MATCH($A23,股债表现与四个维度!$A:$A,0),MATCH(O$3&O$4,股债表现与四个维度!$2:$2&股债表现与四个维度!$3:$3,0))} -> -0.047619048 | P23: {=INDEX(股债表现与四个维度!$A:$T,MATCH($A23,股债表现与四个维度!$A:$A,0),MATCH(P$3&P$4,股债表现与四个维度!$2:$2&股债表现与四个维度!$3:$3,0))} -> 0.047619048 | Q23: {=INDEX(股债表现与四个维度!$A:$T,MATCH($A23,股债表现与四个维度!$A:$A,0),MATCH(Q$3&Q$4,股债表现与四个维度!$2:$2&股债表现与四个维度!$3:$3,0))} -> 0.33333333 | ... S23: {=INDEX(股债表现与四个维度!$A:$T,MATCH($A23,股债表现与四个维度!$A:$A,0),MATCH(S$3&S$4,股债表现与四个维度!$2:$2&股债表现与四个维度!$3:$3,0))} -> 0.076923077 | T23: =SUMIFS($J23:$S23,$J23:$S23,"<>"&"#N/A",$J$4:$S$4,T$4) -> 0.59083022 | U23: =SUMIFS($J23:$S23,$J23:$S23,"<>"&"#N/A",$J$4:$S$4,U$4) -> 1.4104843 | V23: =T23-U23 -> -0.81965403 | W23: =B23+C23 -> -9.8929411 | X23: =B23-D23 -> #N/A | Y23: =AVERAGE(V23:V28) -> -1.0745905 | Z23: =AVERAGE(W23:W28) -> -7.1639653 | AA23: =AVERAGE(AC23:AC28) -> -1.1612881 | AB23: -1.1612881 | AC23: -1.1843058
A24: =EOMONTH(A23,-1) -> 45443 | B24: {=INDEX(股债表现与四个维度!$A:$T,MATCH($A24,股债表现与四个维度!$A:$A,0),MATCH(B$4,股债表现与四个维度!$2:$2,0))} -> -1.2058617 | C24: {=INDEX(股债表现与四个维度!$A:$T,MATCH($A24,股债表现与四个维度!$A:$A,0),MATCH(C$4,股债表现与四个维度!$2:$2,0))} -> 2.1025974 | D24: {=INDEX(股债表现与四个维度!$A:$T,MATCH($A24,股债表现与四个维度!$A:$A,0),MATCH(D$4,股债表现与四个维度!$2:$2,0))} -> #N/A | E24: {=INDEX(股债表现与四个维度!$A:$T,MATCH($A24,股债表现与四个维度!$A:$A,0),MATCH(E$4,股债表现与四个维度!$2:$2,0))} -> 滞涨 | F24: {=INDEX(股债表现与四个维度!$A:$T,MATCH($A24,股债表现与四个维度!$A:$A,0),MATCH(F$4,股债表现与四个维度!$2:$2,0))} -> 宽货币宽信用 | G24: {=INDEX(股债表现与四个维度!$A:$T,MATCH($A24,股债表现与四个维度!$A:$A,0),MATCH(G$4,股债表现与四个维度!$2:$2,0))} -> 双宽 | H24: {=INDEX(股债表现与四个维度!$A:$T,MATCH($A24,股债表现与四个维度!$A:$A,0),MATCH(H$4,股债表现与四个维度!$2:$2,0))} -> 被动补库存 | I24: {=INDEX(股债表现与四个维度!$A:$T,MATCH($A24,股债表现与四个维度!$A:$A,0),MATCH(I$4,股债表现与四个维度!$2:$2,0))} -> 产能周期下行,主动去库存 | J24: {=INDEX(股债表现与四个维度!$A:$T,MATCH($A24,股债表现与四个维度!$A:$A,0),MATCH(J$3&J$4,股债表现与四个维度!$2:$2&股债表现与四个维度!$3:$3,0))} -> -0.1 | K24: {=INDEX(股债表现与四个维度!$A:$T,MATCH($A24,股债表现与四个维度!$A:$A,0),MATCH(K$3&K$4,股债表现与四个维度!$2:$2&股债表现与四个维度!$3:$3,0))} -> -0.3 | L24: {=INDEX(股债表现与四个维度!$A:$T,MATCH($A24,股债表现与四个维度!$A:$A,0),MATCH(L$3&L$4,股债表现与四个维度!$2:$2&股债表现与四个维度!$3:$3,0))} -> -0.21428571 | M24: {=INDEX(股债表现与四个维度!$A:$T,MATCH($A24,股债表现与四个维度!$A:$A,0),MATCH(M$3&M$4,股债表现与四个维度!$2:$2&股债表现与四个维度!$3:$3,0))} -> 0.5 | N24: {=INDEX(股债表现与四个维度!$A:$T,MATCH($A24,股债表现与四个维度!$A:$A,0),MATCH(N$3&N$4,股债表现与四个维度!$2:$2&股债表现与四个维度!$3:$3,0))} -> -0.078947368 | O24: {=INDEX(股债表现与四个维度!$A:$T,MATCH($A24,股债表现与四个维度!$A:$A,0),MATCH(O$3&O$4,股债表现与四个维度!$2:$2&股债表现与四个维度!$3:$3,0))} -> 0.34210526 | P24: {=INDEX(股债表现与四个维度!$A:$T,MATCH($A24,股债表现与四个维度!$A:$A,0),MATCH(P$3&P$4,股债表现与四个维度!$2:$2&股债表现与四个维度!$3:$3,0))} -> -0.047619048 | Q24: {=INDEX(股债表现与四个维度!$A:$T,MATCH($A24,股债表现与四个维度!$A:$A,0),MATCH(Q$3&Q$4,股债表现与四个维度!$2:$2&股债表现与四个维度!$3:$3,0))} -> 0.23809524 | ... S24: {=INDEX(股债表现与四个维度!$A:$T,MATCH($A24,股债表现与四个维度!$A:$A,0),MATCH(S$3&S$4,股债表现与四个维度!$2:$2&股债表现与四个维度!$3:$3,0))} -> 0.076923077 | T24: =SUMIFS($J24:$S24,$J24:$S24,"<>"&"#N/A",$J$4:$S$4,T$4) -> -0.67162136 | U24: =SUMIFS($J24:$S24,$J24:$S24,"<>"&"#N/A",$J$4:$S$4,U$4) -> 0.85712358 | V24: =T24-U24 -> -1.5287449 | W24: =B24+C24 -> 0.89673569 | X24: =B24-D24 -> #N/A | Y24: =AVERAGE(V24:V29) -> -0.88123548 | Z24: =AVERAGE(W24:W29) -> -6.7064098 | AA24: =AVERAGE(AC24:AC29) -> -1.0148199 | AB24: -1.0148199 | AC24: -1.5354306
